<robot name = "robot">
    <link name="root">
        <inertial>
            <origin xyz="0.0 0.0 1.5" rpy="0 0 0"/>
            <mass value="1" />
            <inertia ixx="100" ixy="0" ixz="0" iyy="100" iyz="0" izz="100" />
        </inertial>
        <visual>
            <origin xyz="0.0 0.0 1.5" rpy="0 0 0"/>
            <geometry>
                <box size="0 0 0.0001" />
            </geometry>
            <material name="Green">
                <color rgba="0 1.0 0.0 1.0"/>
            </material>
        </visual>
        <collision>
            <origin xyz="0.0 0.0 1.5" rpy="0 0 0"/>
            <geometry>
                <box size="0 0 0.0001" />
            </geometry>
        </collision>
    </link>
    <joint name="root_000" type="revolute">
       <parent link="root"/>
       <child  link="000"/>
       <origin rpy="0 0 0" xyz="0.0 0.0 1.5" />
     <axis xyz="1 0 0"/>
       <limit effort="0.0" lower="-3.14159" upper="3.14159" velocity="0.0"/>
    </joint>
    <link name="000">
        <inertial>
            <origin xyz="0.1 0.0 0.0" rpy="0 0 0"/>
            <mass value="1" />
            <inertia ixx="100" ixy="0" ixz="0" iyy="100" iyz="0" izz="100" />
        </inertial>
        <visual>
            <origin xyz="0.1 0.0 0.0" rpy="0 0 0"/>
            <geometry>
                <box size="0.2 0.7 0.4" />
            </geometry>
            <material name="Green">
                <color rgba="0 1.0 0.0 1.0"/>
            </material>
        </visual>
        <collision>
            <origin xyz="0.1 0.0 0.0" rpy="0 0 0"/>
            <geometry>
                <box size="0.2 0.7 0.4" />
            </geometry>
        </collision>
    </link>
    <joint name="000_010" type="revolute">
       <parent link="000"/>
       <child  link="010"/>
       <origin rpy="0 0 0" xyz="0.2 0.0 -0.0" />
     <axis xyz="1 0 0"/>
       <limit effort="0.0" lower="-3.14159" upper="3.14159" velocity="0.0"/>
    </joint>
    <link name="010">
        <inertial>
            <origin xyz="0.1 0.0 -0.0" rpy="0 0 0"/>
            <mass value="1" />
            <inertia ixx="100" ixy="0" ixz="0" iyy="100" iyz="0" izz="100" />
        </inertial>
        <visual>
            <origin xyz="0.1 0.0 -0.0" rpy="0 0 0"/>
            <geometry>
                <box size="0.2 0.7 0.4" />
            </geometry>
            <material name="Green">
                <color rgba="0 1.0 0.0 1.0"/>
            </material>
        </visual>
        <collision>
            <origin xyz="0.1 0.0 -0.0" rpy="0 0 0"/>
            <geometry>
                <box size="0.2 0.7 0.4" />
            </geometry>
        </collision>
    </link>
    <joint name="010_020" type="revolute">
       <parent link="010"/>
       <child  link="020"/>
       <origin rpy="0 0 0" xyz="0.2 0.0 -0.0" />
     <axis xyz="1 0 0"/>
       <limit effort="0.0" lower="-3.14159" upper="3.14159" velocity="0.0"/>
    </joint>
    <link name="020">
        <inertial>
            <origin xyz="0.1 0.0 -0.0" rpy="0 0 0"/>
            <mass value="1" />
            <inertia ixx="100" ixy="0" ixz="0" iyy="100" iyz="0" izz="100" />
        </inertial>
        <visual>
            <origin xyz="0.1 0.0 -0.0" rpy="0 0 0"/>
            <geometry>
                <box size="0.2 0.7 0.4" />
            </geometry>
            <material name="Green">
                <color rgba="0 1.0 0.0 1.0"/>
            </material>
        </visual>
        <collision>
            <origin xyz="0.1 0.0 -0.0" rpy="0 0 0"/>
            <geometry>
                <box size="0.2 0.7 0.4" />
            </geometry>
        </collision>
    </link>
    <joint name="020_020-100" type="revolute">
       <parent link="020"/>
       <child  link="020-100"/>
       <origin rpy="0 0 0" xyz="0.1 0.35 -0.0" />
     <axis xyz="0 1 0"/>
       <limit effort="0.0" lower="-3.14159" upper="3.14159" velocity="0.0"/>
    </joint>
    <link name="020-100">
        <inertial>
            <origin xyz="0.0 0.2 -0.0" rpy="0 0 0"/>
            <mass value="1" />
            <inertia ixx="100" ixy="0" ixz="0" iyy="100" iyz="0" izz="100" />
        </inertial>
        <visual>
            <origin xyz="0.0 0.2 -0.0" rpy="0 0 0"/>
            <geometry>
                <box size="0.5 0.4 0.7" />
            </geometry>
            <material name="Green">
                <color rgba="0 1.0 0.0 1.0"/>
            </material>
        </visual>
        <collision>
            <origin xyz="0.0 0.2 -0.0" rpy="0 0 0"/>
            <geometry>
                <box size="0.5 0.4 0.7" />
            </geometry>
        </collision>
    </link>
    <joint name="020-100_020-110" type="revolute">
       <parent link="020-100"/>
       <child  link="020-110"/>
       <origin rpy="0 0 0" xyz="0.0 0.4 -0.0" />
     <axis xyz="0 1 0"/>
       <limit effort="0.0" lower="-3.14159" upper="3.14159" velocity="0.0"/>
    </joint>
    <link name="020-110">
        <inertial>
            <origin xyz="0.0 0.2 -0.0" rpy="0 0 0"/>
            <mass value="1" />
            <inertia ixx="100" ixy="0" ixz="0" iyy="100" iyz="0" izz="100" />
        </inertial>
        <visual>
            <origin xyz="0.0 0.2 -0.0" rpy="0 0 0"/>
            <geometry>
                <box size="0.5 0.4 0.7" />
            </geometry>
            <material name="Green">
                <color rgba="0 1.0 0.0 1.0"/>
            </material>
        </visual>
        <collision>
            <origin xyz="0.0 0.2 -0.0" rpy="0 0 0"/>
            <geometry>
                <box size="0.5 0.4 0.7" />
            </geometry>
        </collision>
    </link>
    <joint name="020-110_020-110-200" type="revolute">
       <parent link="020-110"/>
       <child  link="020-110-200"/>
       <origin rpy="0 0 0" xyz="0.0 0.2 -0.35" />
     <axis xyz="0 0 1"/>
       <limit effort="0.0" lower="-3.14159" upper="3.14159" velocity="0.0"/>
    </joint>
    <link name="020-110-200">
        <inertial>
            <origin xyz="0.0 0.0 -0.15" rpy="0 0 0"/>
            <mass value="1" />
            <inertia ixx="100" ixy="0" ixz="0" iyy="100" iyz="0" izz="100" />
        </inertial>
        <visual>
            <origin xyz="0.0 0.0 -0.15" rpy="0 0 0"/>
            <geometry>
                <box size="0.7 0.6 0.3" />
            </geometry>
            <material name="Green">
                <color rgba="0 1.0 0.0 1.0"/>
            </material>
        </visual>
        <collision>
            <origin xyz="0.0 0.0 -0.15" rpy="0 0 0"/>
            <geometry>
                <box size="0.7 0.6 0.3" />
            </geometry>
        </collision>
    </link>
    <joint name="020-110-200_020-110-210" type="revolute">
       <parent link="020-110-200"/>
       <child  link="020-110-210"/>
       <origin rpy="0 0 0" xyz="0.0 0.0 -0.3" />
     <axis xyz="0 0 1"/>
       <limit effort="0.0" lower="-3.14159" upper="3.14159" velocity="0.0"/>
    </joint>
    <link name="020-110-210">
        <inertial>
            <origin xyz="0.0 0.0 -0.15" rpy="0 0 0"/>
            <mass value="1" />
            <inertia ixx="100" ixy="0" ixz="0" iyy="100" iyz="0" izz="100" />
        </inertial>
        <visual>
            <origin xyz="0.0 0.0 -0.15" rpy="0 0 0"/>
            <geometry>
                <box size="0.7 0.6 0.3" />
            </geometry>
            <material name="Green">
                <color rgba="0 1.0 0.0 1.0"/>
            </material>
        </visual>
        <collision>
            <origin xyz="0.0 0.0 -0.15" rpy="0 0 0"/>
            <geometry>
                <box size="0.7 0.6 0.3" />
            </geometry>
        </collision>
    </link>
    <joint name="020-110-210_020-110-210-300" type="revolute">
       <parent link="020-110-210"/>
       <child  link="020-110-210-300"/>
       <origin rpy="0 0 0" xyz="0.35 0.0 -0.15" />
     <axis xyz="1 0 0"/>
       <limit effort="0.0" lower="-3.14159" upper="3.14159" velocity="0.0"/>
    </joint>
    <link name="020-110-210-300">
        <inertial>
            <origin xyz="0.05 0.0 -0.0" rpy="0 0 0"/>
            <mass value="1" />
            <inertia ixx="100" ixy="0" ixz="0" iyy="100" iyz="0" izz="100" />
        </inertial>
        <visual>
            <origin xyz="0.05 0.0 -0.0" rpy="0 0 0"/>
            <geometry>
                <box size="0.1 0.5 0.5" />
            </geometry>
            <material name="Blue">
                <color rgba="0 0.0 1.0 1.0"/>
            </material>
        </visual>
        <collision>
            <origin xyz="0.05 0.0 -0.0" rpy="0 0 0"/>
            <geometry>
                <box size="0.1 0.5 0.5" />
            </geometry>
        </collision>
    </link>
    <joint name="020-110-210-300_020-110-210-310" type="revolute">
       <parent link="020-110-210-300"/>
       <child  link="020-110-210-310"/>
       <origin rpy="0 0 0" xyz="0.1 0.0 -0.0" />
     <axis xyz="1 0 0"/>
       <limit effort="0.0" lower="-3.14159" upper="3.14159" velocity="0.0"/>
    </joint>
    <link name="020-110-210-310">
        <inertial>
            <origin xyz="0.05 0.0 -0.0" rpy="0 0 0"/>
            <mass value="1" />
            <inertia ixx="100" ixy="0" ixz="0" iyy="100" iyz="0" izz="100" />
        </inertial>
        <visual>
            <origin xyz="0.05 0.0 -0.0" rpy="0 0 0"/>
            <geometry>
                <box size="0.1 0.5 0.5" />
            </geometry>
            <material name="Blue">
                <color rgba="0 0.0 1.0 1.0"/>
            </material>
        </visual>
        <collision>
            <origin xyz="0.05 0.0 -0.0" rpy="0 0 0"/>
            <geometry>
                <box size="0.1 0.5 0.5" />
            </geometry>
        </collision>
    </link>
    <joint name="020-100_020-100-200" type="revolute">
       <parent link="020-100"/>
       <child  link="020-100-200"/>
       <origin rpy="0 0 0" xyz="0.0 0.2 -0.35" />
     <axis xyz="0 0 1"/>
       <limit effort="0.0" lower="-3.14159" upper="3.14159" velocity="0.0"/>
    </joint>
    <link name="020-100-200">
        <inertial>
            <origin xyz="0.0 0.0 -0.15" rpy="0 0 0"/>
            <mass value="1" />
            <inertia ixx="100" ixy="0" ixz="0" iyy="100" iyz="0" izz="100" />
        </inertial>
        <visual>
            <origin xyz="0.0 0.0 -0.15" rpy="0 0 0"/>
            <geometry>
                <box size="0.7 0.6 0.3" />
            </geometry>
            <material name="Green">
                <color rgba="0 1.0 0.0 1.0"/>
            </material>
        </visual>
        <collision>
            <origin xyz="0.0 0.0 -0.15" rpy="0 0 0"/>
            <geometry>
                <box size="0.7 0.6 0.3" />
            </geometry>
        </collision>
    </link>
    <joint name="020-100-200_020-100-210" type="revolute">
       <parent link="020-100-200"/>
       <child  link="020-100-210"/>
       <origin rpy="0 0 0" xyz="0.0 0.0 -0.3" />
     <axis xyz="0 0 1"/>
       <limit effort="0.0" lower="-3.14159" upper="3.14159" velocity="0.0"/>
    </joint>
    <link name="020-100-210">
        <inertial>
            <origin xyz="0.0 0.0 -0.15" rpy="0 0 0"/>
            <mass value="1" />
            <inertia ixx="100" ixy="0" ixz="0" iyy="100" iyz="0" izz="100" />
        </inertial>
        <visual>
            <origin xyz="0.0 0.0 -0.15" rpy="0 0 0"/>
            <geometry>
                <box size="0.7 0.6 0.3" />
            </geometry>
            <material name="Green">
                <color rgba="0 1.0 0.0 1.0"/>
            </material>
        </visual>
        <collision>
            <origin xyz="0.0 0.0 -0.15" rpy="0 0 0"/>
            <geometry>
                <box size="0.7 0.6 0.3" />
            </geometry>
        </collision>
    </link>
    <joint name="020-100-210_020-100-210-300" type="revolute">
       <parent link="020-100-210"/>
       <child  link="020-100-210-300"/>
       <origin rpy="0 0 0" xyz="0.35 0.0 -0.15" />
     <axis xyz="1 0 0"/>
       <limit effort="0.0" lower="-3.14159" upper="3.14159" velocity="0.0"/>
    </joint>
    <link name="020-100-210-300">
        <inertial>
            <origin xyz="0.05 0.0 -0.0" rpy="0 0 0"/>
            <mass value="1" />
            <inertia ixx="100" ixy="0" ixz="0" iyy="100" iyz="0" izz="100" />
        </inertial>
        <visual>
            <origin xyz="0.05 0.0 -0.0" rpy="0 0 0"/>
            <geometry>
                <box size="0.1 0.5 0.5" />
            </geometry>
            <material name="Blue">
                <color rgba="0 0.0 1.0 1.0"/>
            </material>
        </visual>
        <collision>
            <origin xyz="0.05 0.0 -0.0" rpy="0 0 0"/>
            <geometry>
                <box size="0.1 0.5 0.5" />
            </geometry>
        </collision>
    </link>
    <joint name="020-100-210-300_020-100-210-310" type="revolute">
       <parent link="020-100-210-300"/>
       <child  link="020-100-210-310"/>
       <origin rpy="0 0 0" xyz="0.1 0.0 -0.0" />
     <axis xyz="1 0 0"/>
       <limit effort="0.0" lower="-3.14159" upper="3.14159" velocity="0.0"/>
    </joint>
    <link name="020-100-210-310">
        <inertial>
            <origin xyz="0.05 0.0 -0.0" rpy="0 0 0"/>
            <mass value="1" />
            <inertia ixx="100" ixy="0" ixz="0" iyy="100" iyz="0" izz="100" />
        </inertial>
        <visual>
            <origin xyz="0.05 0.0 -0.0" rpy="0 0 0"/>
            <geometry>
                <box size="0.1 0.5 0.5" />
            </geometry>
            <material name="Blue">
                <color rgba="0 0.0 1.0 1.0"/>
            </material>
        </visual>
        <collision>
            <origin xyz="0.05 0.0 -0.0" rpy="0 0 0"/>
            <geometry>
                <box size="0.1 0.5 0.5" />
            </geometry>
        </collision>
    </link>
    <joint name="020_020-101" type="revolute">
       <parent link="020"/>
       <child  link="020-101"/>
       <origin rpy="0 0 0" xyz="0.1 -0.35 -0.0" />
     <axis xyz="0 1 0"/>
       <limit effort="0.0" lower="-3.14159" upper="3.14159" velocity="0.0"/>
    </joint>
    <link name="020-101">
        <inertial>
            <origin xyz="0.0 -0.2 -0.0" rpy="0 0 0"/>
            <mass value="1" />
            <inertia ixx="100" ixy="0" ixz="0" iyy="100" iyz="0" izz="100" />
        </inertial>
        <visual>
            <origin xyz="0.0 -0.2 -0.0" rpy="0 0 0"/>
            <geometry>
                <box size="0.5 0.4 0.7" />
            </geometry>
            <material name="Green">
                <color rgba="0 1.0 0.0 1.0"/>
            </material>
        </visual>
        <collision>
            <origin xyz="0.0 -0.2 -0.0" rpy="0 0 0"/>
            <geometry>
                <box size="0.5 0.4 0.7" />
            </geometry>
        </collision>
    </link>
    <joint name="020-101_020-111" type="revolute">
       <parent link="020-101"/>
       <child  link="020-111"/>
       <origin rpy="0 0 0" xyz="0.0 -0.4 -0.0" />
     <axis xyz="0 1 0"/>
       <limit effort="0.0" lower="-3.14159" upper="3.14159" velocity="0.0"/>
    </joint>
    <link name="020-111">
        <inertial>
            <origin xyz="0.0 -0.2 -0.0" rpy="0 0 0"/>
            <mass value="1" />
            <inertia ixx="100" ixy="0" ixz="0" iyy="100" iyz="0" izz="100" />
        </inertial>
        <visual>
            <origin xyz="0.0 -0.2 -0.0" rpy="0 0 0"/>
            <geometry>
                <box size="0.5 0.4 0.7" />
            </geometry>
            <material name="Green">
                <color rgba="0 1.0 0.0 1.0"/>
            </material>
        </visual>
        <collision>
            <origin xyz="0.0 -0.2 -0.0" rpy="0 0 0"/>
            <geometry>
                <box size="0.5 0.4 0.7" />
            </geometry>
        </collision>
    </link>
    <joint name="020-111_020-111-200" type="revolute">
       <parent link="020-111"/>
       <child  link="020-111-200"/>
       <origin rpy="0 0 0" xyz="0.0 -0.2 -0.35" />
     <axis xyz="0 0 1"/>
       <limit effort="0.0" lower="-3.14159" upper="3.14159" velocity="0.0"/>
    </joint>
    <link name="020-111-200">
        <inertial>
            <origin xyz="0.0 -0.0 -0.15" rpy="0 0 0"/>
            <mass value="1" />
            <inertia ixx="100" ixy="0" ixz="0" iyy="100" iyz="0" izz="100" />
        </inertial>
        <visual>
            <origin xyz="0.0 -0.0 -0.15" rpy="0 0 0"/>
            <geometry>
                <box size="0.7 0.6 0.3" />
            </geometry>
            <material name="Green">
                <color rgba="0 1.0 0.0 1.0"/>
            </material>
        </visual>
        <collision>
            <origin xyz="0.0 -0.0 -0.15" rpy="0 0 0"/>
            <geometry>
                <box size="0.7 0.6 0.3" />
            </geometry>
        </collision>
    </link>
    <joint name="020-111-200_020-111-210" type="revolute">
       <parent link="020-111-200"/>
       <child  link="020-111-210"/>
       <origin rpy="0 0 0" xyz="0.0 -0.0 -0.3" />
     <axis xyz="0 0 1"/>
       <limit effort="0.0" lower="-3.14159" upper="3.14159" velocity="0.0"/>
    </joint>
    <link name="020-111-210">
        <inertial>
            <origin xyz="0.0 -0.0 -0.15" rpy="0 0 0"/>
            <mass value="1" />
            <inertia ixx="100" ixy="0" ixz="0" iyy="100" iyz="0" izz="100" />
        </inertial>
        <visual>
            <origin xyz="0.0 -0.0 -0.15" rpy="0 0 0"/>
            <geometry>
                <box size="0.7 0.6 0.3" />
            </geometry>
            <material name="Green">
                <color rgba="0 1.0 0.0 1.0"/>
            </material>
        </visual>
        <collision>
            <origin xyz="0.0 -0.0 -0.15" rpy="0 0 0"/>
            <geometry>
                <box size="0.7 0.6 0.3" />
            </geometry>
        </collision>
    </link>
    <joint name="020-111-210_020-111-210-300" type="revolute">
       <parent link="020-111-210"/>
       <child  link="020-111-210-300"/>
       <origin rpy="0 0 0" xyz="0.35 -0.0 -0.15" />
     <axis xyz="1 0 0"/>
       <limit effort="0.0" lower="-3.14159" upper="3.14159" velocity="0.0"/>
    </joint>
    <link name="020-111-210-300">
        <inertial>
            <origin xyz="0.05 -0.0 -0.0" rpy="0 0 0"/>
            <mass value="1" />
            <inertia ixx="100" ixy="0" ixz="0" iyy="100" iyz="0" izz="100" />
        </inertial>
        <visual>
            <origin xyz="0.05 -0.0 -0.0" rpy="0 0 0"/>
            <geometry>
                <box size="0.1 0.5 0.5" />
            </geometry>
            <material name="Blue">
                <color rgba="0 0.0 1.0 1.0"/>
            </material>
        </visual>
        <collision>
            <origin xyz="0.05 -0.0 -0.0" rpy="0 0 0"/>
            <geometry>
                <box size="0.1 0.5 0.5" />
            </geometry>
        </collision>
    </link>
    <joint name="020-111-210-300_020-111-210-310" type="revolute">
       <parent link="020-111-210-300"/>
       <child  link="020-111-210-310"/>
       <origin rpy="0 0 0" xyz="0.1 -0.0 -0.0" />
     <axis xyz="1 0 0"/>
       <limit effort="0.0" lower="-3.14159" upper="3.14159" velocity="0.0"/>
    </joint>
    <link name="020-111-210-310">
        <inertial>
            <origin xyz="0.05 -0.0 -0.0" rpy="0 0 0"/>
            <mass value="1" />
            <inertia ixx="100" ixy="0" ixz="0" iyy="100" iyz="0" izz="100" />
        </inertial>
        <visual>
            <origin xyz="0.05 -0.0 -0.0" rpy="0 0 0"/>
            <geometry>
                <box size="0.1 0.5 0.5" />
            </geometry>
            <material name="Blue">
                <color rgba="0 0.0 1.0 1.0"/>
            </material>
        </visual>
        <collision>
            <origin xyz="0.05 -0.0 -0.0" rpy="0 0 0"/>
            <geometry>
                <box size="0.1 0.5 0.5" />
            </geometry>
        </collision>
    </link>
    <joint name="020-101_020-101-200" type="revolute">
       <parent link="020-101"/>
       <child  link="020-101-200"/>
       <origin rpy="0 0 0" xyz="0.0 -0.2 -0.35" />
     <axis xyz="0 0 1"/>
       <limit effort="0.0" lower="-3.14159" upper="3.14159" velocity="0.0"/>
    </joint>
    <link name="020-101-200">
        <inertial>
            <origin xyz="0.0 -0.0 -0.15" rpy="0 0 0"/>
            <mass value="1" />
            <inertia ixx="100" ixy="0" ixz="0" iyy="100" iyz="0" izz="100" />
        </inertial>
        <visual>
            <origin xyz="0.0 -0.0 -0.15" rpy="0 0 0"/>
            <geometry>
                <box size="0.7 0.6 0.3" />
            </geometry>
            <material name="Green">
                <color rgba="0 1.0 0.0 1.0"/>
            </material>
        </visual>
        <collision>
            <origin xyz="0.0 -0.0 -0.15" rpy="0 0 0"/>
            <geometry>
                <box size="0.7 0.6 0.3" />
            </geometry>
        </collision>
    </link>
    <joint name="020-101-200_020-101-210" type="revolute">
       <parent link="020-101-200"/>
       <child  link="020-101-210"/>
       <origin rpy="0 0 0" xyz="0.0 -0.0 -0.3" />
     <axis xyz="0 0 1"/>
       <limit effort="0.0" lower="-3.14159" upper="3.14159" velocity="0.0"/>
    </joint>
    <link name="020-101-210">
        <inertial>
            <origin xyz="0.0 -0.0 -0.15" rpy="0 0 0"/>
            <mass value="1" />
            <inertia ixx="100" ixy="0" ixz="0" iyy="100" iyz="0" izz="100" />
        </inertial>
        <visual>
            <origin xyz="0.0 -0.0 -0.15" rpy="0 0 0"/>
            <geometry>
                <box size="0.7 0.6 0.3" />
            </geometry>
            <material name="Green">
                <color rgba="0 1.0 0.0 1.0"/>
            </material>
        </visual>
        <collision>
            <origin xyz="0.0 -0.0 -0.15" rpy="0 0 0"/>
            <geometry>
                <box size="0.7 0.6 0.3" />
            </geometry>
        </collision>
    </link>
    <joint name="020-101-210_020-101-210-300" type="revolute">
       <parent link="020-101-210"/>
       <child  link="020-101-210-300"/>
       <origin rpy="0 0 0" xyz="0.35 -0.0 -0.15" />
     <axis xyz="1 0 0"/>
       <limit effort="0.0" lower="-3.14159" upper="3.14159" velocity="0.0"/>
    </joint>
    <link name="020-101-210-300">
        <inertial>
            <origin xyz="0.05 -0.0 -0.0" rpy="0 0 0"/>
            <mass value="1" />
            <inertia ixx="100" ixy="0" ixz="0" iyy="100" iyz="0" izz="100" />
        </inertial>
        <visual>
            <origin xyz="0.05 -0.0 -0.0" rpy="0 0 0"/>
            <geometry>
                <box size="0.1 0.5 0.5" />
            </geometry>
            <material name="Blue">
                <color rgba="0 0.0 1.0 1.0"/>
            </material>
        </visual>
        <collision>
            <origin xyz="0.05 -0.0 -0.0" rpy="0 0 0"/>
            <geometry>
                <box size="0.1 0.5 0.5" />
            </geometry>
        </collision>
    </link>
    <joint name="020-101-210-300_020-101-210-310" type="revolute">
       <parent link="020-101-210-300"/>
       <child  link="020-101-210-310"/>
       <origin rpy="0 0 0" xyz="0.1 -0.0 -0.0" />
     <axis xyz="1 0 0"/>
       <limit effort="0.0" lower="-3.14159" upper="3.14159" velocity="0.0"/>
    </joint>
    <link name="020-101-210-310">
        <inertial>
            <origin xyz="0.05 -0.0 -0.0" rpy="0 0 0"/>
            <mass value="1" />
            <inertia ixx="100" ixy="0" ixz="0" iyy="100" iyz="0" izz="100" />
        </inertial>
        <visual>
            <origin xyz="0.05 -0.0 -0.0" rpy="0 0 0"/>
            <geometry>
                <box size="0.1 0.5 0.5" />
            </geometry>
            <material name="Blue">
                <color rgba="0 0.0 1.0 1.0"/>
            </material>
        </visual>
        <collision>
            <origin xyz="0.05 -0.0 -0.0" rpy="0 0 0"/>
            <geometry>
                <box size="0.1 0.5 0.5" />
            </geometry>
        </collision>
    </link>
    <joint name="000_000-100" type="revolute">
       <parent link="000"/>
       <child  link="000-100"/>
       <origin rpy="0 0 0" xyz="0.1 0.35 -0.0" />
     <axis xyz="0 1 0"/>
       <limit effort="0.0" lower="-3.14159" upper="3.14159" velocity="0.0"/>
    </joint>
    <link name="000-100">
        <inertial>
            <origin xyz="0.0 0.2 -0.0" rpy="0 0 0"/>
            <mass value="1" />
            <inertia ixx="100" ixy="0" ixz="0" iyy="100" iyz="0" izz="100" />
        </inertial>
        <visual>
            <origin xyz="0.0 0.2 -0.0" rpy="0 0 0"/>
            <geometry>
                <box size="0.5 0.4 0.7" />
            </geometry>
            <material name="Green">
                <color rgba="0 1.0 0.0 1.0"/>
            </material>
        </visual>
        <collision>
            <origin xyz="0.0 0.2 -0.0" rpy="0 0 0"/>
            <geometry>
                <box size="0.5 0.4 0.7" />
            </geometry>
        </collision>
    </link>
    <joint name="000-100_000-110" type="revolute">
       <parent link="000-100"/>
       <child  link="000-110"/>
       <origin rpy="0 0 0" xyz="0.0 0.4 -0.0" />
     <axis xyz="0 1 0"/>
       <limit effort="0.0" lower="-3.14159" upper="3.14159" velocity="0.0"/>
    </joint>
    <link name="000-110">
        <inertial>
            <origin xyz="0.0 0.2 -0.0" rpy="0 0 0"/>
            <mass value="1" />
            <inertia ixx="100" ixy="0" ixz="0" iyy="100" iyz="0" izz="100" />
        </inertial>
        <visual>
            <origin xyz="0.0 0.2 -0.0" rpy="0 0 0"/>
            <geometry>
                <box size="0.5 0.4 0.7" />
            </geometry>
            <material name="Green">
                <color rgba="0 1.0 0.0 1.0"/>
            </material>
        </visual>
        <collision>
            <origin xyz="0.0 0.2 -0.0" rpy="0 0 0"/>
            <geometry>
                <box size="0.5 0.4 0.7" />
            </geometry>
        </collision>
    </link>
    <joint name="000_000-101" type="revolute">
       <parent link="000"/>
       <child  link="000-101"/>
       <origin rpy="0 0 0" xyz="0.1 -0.35 -0.0" />
     <axis xyz="0 1 0"/>
       <limit effort="0.0" lower="-3.14159" upper="3.14159" velocity="0.0"/>
    </joint>
    <link name="000-101">
        <inertial>
            <origin xyz="0.0 -0.2 -0.0" rpy="0 0 0"/>
            <mass value="1" />
            <inertia ixx="100" ixy="0" ixz="0" iyy="100" iyz="0" izz="100" />
        </inertial>
        <visual>
            <origin xyz="0.0 -0.2 -0.0" rpy="0 0 0"/>
            <geometry>
                <box size="0.5 0.4 0.7" />
            </geometry>
            <material name="Green">
                <color rgba="0 1.0 0.0 1.0"/>
            </material>
        </visual>
        <collision>
            <origin xyz="0.0 -0.2 -0.0" rpy="0 0 0"/>
            <geometry>
                <box size="0.5 0.4 0.7" />
            </geometry>
        </collision>
    </link>
    <joint name="000-101_000-111" type="revolute">
       <parent link="000-101"/>
       <child  link="000-111"/>
       <origin rpy="0 0 0" xyz="0.0 -0.4 -0.0" />
     <axis xyz="0 1 0"/>
       <limit effort="0.0" lower="-3.14159" upper="3.14159" velocity="0.0"/>
    </joint>
    <link name="000-111">
        <inertial>
            <origin xyz="0.0 -0.2 -0.0" rpy="0 0 0"/>
            <mass value="1" />
            <inertia ixx="100" ixy="0" ixz="0" iyy="100" iyz="0" izz="100" />
        </inertial>
        <visual>
            <origin xyz="0.0 -0.2 -0.0" rpy="0 0 0"/>
            <geometry>
                <box size="0.5 0.4 0.7" />
            </geometry>
            <material name="Green">
                <color rgba="0 1.0 0.0 1.0"/>
            </material>
        </visual>
        <collision>
            <origin xyz="0.0 -0.2 -0.0" rpy="0 0 0"/>
            <geometry>
                <box size="0.5 0.4 0.7" />
            </geometry>
        </collision>
    </link>
</robot>