<robot name = "robot">
    <link name="root">
        <inertial>
            <origin xyz="0.0 0.0 1.5" rpy="0 0 0"/>
            <mass value="1" />
            <inertia ixx="100" ixy="0" ixz="0" iyy="100" iyz="0" izz="100" />
        </inertial>
        <visual>
            <origin xyz="0.0 0.0 1.5" rpy="0 0 0"/>
            <geometry>
                <box size="0 0 0.0001" />
            </geometry>
            <material name="Green">
                <color rgba="0 1.0 0.0 1.0"/>
            </material>
        </visual>
        <collision>
            <origin xyz="0.0 0.0 1.5" rpy="0 0 0"/>
            <geometry>
                <box size="0 0 0.0001" />
            </geometry>
        </collision>
    </link>
    <joint name="root_000" type="revolute">
       <parent link="root"/>
       <child  link="000"/>
       <origin rpy="0 0 0" xyz="0.0 0.0 1.5" />
     <axis xyz="1 0 0"/>
       <limit effort="0.0" lower="-3.14159" upper="3.14159" velocity="0.0"/>
    </joint>
    <link name="000">
        <inertial>
            <origin xyz="0.15 0.0 0.0" rpy="0 0 0"/>
            <mass value="1" />
            <inertia ixx="100" ixy="0" ixz="0" iyy="100" iyz="0" izz="100" />
        </inertial>
        <visual>
            <origin xyz="0.15 0.0 0.0" rpy="0 0 0"/>
            <geometry>
                <box size="0.3 0.5 0.3" />
            </geometry>
            <material name="Blue">
                <color rgba="0 0.0 1.0 1.0"/>
            </material>
        </visual>
        <collision>
            <origin xyz="0.15 0.0 0.0" rpy="0 0 0"/>
            <geometry>
                <box size="0.3 0.5 0.3" />
            </geometry>
        </collision>
    </link>
    <joint name="000_010" type="revolute">
       <parent link="000"/>
       <child  link="010"/>
       <origin rpy="0 0 0" xyz="0.3 0.0 -0.0" />
     <axis xyz="1 0 0"/>
       <limit effort="0.0" lower="-3.14159" upper="3.14159" velocity="0.0"/>
    </joint>
    <link name="010">
        <inertial>
            <origin xyz="0.15 0.0 -0.0" rpy="0 0 0"/>
            <mass value="1" />
            <inertia ixx="100" ixy="0" ixz="0" iyy="100" iyz="0" izz="100" />
        </inertial>
        <visual>
            <origin xyz="0.15 0.0 -0.0" rpy="0 0 0"/>
            <geometry>
                <box size="0.3 0.5 0.3" />
            </geometry>
            <material name="Blue">
                <color rgba="0 0.0 1.0 1.0"/>
            </material>
        </visual>
        <collision>
            <origin xyz="0.15 0.0 -0.0" rpy="0 0 0"/>
            <geometry>
                <box size="0.3 0.5 0.3" />
            </geometry>
        </collision>
    </link>
    <joint name="010_020" type="revolute">
       <parent link="010"/>
       <child  link="020"/>
       <origin rpy="0 0 0" xyz="0.3 0.0 -0.0" />
     <axis xyz="1 0 0"/>
       <limit effort="0.0" lower="-3.14159" upper="3.14159" velocity="0.0"/>
    </joint>
    <link name="020">
        <inertial>
            <origin xyz="0.15 0.0 -0.0" rpy="0 0 0"/>
            <mass value="1" />
            <inertia ixx="100" ixy="0" ixz="0" iyy="100" iyz="0" izz="100" />
        </inertial>
        <visual>
            <origin xyz="0.15 0.0 -0.0" rpy="0 0 0"/>
            <geometry>
                <box size="0.3 0.5 0.3" />
            </geometry>
            <material name="Blue">
                <color rgba="0 0.0 1.0 1.0"/>
            </material>
        </visual>
        <collision>
            <origin xyz="0.15 0.0 -0.0" rpy="0 0 0"/>
            <geometry>
                <box size="0.3 0.5 0.3" />
            </geometry>
        </collision>
    </link>
    <joint name="020_020-100" type="revolute">
       <parent link="020"/>
       <child  link="020-100"/>
       <origin rpy="0 0 0" xyz="0.15 0.0 -0.15" />
     <axis xyz="0 0 1"/>
       <limit effort="0.0" lower="-3.14159" upper="3.14159" velocity="0.0"/>
    </joint>
    <link name="020-100">
        <inertial>
            <origin xyz="0.0 0.0 -0.25" rpy="0 0 0"/>
            <mass value="1" />
            <inertia ixx="100" ixy="0" ixz="0" iyy="100" iyz="0" izz="100" />
        </inertial>
        <visual>
            <origin xyz="0.0 0.0 -0.25" rpy="0 0 0"/>
            <geometry>
                <box size="0.6 0.4 0.5" />
            </geometry>
            <material name="Green">
                <color rgba="0 1.0 0.0 1.0"/>
            </material>
        </visual>
        <collision>
            <origin xyz="0.0 0.0 -0.25" rpy="0 0 0"/>
            <geometry>
                <box size="0.6 0.4 0.5" />
            </geometry>
        </collision>
    </link>
    <joint name="020-100_020-110" type="revolute">
       <parent link="020-100"/>
       <child  link="020-110"/>
       <origin rpy="0 0 0" xyz="0.0 0.0 -0.5" />
     <axis xyz="0 0 1"/>
       <limit effort="0.0" lower="-3.14159" upper="3.14159" velocity="0.0"/>
    </joint>
    <link name="020-110">
        <inertial>
            <origin xyz="0.0 0.0 -0.25" rpy="0 0 0"/>
            <mass value="1" />
            <inertia ixx="100" ixy="0" ixz="0" iyy="100" iyz="0" izz="100" />
        </inertial>
        <visual>
            <origin xyz="0.0 0.0 -0.25" rpy="0 0 0"/>
            <geometry>
                <box size="0.6 0.4 0.5" />
            </geometry>
            <material name="Green">
                <color rgba="0 1.0 0.0 1.0"/>
            </material>
        </visual>
        <collision>
            <origin xyz="0.0 0.0 -0.25" rpy="0 0 0"/>
            <geometry>
                <box size="0.6 0.4 0.5" />
            </geometry>
        </collision>
    </link>
    <joint name="020-100_020-100-200" type="revolute">
       <parent link="020-100"/>
       <child  link="020-100-200"/>
       <origin rpy="0 0 0" xyz="0.0 0.2 -0.25" />
     <axis xyz="0 1 0"/>
       <limit effort="0.0" lower="-3.14159" upper="3.14159" velocity="0.0"/>
    </joint>
    <link name="020-100-200">
        <inertial>
            <origin xyz="0.0 0.05 -0.0" rpy="0 0 0"/>
            <mass value="1" />
            <inertia ixx="100" ixy="0" ixz="0" iyy="100" iyz="0" izz="100" />
        </inertial>
        <visual>
            <origin xyz="0.0 0.05 -0.0" rpy="0 0 0"/>
            <geometry>
                <box size="0.2 0.1 0.7" />
            </geometry>
            <material name="Blue">
                <color rgba="0 0.0 1.0 1.0"/>
            </material>
        </visual>
        <collision>
            <origin xyz="0.0 0.05 -0.0" rpy="0 0 0"/>
            <geometry>
                <box size="0.2 0.1 0.7" />
            </geometry>
        </collision>
    </link>
    <joint name="020-100-200_020-100-210" type="revolute">
       <parent link="020-100-200"/>
       <child  link="020-100-210"/>
       <origin rpy="0 0 0" xyz="0.0 0.1 -0.0" />
     <axis xyz="0 1 0"/>
       <limit effort="0.0" lower="-3.14159" upper="3.14159" velocity="0.0"/>
    </joint>
    <link name="020-100-210">
        <inertial>
            <origin xyz="0.0 0.05 -0.0" rpy="0 0 0"/>
            <mass value="1" />
            <inertia ixx="100" ixy="0" ixz="0" iyy="100" iyz="0" izz="100" />
        </inertial>
        <visual>
            <origin xyz="0.0 0.05 -0.0" rpy="0 0 0"/>
            <geometry>
                <box size="0.2 0.1 0.7" />
            </geometry>
            <material name="Blue">
                <color rgba="0 0.0 1.0 1.0"/>
            </material>
        </visual>
        <collision>
            <origin xyz="0.0 0.05 -0.0" rpy="0 0 0"/>
            <geometry>
                <box size="0.2 0.1 0.7" />
            </geometry>
        </collision>
    </link>
    <joint name="020-100-210_020-100-220" type="revolute">
       <parent link="020-100-210"/>
       <child  link="020-100-220"/>
       <origin rpy="0 0 0" xyz="0.0 0.1 -0.0" />
     <axis xyz="0 1 0"/>
       <limit effort="0.0" lower="-3.14159" upper="3.14159" velocity="0.0"/>
    </joint>
    <link name="020-100-220">
        <inertial>
            <origin xyz="0.0 0.05 -0.0" rpy="0 0 0"/>
            <mass value="1" />
            <inertia ixx="100" ixy="0" ixz="0" iyy="100" iyz="0" izz="100" />
        </inertial>
        <visual>
            <origin xyz="0.0 0.05 -0.0" rpy="0 0 0"/>
            <geometry>
                <box size="0.2 0.1 0.7" />
            </geometry>
            <material name="Blue">
                <color rgba="0 0.0 1.0 1.0"/>
            </material>
        </visual>
        <collision>
            <origin xyz="0.0 0.05 -0.0" rpy="0 0 0"/>
            <geometry>
                <box size="0.2 0.1 0.7" />
            </geometry>
        </collision>
    </link>
    <joint name="020-100-220_020-100-220-300" type="revolute">
       <parent link="020-100-220"/>
       <child  link="020-100-220-300"/>
       <origin rpy="0 0 0" xyz="0.1 0.05 -0.0" />
     <axis xyz="1 0 0"/>
       <limit effort="0.0" lower="-3.14159" upper="3.14159" velocity="0.0"/>
    </joint>
    <link name="020-100-220-300">
        <inertial>
            <origin xyz="0.25 0.0 -0.0" rpy="0 0 0"/>
            <mass value="1" />
            <inertia ixx="100" ixy="0" ixz="0" iyy="100" iyz="0" izz="100" />
        </inertial>
        <visual>
            <origin xyz="0.25 0.0 -0.0" rpy="0 0 0"/>
            <geometry>
                <box size="0.5 0.3 0.5" />
            </geometry>
            <material name="Blue">
                <color rgba="0 0.0 1.0 1.0"/>
            </material>
        </visual>
        <collision>
            <origin xyz="0.25 0.0 -0.0" rpy="0 0 0"/>
            <geometry>
                <box size="0.5 0.3 0.5" />
            </geometry>
        </collision>
    </link>
    <joint name="020-100-220-300_020-100-220-310" type="revolute">
       <parent link="020-100-220-300"/>
       <child  link="020-100-220-310"/>
       <origin rpy="0 0 0" xyz="0.5 0.0 -0.0" />
     <axis xyz="1 0 0"/>
       <limit effort="0.0" lower="-3.14159" upper="3.14159" velocity="0.0"/>
    </joint>
    <link name="020-100-220-310">
        <inertial>
            <origin xyz="0.25 0.0 -0.0" rpy="0 0 0"/>
            <mass value="1" />
            <inertia ixx="100" ixy="0" ixz="0" iyy="100" iyz="0" izz="100" />
        </inertial>
        <visual>
            <origin xyz="0.25 0.0 -0.0" rpy="0 0 0"/>
            <geometry>
                <box size="0.5 0.3 0.5" />
            </geometry>
            <material name="Blue">
                <color rgba="0 0.0 1.0 1.0"/>
            </material>
        </visual>
        <collision>
            <origin xyz="0.25 0.0 -0.0" rpy="0 0 0"/>
            <geometry>
                <box size="0.5 0.3 0.5" />
            </geometry>
        </collision>
    </link>
    <joint name="000_000-100" type="revolute">
       <parent link="000"/>
       <child  link="000-100"/>
       <origin rpy="0 0 0" xyz="0.15 0.0 -0.15" />
     <axis xyz="0 0 1"/>
       <limit effort="0.0" lower="-3.14159" upper="3.14159" velocity="0.0"/>
    </joint>
    <link name="000-100">
        <inertial>
            <origin xyz="0.0 0.0 -0.25" rpy="0 0 0"/>
            <mass value="1" />
            <inertia ixx="100" ixy="0" ixz="0" iyy="100" iyz="0" izz="100" />
        </inertial>
        <visual>
            <origin xyz="0.0 0.0 -0.25" rpy="0 0 0"/>
            <geometry>
                <box size="0.6 0.4 0.5" />
            </geometry>
            <material name="Green">
                <color rgba="0 1.0 0.0 1.0"/>
            </material>
        </visual>
        <collision>
            <origin xyz="0.0 0.0 -0.25" rpy="0 0 0"/>
            <geometry>
                <box size="0.6 0.4 0.5" />
            </geometry>
        </collision>
    </link>
    <joint name="000-100_000-110" type="revolute">
       <parent link="000-100"/>
       <child  link="000-110"/>
       <origin rpy="0 0 0" xyz="0.0 0.0 -0.5" />
     <axis xyz="0 0 1"/>
       <limit effort="0.0" lower="-3.14159" upper="3.14159" velocity="0.0"/>
    </joint>
    <link name="000-110">
        <inertial>
            <origin xyz="0.0 0.0 -0.25" rpy="0 0 0"/>
            <mass value="1" />
            <inertia ixx="100" ixy="0" ixz="0" iyy="100" iyz="0" izz="100" />
        </inertial>
        <visual>
            <origin xyz="0.0 0.0 -0.25" rpy="0 0 0"/>
            <geometry>
                <box size="0.6 0.4 0.5" />
            </geometry>
            <material name="Green">
                <color rgba="0 1.0 0.0 1.0"/>
            </material>
        </visual>
        <collision>
            <origin xyz="0.0 0.0 -0.25" rpy="0 0 0"/>
            <geometry>
                <box size="0.6 0.4 0.5" />
            </geometry>
        </collision>
    </link>
    <joint name="000-100_000-100-200" type="revolute">
       <parent link="000-100"/>
       <child  link="000-100-200"/>
       <origin rpy="0 0 0" xyz="0.0 0.2 -0.25" />
     <axis xyz="0 1 0"/>
       <limit effort="0.0" lower="-3.14159" upper="3.14159" velocity="0.0"/>
    </joint>
    <link name="000-100-200">
        <inertial>
            <origin xyz="0.0 0.05 -0.0" rpy="0 0 0"/>
            <mass value="1" />
            <inertia ixx="100" ixy="0" ixz="0" iyy="100" iyz="0" izz="100" />
        </inertial>
        <visual>
            <origin xyz="0.0 0.05 -0.0" rpy="0 0 0"/>
            <geometry>
                <box size="0.2 0.1 0.7" />
            </geometry>
            <material name="Blue">
                <color rgba="0 0.0 1.0 1.0"/>
            </material>
        </visual>
        <collision>
            <origin xyz="0.0 0.05 -0.0" rpy="0 0 0"/>
            <geometry>
                <box size="0.2 0.1 0.7" />
            </geometry>
        </collision>
    </link>
    <joint name="000-100-200_000-100-210" type="revolute">
       <parent link="000-100-200"/>
       <child  link="000-100-210"/>
       <origin rpy="0 0 0" xyz="0.0 0.1 -0.0" />
     <axis xyz="0 1 0"/>
       <limit effort="0.0" lower="-3.14159" upper="3.14159" velocity="0.0"/>
    </joint>
    <link name="000-100-210">
        <inertial>
            <origin xyz="0.0 0.05 -0.0" rpy="0 0 0"/>
            <mass value="1" />
            <inertia ixx="100" ixy="0" ixz="0" iyy="100" iyz="0" izz="100" />
        </inertial>
        <visual>
            <origin xyz="0.0 0.05 -0.0" rpy="0 0 0"/>
            <geometry>
                <box size="0.2 0.1 0.7" />
            </geometry>
            <material name="Blue">
                <color rgba="0 0.0 1.0 1.0"/>
            </material>
        </visual>
        <collision>
            <origin xyz="0.0 0.05 -0.0" rpy="0 0 0"/>
            <geometry>
                <box size="0.2 0.1 0.7" />
            </geometry>
        </collision>
    </link>
    <joint name="000-100-210_000-100-220" type="revolute">
       <parent link="000-100-210"/>
       <child  link="000-100-220"/>
       <origin rpy="0 0 0" xyz="0.0 0.1 -0.0" />
     <axis xyz="0 1 0"/>
       <limit effort="0.0" lower="-3.14159" upper="3.14159" velocity="0.0"/>
    </joint>
    <link name="000-100-220">
        <inertial>
            <origin xyz="0.0 0.05 -0.0" rpy="0 0 0"/>
            <mass value="1" />
            <inertia ixx="100" ixy="0" ixz="0" iyy="100" iyz="0" izz="100" />
        </inertial>
        <visual>
            <origin xyz="0.0 0.05 -0.0" rpy="0 0 0"/>
            <geometry>
                <box size="0.2 0.1 0.7" />
            </geometry>
            <material name="Blue">
                <color rgba="0 0.0 1.0 1.0"/>
            </material>
        </visual>
        <collision>
            <origin xyz="0.0 0.05 -0.0" rpy="0 0 0"/>
            <geometry>
                <box size="0.2 0.1 0.7" />
            </geometry>
        </collision>
    </link>
    <joint name="000-100-220_000-100-220-300" type="revolute">
       <parent link="000-100-220"/>
       <child  link="000-100-220-300"/>
       <origin rpy="0 0 0" xyz="0.1 0.05 -0.0" />
     <axis xyz="1 0 0"/>
       <limit effort="0.0" lower="-3.14159" upper="3.14159" velocity="0.0"/>
    </joint>
    <link name="000-100-220-300">
        <inertial>
            <origin xyz="0.25 0.0 -0.0" rpy="0 0 0"/>
            <mass value="1" />
            <inertia ixx="100" ixy="0" ixz="0" iyy="100" iyz="0" izz="100" />
        </inertial>
        <visual>
            <origin xyz="0.25 0.0 -0.0" rpy="0 0 0"/>
            <geometry>
                <box size="0.5 0.3 0.5" />
            </geometry>
            <material name="Blue">
                <color rgba="0 0.0 1.0 1.0"/>
            </material>
        </visual>
        <collision>
            <origin xyz="0.25 0.0 -0.0" rpy="0 0 0"/>
            <geometry>
                <box size="0.5 0.3 0.5" />
            </geometry>
        </collision>
    </link>
</robot>