<robot name = "robot">
    <link name="root">
        <inertial>
            <origin xyz="0.0 0.0 1.5" rpy="0 0 0"/>
            <mass value="1" />
            <inertia ixx="100" ixy="0" ixz="0" iyy="100" iyz="0" izz="100" />
        </inertial>
        <visual>
            <origin xyz="0.0 0.0 1.5" rpy="0 0 0"/>
            <geometry>
                <box size="0 0 0.0001" />
            </geometry>
            <material name="Green">
                <color rgba="0 1.0 0.0 1.0"/>
            </material>
        </visual>
        <collision>
            <origin xyz="0.0 0.0 1.5" rpy="0 0 0"/>
            <geometry>
                <box size="0 0 0.0001" />
            </geometry>
        </collision>
    </link>
    <joint name="root_000" type="revolute">
       <parent link="root"/>
       <child  link="000"/>
       <origin rpy="0 0 0" xyz="0.0 0.0 1.5" />
     <axis xyz="1 0 0"/>
       <limit effort="0.0" lower="-3.14159" upper="3.14159" velocity="0.0"/>
    </joint>
    <link name="000">
        <inertial>
            <origin xyz="0.0 0.0 -0.2" rpy="0 0 0"/>
            <mass value="1" />
            <inertia ixx="100" ixy="0" ixz="0" iyy="100" iyz="0" izz="100" />
        </inertial>
        <visual>
            <origin xyz="0.0 0.0 -0.2" rpy="0 0 0"/>
            <geometry>
                <box size="0.2 0.4 0.4" />
            </geometry>
            <material name="Green">
                <color rgba="0 1.0 0.0 1.0"/>
            </material>
        </visual>
        <collision>
            <origin xyz="0.0 0.0 -0.2" rpy="0 0 0"/>
            <geometry>
                <box size="0.2 0.4 0.4" />
            </geometry>
        </collision>
    </link>
    <joint name="000_000-100" type="revolute">
       <parent link="000"/>
       <child  link="000-100"/>
       <origin rpy="0 0 0" xyz="0.1 0.0 -0.2" />
     <axis xyz="1 0 0"/>
       <limit effort="0.0" lower="-3.14159" upper="3.14159" velocity="0.0"/>
    </joint>
    <link name="000-100">
        <inertial>
            <origin xyz="0.2 0.0 -0.0" rpy="0 0 0"/>
            <mass value="1" />
            <inertia ixx="100" ixy="0" ixz="0" iyy="100" iyz="0" izz="100" />
        </inertial>
        <visual>
            <origin xyz="0.2 0.0 -0.0" rpy="0 0 0"/>
            <geometry>
                <box size="0.4 0.5 0.5" />
            </geometry>
            <material name="Blue">
                <color rgba="0 0.0 1.0 1.0"/>
            </material>
        </visual>
        <collision>
            <origin xyz="0.2 0.0 -0.0" rpy="0 0 0"/>
            <geometry>
                <box size="0.4 0.5 0.5" />
            </geometry>
        </collision>
    </link>
    <joint name="000-100_000-110" type="revolute">
       <parent link="000-100"/>
       <child  link="000-110"/>
       <origin rpy="0 0 0" xyz="0.4 0.0 -0.0" />
     <axis xyz="1 0 0"/>
       <limit effort="0.0" lower="-3.14159" upper="3.14159" velocity="0.0"/>
    </joint>
    <link name="000-110">
        <inertial>
            <origin xyz="0.2 0.0 -0.0" rpy="0 0 0"/>
            <mass value="1" />
            <inertia ixx="100" ixy="0" ixz="0" iyy="100" iyz="0" izz="100" />
        </inertial>
        <visual>
            <origin xyz="0.2 0.0 -0.0" rpy="0 0 0"/>
            <geometry>
                <box size="0.4 0.5 0.5" />
            </geometry>
            <material name="Blue">
                <color rgba="0 0.0 1.0 1.0"/>
            </material>
        </visual>
        <collision>
            <origin xyz="0.2 0.0 -0.0" rpy="0 0 0"/>
            <geometry>
                <box size="0.4 0.5 0.5" />
            </geometry>
        </collision>
    </link>
    <joint name="000-110_000-110-200" type="revolute">
       <parent link="000-110"/>
       <child  link="000-110-200"/>
       <origin rpy="0 0 0" xyz="0.2 0.25 -0.0" />
     <axis xyz="0 1 0"/>
       <limit effort="0.0" lower="-3.14159" upper="3.14159" velocity="0.0"/>
    </joint>
    <link name="000-110-200">
        <inertial>
            <origin xyz="0.0 0.35 -0.0" rpy="0 0 0"/>
            <mass value="1" />
            <inertia ixx="100" ixy="0" ixz="0" iyy="100" iyz="0" izz="100" />
        </inertial>
        <visual>
            <origin xyz="0.0 0.35 -0.0" rpy="0 0 0"/>
            <geometry>
                <box size="0.6 0.7 0.7" />
            </geometry>
            <material name="Green">
                <color rgba="0 1.0 0.0 1.0"/>
            </material>
        </visual>
        <collision>
            <origin xyz="0.0 0.35 -0.0" rpy="0 0 0"/>
            <geometry>
                <box size="0.6 0.7 0.7" />
            </geometry>
        </collision>
    </link>
    <joint name="000-110-200_000-110-210" type="revolute">
       <parent link="000-110-200"/>
       <child  link="000-110-210"/>
       <origin rpy="0 0 0" xyz="0.0 0.7 -0.0" />
     <axis xyz="0 1 0"/>
       <limit effort="0.0" lower="-3.14159" upper="3.14159" velocity="0.0"/>
    </joint>
    <link name="000-110-210">
        <inertial>
            <origin xyz="0.0 0.35 -0.0" rpy="0 0 0"/>
            <mass value="1" />
            <inertia ixx="100" ixy="0" ixz="0" iyy="100" iyz="0" izz="100" />
        </inertial>
        <visual>
            <origin xyz="0.0 0.35 -0.0" rpy="0 0 0"/>
            <geometry>
                <box size="0.6 0.7 0.7" />
            </geometry>
            <material name="Green">
                <color rgba="0 1.0 0.0 1.0"/>
            </material>
        </visual>
        <collision>
            <origin xyz="0.0 0.35 -0.0" rpy="0 0 0"/>
            <geometry>
                <box size="0.6 0.7 0.7" />
            </geometry>
        </collision>
    </link>
    <joint name="000-110-210_000-110-210-300" type="revolute">
       <parent link="000-110-210"/>
       <child  link="000-110-210-300"/>
       <origin rpy="0 0 0" xyz="0.0 0.7 -0.0" />
     <axis xyz="0 1 0"/>
       <limit effort="0.0" lower="-3.14159" upper="3.14159" velocity="0.0"/>
    </joint>
    <link name="000-110-210-300">
        <inertial>
            <origin xyz="0.0 0.15 -0.0" rpy="0 0 0"/>
            <mass value="1" />
            <inertia ixx="100" ixy="0" ixz="0" iyy="100" iyz="0" izz="100" />
        </inertial>
        <visual>
            <origin xyz="0.0 0.15 -0.0" rpy="0 0 0"/>
            <geometry>
                <box size="0.5 0.3 0.6" />
            </geometry>
            <material name="Green">
                <color rgba="0 1.0 0.0 1.0"/>
            </material>
        </visual>
        <collision>
            <origin xyz="0.0 0.15 -0.0" rpy="0 0 0"/>
            <geometry>
                <box size="0.5 0.3 0.6" />
            </geometry>
        </collision>
    </link>
    <joint name="000-110-210-300_000-110-210-310" type="revolute">
       <parent link="000-110-210-300"/>
       <child  link="000-110-210-310"/>
       <origin rpy="0 0 0" xyz="0.0 0.3 -0.0" />
     <axis xyz="0 1 0"/>
       <limit effort="0.0" lower="-3.14159" upper="3.14159" velocity="0.0"/>
    </joint>
    <link name="000-110-210-310">
        <inertial>
            <origin xyz="0.0 0.15 -0.0" rpy="0 0 0"/>
            <mass value="1" />
            <inertia ixx="100" ixy="0" ixz="0" iyy="100" iyz="0" izz="100" />
        </inertial>
        <visual>
            <origin xyz="0.0 0.15 -0.0" rpy="0 0 0"/>
            <geometry>
                <box size="0.5 0.3 0.6" />
            </geometry>
            <material name="Green">
                <color rgba="0 1.0 0.0 1.0"/>
            </material>
        </visual>
        <collision>
            <origin xyz="0.0 0.15 -0.0" rpy="0 0 0"/>
            <geometry>
                <box size="0.5 0.3 0.6" />
            </geometry>
        </collision>
    </link>
    <joint name="000-110_000-110-201" type="revolute">
       <parent link="000-110"/>
       <child  link="000-110-201"/>
       <origin rpy="0 0 0" xyz="0.2 -0.25 -0.0" />
     <axis xyz="0 1 0"/>
       <limit effort="0.0" lower="-3.14159" upper="3.14159" velocity="0.0"/>
    </joint>
    <link name="000-110-201">
        <inertial>
            <origin xyz="0.0 -0.35 -0.0" rpy="0 0 0"/>
            <mass value="1" />
            <inertia ixx="100" ixy="0" ixz="0" iyy="100" iyz="0" izz="100" />
        </inertial>
        <visual>
            <origin xyz="0.0 -0.35 -0.0" rpy="0 0 0"/>
            <geometry>
                <box size="0.6 0.7 0.7" />
            </geometry>
            <material name="Green">
                <color rgba="0 1.0 0.0 1.0"/>
            </material>
        </visual>
        <collision>
            <origin xyz="0.0 -0.35 -0.0" rpy="0 0 0"/>
            <geometry>
                <box size="0.6 0.7 0.7" />
            </geometry>
        </collision>
    </link>
    <joint name="000-110-201_000-110-211" type="revolute">
       <parent link="000-110-201"/>
       <child  link="000-110-211"/>
       <origin rpy="0 0 0" xyz="0.0 -0.7 -0.0" />
     <axis xyz="0 1 0"/>
       <limit effort="0.0" lower="-3.14159" upper="3.14159" velocity="0.0"/>
    </joint>
    <link name="000-110-211">
        <inertial>
            <origin xyz="0.0 -0.35 -0.0" rpy="0 0 0"/>
            <mass value="1" />
            <inertia ixx="100" ixy="0" ixz="0" iyy="100" iyz="0" izz="100" />
        </inertial>
        <visual>
            <origin xyz="0.0 -0.35 -0.0" rpy="0 0 0"/>
            <geometry>
                <box size="0.6 0.7 0.7" />
            </geometry>
            <material name="Green">
                <color rgba="0 1.0 0.0 1.0"/>
            </material>
        </visual>
        <collision>
            <origin xyz="0.0 -0.35 -0.0" rpy="0 0 0"/>
            <geometry>
                <box size="0.6 0.7 0.7" />
            </geometry>
        </collision>
    </link>
    <joint name="000-110-211_000-110-211-300" type="revolute">
       <parent link="000-110-211"/>
       <child  link="000-110-211-300"/>
       <origin rpy="0 0 0" xyz="0.0 -0.7 -0.0" />
     <axis xyz="0 1 0"/>
       <limit effort="0.0" lower="-3.14159" upper="3.14159" velocity="0.0"/>
    </joint>
    <link name="000-110-211-300">
        <inertial>
            <origin xyz="0.0 -0.15 -0.0" rpy="0 0 0"/>
            <mass value="1" />
            <inertia ixx="100" ixy="0" ixz="0" iyy="100" iyz="0" izz="100" />
        </inertial>
        <visual>
            <origin xyz="0.0 -0.15 -0.0" rpy="0 0 0"/>
            <geometry>
                <box size="0.5 0.3 0.6" />
            </geometry>
            <material name="Green">
                <color rgba="0 1.0 0.0 1.0"/>
            </material>
        </visual>
        <collision>
            <origin xyz="0.0 -0.15 -0.0" rpy="0 0 0"/>
            <geometry>
                <box size="0.5 0.3 0.6" />
            </geometry>
        </collision>
    </link>
    <joint name="000-110-211-300_000-110-211-310" type="revolute">
       <parent link="000-110-211-300"/>
       <child  link="000-110-211-310"/>
       <origin rpy="0 0 0" xyz="0.0 -0.3 -0.0" />
     <axis xyz="0 1 0"/>
       <limit effort="0.0" lower="-3.14159" upper="3.14159" velocity="0.0"/>
    </joint>
    <link name="000-110-211-310">
        <inertial>
            <origin xyz="0.0 -0.15 -0.0" rpy="0 0 0"/>
            <mass value="1" />
            <inertia ixx="100" ixy="0" ixz="0" iyy="100" iyz="0" izz="100" />
        </inertial>
        <visual>
            <origin xyz="0.0 -0.15 -0.0" rpy="0 0 0"/>
            <geometry>
                <box size="0.5 0.3 0.6" />
            </geometry>
            <material name="Green">
                <color rgba="0 1.0 0.0 1.0"/>
            </material>
        </visual>
        <collision>
            <origin xyz="0.0 -0.15 -0.0" rpy="0 0 0"/>
            <geometry>
                <box size="0.5 0.3 0.6" />
            </geometry>
        </collision>
    </link>
    <joint name="000-100_000-100-200" type="revolute">
       <parent link="000-100"/>
       <child  link="000-100-200"/>
       <origin rpy="0 0 0" xyz="0.2 0.25 -0.0" />
     <axis xyz="0 1 0"/>
       <limit effort="0.0" lower="-3.14159" upper="3.14159" velocity="0.0"/>
    </joint>
    <link name="000-100-200">
        <inertial>
            <origin xyz="0.0 0.35 -0.0" rpy="0 0 0"/>
            <mass value="1" />
            <inertia ixx="100" ixy="0" ixz="0" iyy="100" iyz="0" izz="100" />
        </inertial>
        <visual>
            <origin xyz="0.0 0.35 -0.0" rpy="0 0 0"/>
            <geometry>
                <box size="0.6 0.7 0.7" />
            </geometry>
            <material name="Green">
                <color rgba="0 1.0 0.0 1.0"/>
            </material>
        </visual>
        <collision>
            <origin xyz="0.0 0.35 -0.0" rpy="0 0 0"/>
            <geometry>
                <box size="0.6 0.7 0.7" />
            </geometry>
        </collision>
    </link>
    <joint name="000-100-200_000-100-210" type="revolute">
       <parent link="000-100-200"/>
       <child  link="000-100-210"/>
       <origin rpy="0 0 0" xyz="0.0 0.7 -0.0" />
     <axis xyz="0 1 0"/>
       <limit effort="0.0" lower="-3.14159" upper="3.14159" velocity="0.0"/>
    </joint>
    <link name="000-100-210">
        <inertial>
            <origin xyz="0.0 0.35 -0.0" rpy="0 0 0"/>
            <mass value="1" />
            <inertia ixx="100" ixy="0" ixz="0" iyy="100" iyz="0" izz="100" />
        </inertial>
        <visual>
            <origin xyz="0.0 0.35 -0.0" rpy="0 0 0"/>
            <geometry>
                <box size="0.6 0.7 0.7" />
            </geometry>
            <material name="Green">
                <color rgba="0 1.0 0.0 1.0"/>
            </material>
        </visual>
        <collision>
            <origin xyz="0.0 0.35 -0.0" rpy="0 0 0"/>
            <geometry>
                <box size="0.6 0.7 0.7" />
            </geometry>
        </collision>
    </link>
    <joint name="000-100-210_000-100-210-300" type="revolute">
       <parent link="000-100-210"/>
       <child  link="000-100-210-300"/>
       <origin rpy="0 0 0" xyz="0.0 0.7 -0.0" />
     <axis xyz="0 1 0"/>
       <limit effort="0.0" lower="-3.14159" upper="3.14159" velocity="0.0"/>
    </joint>
    <link name="000-100-210-300">
        <inertial>
            <origin xyz="0.0 0.15 -0.0" rpy="0 0 0"/>
            <mass value="1" />
            <inertia ixx="100" ixy="0" ixz="0" iyy="100" iyz="0" izz="100" />
        </inertial>
        <visual>
            <origin xyz="0.0 0.15 -0.0" rpy="0 0 0"/>
            <geometry>
                <box size="0.5 0.3 0.6" />
            </geometry>
            <material name="Green">
                <color rgba="0 1.0 0.0 1.0"/>
            </material>
        </visual>
        <collision>
            <origin xyz="0.0 0.15 -0.0" rpy="0 0 0"/>
            <geometry>
                <box size="0.5 0.3 0.6" />
            </geometry>
        </collision>
    </link>
    <joint name="000-100-210-300_000-100-210-310" type="revolute">
       <parent link="000-100-210-300"/>
       <child  link="000-100-210-310"/>
       <origin rpy="0 0 0" xyz="0.0 0.3 -0.0" />
     <axis xyz="0 1 0"/>
       <limit effort="0.0" lower="-3.14159" upper="3.14159" velocity="0.0"/>
    </joint>
    <link name="000-100-210-310">
        <inertial>
            <origin xyz="0.0 0.15 -0.0" rpy="0 0 0"/>
            <mass value="1" />
            <inertia ixx="100" ixy="0" ixz="0" iyy="100" iyz="0" izz="100" />
        </inertial>
        <visual>
            <origin xyz="0.0 0.15 -0.0" rpy="0 0 0"/>
            <geometry>
                <box size="0.5 0.3 0.6" />
            </geometry>
            <material name="Green">
                <color rgba="0 1.0 0.0 1.0"/>
            </material>
        </visual>
        <collision>
            <origin xyz="0.0 0.15 -0.0" rpy="0 0 0"/>
            <geometry>
                <box size="0.5 0.3 0.6" />
            </geometry>
        </collision>
    </link>
    <joint name="000-100_000-100-201" type="revolute">
       <parent link="000-100"/>
       <child  link="000-100-201"/>
       <origin rpy="0 0 0" xyz="0.2 -0.25 -0.0" />
     <axis xyz="0 1 0"/>
       <limit effort="0.0" lower="-3.14159" upper="3.14159" velocity="0.0"/>
    </joint>
    <link name="000-100-201">
        <inertial>
            <origin xyz="0.0 -0.35 -0.0" rpy="0 0 0"/>
            <mass value="1" />
            <inertia ixx="100" ixy="0" ixz="0" iyy="100" iyz="0" izz="100" />
        </inertial>
        <visual>
            <origin xyz="0.0 -0.35 -0.0" rpy="0 0 0"/>
            <geometry>
                <box size="0.6 0.7 0.7" />
            </geometry>
            <material name="Green">
                <color rgba="0 1.0 0.0 1.0"/>
            </material>
        </visual>
        <collision>
            <origin xyz="0.0 -0.35 -0.0" rpy="0 0 0"/>
            <geometry>
                <box size="0.6 0.7 0.7" />
            </geometry>
        </collision>
    </link>
    <joint name="000-100-201_000-100-211" type="revolute">
       <parent link="000-100-201"/>
       <child  link="000-100-211"/>
       <origin rpy="0 0 0" xyz="0.0 -0.7 -0.0" />
     <axis xyz="0 1 0"/>
       <limit effort="0.0" lower="-3.14159" upper="3.14159" velocity="0.0"/>
    </joint>
    <link name="000-100-211">
        <inertial>
            <origin xyz="0.0 -0.35 -0.0" rpy="0 0 0"/>
            <mass value="1" />
            <inertia ixx="100" ixy="0" ixz="0" iyy="100" iyz="0" izz="100" />
        </inertial>
        <visual>
            <origin xyz="0.0 -0.35 -0.0" rpy="0 0 0"/>
            <geometry>
                <box size="0.6 0.7 0.7" />
            </geometry>
            <material name="Green">
                <color rgba="0 1.0 0.0 1.0"/>
            </material>
        </visual>
        <collision>
            <origin xyz="0.0 -0.35 -0.0" rpy="0 0 0"/>
            <geometry>
                <box size="0.6 0.7 0.7" />
            </geometry>
        </collision>
    </link>
    <joint name="000-100-211_000-100-211-300" type="revolute">
       <parent link="000-100-211"/>
       <child  link="000-100-211-300"/>
       <origin rpy="0 0 0" xyz="0.0 -0.7 -0.0" />
     <axis xyz="0 1 0"/>
       <limit effort="0.0" lower="-3.14159" upper="3.14159" velocity="0.0"/>
    </joint>
    <link name="000-100-211-300">
        <inertial>
            <origin xyz="0.0 -0.15 -0.0" rpy="0 0 0"/>
            <mass value="1" />
            <inertia ixx="100" ixy="0" ixz="0" iyy="100" iyz="0" izz="100" />
        </inertial>
        <visual>
            <origin xyz="0.0 -0.15 -0.0" rpy="0 0 0"/>
            <geometry>
                <box size="0.5 0.3 0.6" />
            </geometry>
            <material name="Green">
                <color rgba="0 1.0 0.0 1.0"/>
            </material>
        </visual>
        <collision>
            <origin xyz="0.0 -0.15 -0.0" rpy="0 0 0"/>
            <geometry>
                <box size="0.5 0.3 0.6" />
            </geometry>
        </collision>
    </link>
    <joint name="000-100-211-300_000-100-211-310" type="revolute">
       <parent link="000-100-211-300"/>
       <child  link="000-100-211-310"/>
       <origin rpy="0 0 0" xyz="0.0 -0.3 -0.0" />
     <axis xyz="0 1 0"/>
       <limit effort="0.0" lower="-3.14159" upper="3.14159" velocity="0.0"/>
    </joint>
    <link name="000-100-211-310">
        <inertial>
            <origin xyz="0.0 -0.15 -0.0" rpy="0 0 0"/>
            <mass value="1" />
            <inertia ixx="100" ixy="0" ixz="0" iyy="100" iyz="0" izz="100" />
        </inertial>
        <visual>
            <origin xyz="0.0 -0.15 -0.0" rpy="0 0 0"/>
            <geometry>
                <box size="0.5 0.3 0.6" />
            </geometry>
            <material name="Green">
                <color rgba="0 1.0 0.0 1.0"/>
            </material>
        </visual>
        <collision>
            <origin xyz="0.0 -0.15 -0.0" rpy="0 0 0"/>
            <geometry>
                <box size="0.5 0.3 0.6" />
            </geometry>
        </collision>
    </link>
    <joint name="000_000-101" type="revolute">
       <parent link="000"/>
       <child  link="000-101"/>
       <origin rpy="0 0 0" xyz="-0.1 0.0 -0.2" />
     <axis xyz="1 0 0"/>
       <limit effort="0.0" lower="-3.14159" upper="3.14159" velocity="0.0"/>
    </joint>
    <link name="000-101">
        <inertial>
            <origin xyz="-0.2 0.0 -0.0" rpy="0 0 0"/>
            <mass value="1" />
            <inertia ixx="100" ixy="0" ixz="0" iyy="100" iyz="0" izz="100" />
        </inertial>
        <visual>
            <origin xyz="-0.2 0.0 -0.0" rpy="0 0 0"/>
            <geometry>
                <box size="0.4 0.5 0.5" />
            </geometry>
            <material name="Blue">
                <color rgba="0 0.0 1.0 1.0"/>
            </material>
        </visual>
        <collision>
            <origin xyz="-0.2 0.0 -0.0" rpy="0 0 0"/>
            <geometry>
                <box size="0.4 0.5 0.5" />
            </geometry>
        </collision>
    </link>
    <joint name="000-101_000-111" type="revolute">
       <parent link="000-101"/>
       <child  link="000-111"/>
       <origin rpy="0 0 0" xyz="-0.4 0.0 -0.0" />
     <axis xyz="1 0 0"/>
       <limit effort="0.0" lower="-3.14159" upper="3.14159" velocity="0.0"/>
    </joint>
    <link name="000-111">
        <inertial>
            <origin xyz="-0.2 0.0 -0.0" rpy="0 0 0"/>
            <mass value="1" />
            <inertia ixx="100" ixy="0" ixz="0" iyy="100" iyz="0" izz="100" />
        </inertial>
        <visual>
            <origin xyz="-0.2 0.0 -0.0" rpy="0 0 0"/>
            <geometry>
                <box size="0.4 0.5 0.5" />
            </geometry>
            <material name="Blue">
                <color rgba="0 0.0 1.0 1.0"/>
            </material>
        </visual>
        <collision>
            <origin xyz="-0.2 0.0 -0.0" rpy="0 0 0"/>
            <geometry>
                <box size="0.4 0.5 0.5" />
            </geometry>
        </collision>
    </link>
    <joint name="000-111_000-111-200" type="revolute">
       <parent link="000-111"/>
       <child  link="000-111-200"/>
       <origin rpy="0 0 0" xyz="-0.2 0.25 -0.0" />
     <axis xyz="0 1 0"/>
       <limit effort="0.0" lower="-3.14159" upper="3.14159" velocity="0.0"/>
    </joint>
    <link name="000-111-200">
        <inertial>
            <origin xyz="-0.0 0.35 -0.0" rpy="0 0 0"/>
            <mass value="1" />
            <inertia ixx="100" ixy="0" ixz="0" iyy="100" iyz="0" izz="100" />
        </inertial>
        <visual>
            <origin xyz="-0.0 0.35 -0.0" rpy="0 0 0"/>
            <geometry>
                <box size="0.6 0.7 0.7" />
            </geometry>
            <material name="Green">
                <color rgba="0 1.0 0.0 1.0"/>
            </material>
        </visual>
        <collision>
            <origin xyz="-0.0 0.35 -0.0" rpy="0 0 0"/>
            <geometry>
                <box size="0.6 0.7 0.7" />
            </geometry>
        </collision>
    </link>
    <joint name="000-111-200_000-111-210" type="revolute">
       <parent link="000-111-200"/>
       <child  link="000-111-210"/>
       <origin rpy="0 0 0" xyz="-0.0 0.7 -0.0" />
     <axis xyz="0 1 0"/>
       <limit effort="0.0" lower="-3.14159" upper="3.14159" velocity="0.0"/>
    </joint>
    <link name="000-111-210">
        <inertial>
            <origin xyz="-0.0 0.35 -0.0" rpy="0 0 0"/>
            <mass value="1" />
            <inertia ixx="100" ixy="0" ixz="0" iyy="100" iyz="0" izz="100" />
        </inertial>
        <visual>
            <origin xyz="-0.0 0.35 -0.0" rpy="0 0 0"/>
            <geometry>
                <box size="0.6 0.7 0.7" />
            </geometry>
            <material name="Green">
                <color rgba="0 1.0 0.0 1.0"/>
            </material>
        </visual>
        <collision>
            <origin xyz="-0.0 0.35 -0.0" rpy="0 0 0"/>
            <geometry>
                <box size="0.6 0.7 0.7" />
            </geometry>
        </collision>
    </link>
    <joint name="000-111-210_000-111-210-300" type="revolute">
       <parent link="000-111-210"/>
       <child  link="000-111-210-300"/>
       <origin rpy="0 0 0" xyz="-0.0 0.7 -0.0" />
     <axis xyz="0 1 0"/>
       <limit effort="0.0" lower="-3.14159" upper="3.14159" velocity="0.0"/>
    </joint>
    <link name="000-111-210-300">
        <inertial>
            <origin xyz="-0.0 0.15 -0.0" rpy="0 0 0"/>
            <mass value="1" />
            <inertia ixx="100" ixy="0" ixz="0" iyy="100" iyz="0" izz="100" />
        </inertial>
        <visual>
            <origin xyz="-0.0 0.15 -0.0" rpy="0 0 0"/>
            <geometry>
                <box size="0.5 0.3 0.6" />
            </geometry>
            <material name="Green">
                <color rgba="0 1.0 0.0 1.0"/>
            </material>
        </visual>
        <collision>
            <origin xyz="-0.0 0.15 -0.0" rpy="0 0 0"/>
            <geometry>
                <box size="0.5 0.3 0.6" />
            </geometry>
        </collision>
    </link>
    <joint name="000-111-210-300_000-111-210-310" type="revolute">
       <parent link="000-111-210-300"/>
       <child  link="000-111-210-310"/>
       <origin rpy="0 0 0" xyz="-0.0 0.3 -0.0" />
     <axis xyz="0 1 0"/>
       <limit effort="0.0" lower="-3.14159" upper="3.14159" velocity="0.0"/>
    </joint>
    <link name="000-111-210-310">
        <inertial>
            <origin xyz="-0.0 0.15 -0.0" rpy="0 0 0"/>
            <mass value="1" />
            <inertia ixx="100" ixy="0" ixz="0" iyy="100" iyz="0" izz="100" />
        </inertial>
        <visual>
            <origin xyz="-0.0 0.15 -0.0" rpy="0 0 0"/>
            <geometry>
                <box size="0.5 0.3 0.6" />
            </geometry>
            <material name="Green">
                <color rgba="0 1.0 0.0 1.0"/>
            </material>
        </visual>
        <collision>
            <origin xyz="-0.0 0.15 -0.0" rpy="0 0 0"/>
            <geometry>
                <box size="0.5 0.3 0.6" />
            </geometry>
        </collision>
    </link>
    <joint name="000-111_000-111-201" type="revolute">
       <parent link="000-111"/>
       <child  link="000-111-201"/>
       <origin rpy="0 0 0" xyz="-0.2 -0.25 -0.0" />
     <axis xyz="0 1 0"/>
       <limit effort="0.0" lower="-3.14159" upper="3.14159" velocity="0.0"/>
    </joint>
    <link name="000-111-201">
        <inertial>
            <origin xyz="-0.0 -0.35 -0.0" rpy="0 0 0"/>
            <mass value="1" />
            <inertia ixx="100" ixy="0" ixz="0" iyy="100" iyz="0" izz="100" />
        </inertial>
        <visual>
            <origin xyz="-0.0 -0.35 -0.0" rpy="0 0 0"/>
            <geometry>
                <box size="0.6 0.7 0.7" />
            </geometry>
            <material name="Green">
                <color rgba="0 1.0 0.0 1.0"/>
            </material>
        </visual>
        <collision>
            <origin xyz="-0.0 -0.35 -0.0" rpy="0 0 0"/>
            <geometry>
                <box size="0.6 0.7 0.7" />
            </geometry>
        </collision>
    </link>
    <joint name="000-111-201_000-111-211" type="revolute">
       <parent link="000-111-201"/>
       <child  link="000-111-211"/>
       <origin rpy="0 0 0" xyz="-0.0 -0.7 -0.0" />
     <axis xyz="0 1 0"/>
       <limit effort="0.0" lower="-3.14159" upper="3.14159" velocity="0.0"/>
    </joint>
    <link name="000-111-211">
        <inertial>
            <origin xyz="-0.0 -0.35 -0.0" rpy="0 0 0"/>
            <mass value="1" />
            <inertia ixx="100" ixy="0" ixz="0" iyy="100" iyz="0" izz="100" />
        </inertial>
        <visual>
            <origin xyz="-0.0 -0.35 -0.0" rpy="0 0 0"/>
            <geometry>
                <box size="0.6 0.7 0.7" />
            </geometry>
            <material name="Green">
                <color rgba="0 1.0 0.0 1.0"/>
            </material>
        </visual>
        <collision>
            <origin xyz="-0.0 -0.35 -0.0" rpy="0 0 0"/>
            <geometry>
                <box size="0.6 0.7 0.7" />
            </geometry>
        </collision>
    </link>
    <joint name="000-111-211_000-111-211-300" type="revolute">
       <parent link="000-111-211"/>
       <child  link="000-111-211-300"/>
       <origin rpy="0 0 0" xyz="-0.0 -0.7 -0.0" />
     <axis xyz="0 1 0"/>
       <limit effort="0.0" lower="-3.14159" upper="3.14159" velocity="0.0"/>
    </joint>
    <link name="000-111-211-300">
        <inertial>
            <origin xyz="-0.0 -0.15 -0.0" rpy="0 0 0"/>
            <mass value="1" />
            <inertia ixx="100" ixy="0" ixz="0" iyy="100" iyz="0" izz="100" />
        </inertial>
        <visual>
            <origin xyz="-0.0 -0.15 -0.0" rpy="0 0 0"/>
            <geometry>
                <box size="0.5 0.3 0.6" />
            </geometry>
            <material name="Green">
                <color rgba="0 1.0 0.0 1.0"/>
            </material>
        </visual>
        <collision>
            <origin xyz="-0.0 -0.15 -0.0" rpy="0 0 0"/>
            <geometry>
                <box size="0.5 0.3 0.6" />
            </geometry>
        </collision>
    </link>
    <joint name="000-111-211-300_000-111-211-310" type="revolute">
       <parent link="000-111-211-300"/>
       <child  link="000-111-211-310"/>
       <origin rpy="0 0 0" xyz="-0.0 -0.3 -0.0" />
     <axis xyz="0 1 0"/>
       <limit effort="0.0" lower="-3.14159" upper="3.14159" velocity="0.0"/>
    </joint>
    <link name="000-111-211-310">
        <inertial>
            <origin xyz="-0.0 -0.15 -0.0" rpy="0 0 0"/>
            <mass value="1" />
            <inertia ixx="100" ixy="0" ixz="0" iyy="100" iyz="0" izz="100" />
        </inertial>
        <visual>
            <origin xyz="-0.0 -0.15 -0.0" rpy="0 0 0"/>
            <geometry>
                <box size="0.5 0.3 0.6" />
            </geometry>
            <material name="Green">
                <color rgba="0 1.0 0.0 1.0"/>
            </material>
        </visual>
        <collision>
            <origin xyz="-0.0 -0.15 -0.0" rpy="0 0 0"/>
            <geometry>
                <box size="0.5 0.3 0.6" />
            </geometry>
        </collision>
    </link>
    <joint name="000-101_000-101-200" type="revolute">
       <parent link="000-101"/>
       <child  link="000-101-200"/>
       <origin rpy="0 0 0" xyz="-0.2 0.25 -0.0" />
     <axis xyz="0 1 0"/>
       <limit effort="0.0" lower="-3.14159" upper="3.14159" velocity="0.0"/>
    </joint>
    <link name="000-101-200">
        <inertial>
            <origin xyz="-0.0 0.35 -0.0" rpy="0 0 0"/>
            <mass value="1" />
            <inertia ixx="100" ixy="0" ixz="0" iyy="100" iyz="0" izz="100" />
        </inertial>
        <visual>
            <origin xyz="-0.0 0.35 -0.0" rpy="0 0 0"/>
            <geometry>
                <box size="0.6 0.7 0.7" />
            </geometry>
            <material name="Green">
                <color rgba="0 1.0 0.0 1.0"/>
            </material>
        </visual>
        <collision>
            <origin xyz="-0.0 0.35 -0.0" rpy="0 0 0"/>
            <geometry>
                <box size="0.6 0.7 0.7" />
            </geometry>
        </collision>
    </link>
    <joint name="000-101-200_000-101-210" type="revolute">
       <parent link="000-101-200"/>
       <child  link="000-101-210"/>
       <origin rpy="0 0 0" xyz="-0.0 0.7 -0.0" />
     <axis xyz="0 1 0"/>
       <limit effort="0.0" lower="-3.14159" upper="3.14159" velocity="0.0"/>
    </joint>
    <link name="000-101-210">
        <inertial>
            <origin xyz="-0.0 0.35 -0.0" rpy="0 0 0"/>
            <mass value="1" />
            <inertia ixx="100" ixy="0" ixz="0" iyy="100" iyz="0" izz="100" />
        </inertial>
        <visual>
            <origin xyz="-0.0 0.35 -0.0" rpy="0 0 0"/>
            <geometry>
                <box size="0.6 0.7 0.7" />
            </geometry>
            <material name="Green">
                <color rgba="0 1.0 0.0 1.0"/>
            </material>
        </visual>
        <collision>
            <origin xyz="-0.0 0.35 -0.0" rpy="0 0 0"/>
            <geometry>
                <box size="0.6 0.7 0.7" />
            </geometry>
        </collision>
    </link>
    <joint name="000-101-210_000-101-210-300" type="revolute">
       <parent link="000-101-210"/>
       <child  link="000-101-210-300"/>
       <origin rpy="0 0 0" xyz="-0.0 0.7 -0.0" />
     <axis xyz="0 1 0"/>
       <limit effort="0.0" lower="-3.14159" upper="3.14159" velocity="0.0"/>
    </joint>
    <link name="000-101-210-300">
        <inertial>
            <origin xyz="-0.0 0.15 -0.0" rpy="0 0 0"/>
            <mass value="1" />
            <inertia ixx="100" ixy="0" ixz="0" iyy="100" iyz="0" izz="100" />
        </inertial>
        <visual>
            <origin xyz="-0.0 0.15 -0.0" rpy="0 0 0"/>
            <geometry>
                <box size="0.5 0.3 0.6" />
            </geometry>
            <material name="Green">
                <color rgba="0 1.0 0.0 1.0"/>
            </material>
        </visual>
        <collision>
            <origin xyz="-0.0 0.15 -0.0" rpy="0 0 0"/>
            <geometry>
                <box size="0.5 0.3 0.6" />
            </geometry>
        </collision>
    </link>
    <joint name="000-101-210-300_000-101-210-310" type="revolute">
       <parent link="000-101-210-300"/>
       <child  link="000-101-210-310"/>
       <origin rpy="0 0 0" xyz="-0.0 0.3 -0.0" />
     <axis xyz="0 1 0"/>
       <limit effort="0.0" lower="-3.14159" upper="3.14159" velocity="0.0"/>
    </joint>
    <link name="000-101-210-310">
        <inertial>
            <origin xyz="-0.0 0.15 -0.0" rpy="0 0 0"/>
            <mass value="1" />
            <inertia ixx="100" ixy="0" ixz="0" iyy="100" iyz="0" izz="100" />
        </inertial>
        <visual>
            <origin xyz="-0.0 0.15 -0.0" rpy="0 0 0"/>
            <geometry>
                <box size="0.5 0.3 0.6" />
            </geometry>
            <material name="Green">
                <color rgba="0 1.0 0.0 1.0"/>
            </material>
        </visual>
        <collision>
            <origin xyz="-0.0 0.15 -0.0" rpy="0 0 0"/>
            <geometry>
                <box size="0.5 0.3 0.6" />
            </geometry>
        </collision>
    </link>
    <joint name="000-101_000-101-201" type="revolute">
       <parent link="000-101"/>
       <child  link="000-101-201"/>
       <origin rpy="0 0 0" xyz="-0.2 -0.25 -0.0" />
     <axis xyz="0 1 0"/>
       <limit effort="0.0" lower="-3.14159" upper="3.14159" velocity="0.0"/>
    </joint>
    <link name="000-101-201">
        <inertial>
            <origin xyz="-0.0 -0.35 -0.0" rpy="0 0 0"/>
            <mass value="1" />
            <inertia ixx="100" ixy="0" ixz="0" iyy="100" iyz="0" izz="100" />
        </inertial>
        <visual>
            <origin xyz="-0.0 -0.35 -0.0" rpy="0 0 0"/>
            <geometry>
                <box size="0.6 0.7 0.7" />
            </geometry>
            <material name="Green">
                <color rgba="0 1.0 0.0 1.0"/>
            </material>
        </visual>
        <collision>
            <origin xyz="-0.0 -0.35 -0.0" rpy="0 0 0"/>
            <geometry>
                <box size="0.6 0.7 0.7" />
            </geometry>
        </collision>
    </link>
    <joint name="000-101-201_000-101-211" type="revolute">
       <parent link="000-101-201"/>
       <child  link="000-101-211"/>
       <origin rpy="0 0 0" xyz="-0.0 -0.7 -0.0" />
     <axis xyz="0 1 0"/>
       <limit effort="0.0" lower="-3.14159" upper="3.14159" velocity="0.0"/>
    </joint>
    <link name="000-101-211">
        <inertial>
            <origin xyz="-0.0 -0.35 -0.0" rpy="0 0 0"/>
            <mass value="1" />
            <inertia ixx="100" ixy="0" ixz="0" iyy="100" iyz="0" izz="100" />
        </inertial>
        <visual>
            <origin xyz="-0.0 -0.35 -0.0" rpy="0 0 0"/>
            <geometry>
                <box size="0.6 0.7 0.7" />
            </geometry>
            <material name="Green">
                <color rgba="0 1.0 0.0 1.0"/>
            </material>
        </visual>
        <collision>
            <origin xyz="-0.0 -0.35 -0.0" rpy="0 0 0"/>
            <geometry>
                <box size="0.6 0.7 0.7" />
            </geometry>
        </collision>
    </link>
    <joint name="000-101-211_000-101-211-300" type="revolute">
       <parent link="000-101-211"/>
       <child  link="000-101-211-300"/>
       <origin rpy="0 0 0" xyz="-0.0 -0.7 -0.0" />
     <axis xyz="0 1 0"/>
       <limit effort="0.0" lower="-3.14159" upper="3.14159" velocity="0.0"/>
    </joint>
    <link name="000-101-211-300">
        <inertial>
            <origin xyz="-0.0 -0.15 -0.0" rpy="0 0 0"/>
            <mass value="1" />
            <inertia ixx="100" ixy="0" ixz="0" iyy="100" iyz="0" izz="100" />
        </inertial>
        <visual>
            <origin xyz="-0.0 -0.15 -0.0" rpy="0 0 0"/>
            <geometry>
                <box size="0.5 0.3 0.6" />
            </geometry>
            <material name="Green">
                <color rgba="0 1.0 0.0 1.0"/>
            </material>
        </visual>
        <collision>
            <origin xyz="-0.0 -0.15 -0.0" rpy="0 0 0"/>
            <geometry>
                <box size="0.5 0.3 0.6" />
            </geometry>
        </collision>
    </link>
    <joint name="000-101-211-300_000-101-211-310" type="revolute">
       <parent link="000-101-211-300"/>
       <child  link="000-101-211-310"/>
       <origin rpy="0 0 0" xyz="-0.0 -0.3 -0.0" />
     <axis xyz="0 1 0"/>
       <limit effort="0.0" lower="-3.14159" upper="3.14159" velocity="0.0"/>
    </joint>
    <link name="000-101-211-310">
        <inertial>
            <origin xyz="-0.0 -0.15 -0.0" rpy="0 0 0"/>
            <mass value="1" />
            <inertia ixx="100" ixy="0" ixz="0" iyy="100" iyz="0" izz="100" />
        </inertial>
        <visual>
            <origin xyz="-0.0 -0.15 -0.0" rpy="0 0 0"/>
            <geometry>
                <box size="0.5 0.3 0.6" />
            </geometry>
            <material name="Green">
                <color rgba="0 1.0 0.0 1.0"/>
            </material>
        </visual>
        <collision>
            <origin xyz="-0.0 -0.15 -0.0" rpy="0 0 0"/>
            <geometry>
                <box size="0.5 0.3 0.6" />
            </geometry>
        </collision>
    </link>
</robot>