<robot name = "robot">
    <link name="root">
        <inertial>
            <origin xyz="0.0 0.0 1.5" rpy="0 0 0"/>
            <mass value="1" />
            <inertia ixx="100" ixy="0" ixz="0" iyy="100" iyz="0" izz="100" />
        </inertial>
        <visual>
            <origin xyz="0.0 0.0 1.5" rpy="0 0 0"/>
            <geometry>
                <box size="0 0 0.0001" />
            </geometry>
            <material name="Green">
                <color rgba="0 1.0 0.0 1.0"/>
            </material>
        </visual>
        <collision>
            <origin xyz="0.0 0.0 1.5" rpy="0 0 0"/>
            <geometry>
                <box size="0 0 0.0001" />
            </geometry>
        </collision>
    </link>
    <joint name="root_000" type="revolute">
       <parent link="root"/>
       <child  link="000"/>
       <origin rpy="0 0 0" xyz="0.0 0.0 1.5" />
     <axis xyz="1 0 0"/>
       <limit effort="0.0" lower="-3.14159" upper="3.14159" velocity="0.0"/>
    </joint>
    <link name="000">
        <inertial>
            <origin xyz="0.0 0.2 0.0" rpy="0 0 0"/>
            <mass value="1" />
            <inertia ixx="100" ixy="0" ixz="0" iyy="100" iyz="0" izz="100" />
        </inertial>
        <visual>
            <origin xyz="0.0 0.2 0.0" rpy="0 0 0"/>
            <geometry>
                <box size="0.5 0.4 0.6" />
            </geometry>
            <material name="Blue">
                <color rgba="0 0.0 1.0 1.0"/>
            </material>
        </visual>
        <collision>
            <origin xyz="0.0 0.2 0.0" rpy="0 0 0"/>
            <geometry>
                <box size="0.5 0.4 0.6" />
            </geometry>
        </collision>
    </link>
    <joint name="000_010" type="revolute">
       <parent link="000"/>
       <child  link="010"/>
       <origin rpy="0 0 0" xyz="0.0 0.4 -0.0" />
     <axis xyz="0 1 0"/>
       <limit effort="0.0" lower="-3.14159" upper="3.14159" velocity="0.0"/>
    </joint>
    <link name="010">
        <inertial>
            <origin xyz="0.0 0.2 -0.0" rpy="0 0 0"/>
            <mass value="1" />
            <inertia ixx="100" ixy="0" ixz="0" iyy="100" iyz="0" izz="100" />
        </inertial>
        <visual>
            <origin xyz="0.0 0.2 -0.0" rpy="0 0 0"/>
            <geometry>
                <box size="0.5 0.4 0.6" />
            </geometry>
            <material name="Blue">
                <color rgba="0 0.0 1.0 1.0"/>
            </material>
        </visual>
        <collision>
            <origin xyz="0.0 0.2 -0.0" rpy="0 0 0"/>
            <geometry>
                <box size="0.5 0.4 0.6" />
            </geometry>
        </collision>
    </link>
    <joint name="010_010-100" type="revolute">
       <parent link="010"/>
       <child  link="010-100"/>
       <origin rpy="0 0 0" xyz="0.0 0.4 -0.0" />
     <axis xyz="0 1 0"/>
       <limit effort="0.0" lower="-3.14159" upper="3.14159" velocity="0.0"/>
    </joint>
    <link name="010-100">
        <inertial>
            <origin xyz="0.0 0.3 -0.0" rpy="0 0 0"/>
            <mass value="1" />
            <inertia ixx="100" ixy="0" ixz="0" iyy="100" iyz="0" izz="100" />
        </inertial>
        <visual>
            <origin xyz="0.0 0.3 -0.0" rpy="0 0 0"/>
            <geometry>
                <box size="0.4 0.6 0.6" />
            </geometry>
            <material name="Green">
                <color rgba="0 1.0 0.0 1.0"/>
            </material>
        </visual>
        <collision>
            <origin xyz="0.0 0.3 -0.0" rpy="0 0 0"/>
            <geometry>
                <box size="0.4 0.6 0.6" />
            </geometry>
        </collision>
    </link>
    <joint name="010-100_010-110" type="revolute">
       <parent link="010-100"/>
       <child  link="010-110"/>
       <origin rpy="0 0 0" xyz="0.0 0.6 -0.0" />
     <axis xyz="0 1 0"/>
       <limit effort="0.0" lower="-3.14159" upper="3.14159" velocity="0.0"/>
    </joint>
    <link name="010-110">
        <inertial>
            <origin xyz="0.0 0.3 -0.0" rpy="0 0 0"/>
            <mass value="1" />
            <inertia ixx="100" ixy="0" ixz="0" iyy="100" iyz="0" izz="100" />
        </inertial>
        <visual>
            <origin xyz="0.0 0.3 -0.0" rpy="0 0 0"/>
            <geometry>
                <box size="0.4 0.6 0.6" />
            </geometry>
            <material name="Green">
                <color rgba="0 1.0 0.0 1.0"/>
            </material>
        </visual>
        <collision>
            <origin xyz="0.0 0.3 -0.0" rpy="0 0 0"/>
            <geometry>
                <box size="0.4 0.6 0.6" />
            </geometry>
        </collision>
    </link>
    <joint name="010-110_010-120" type="revolute">
       <parent link="010-110"/>
       <child  link="010-120"/>
       <origin rpy="0 0 0" xyz="0.0 0.6 -0.0" />
     <axis xyz="0 1 0"/>
       <limit effort="0.0" lower="-3.14159" upper="3.14159" velocity="0.0"/>
    </joint>
    <link name="010-120">
        <inertial>
            <origin xyz="0.0 0.3 -0.0" rpy="0 0 0"/>
            <mass value="1" />
            <inertia ixx="100" ixy="0" ixz="0" iyy="100" iyz="0" izz="100" />
        </inertial>
        <visual>
            <origin xyz="0.0 0.3 -0.0" rpy="0 0 0"/>
            <geometry>
                <box size="0.4 0.6 0.6" />
            </geometry>
            <material name="Green">
                <color rgba="0 1.0 0.0 1.0"/>
            </material>
        </visual>
        <collision>
            <origin xyz="0.0 0.3 -0.0" rpy="0 0 0"/>
            <geometry>
                <box size="0.4 0.6 0.6" />
            </geometry>
        </collision>
    </link>
    <joint name="010-120_010-120-200" type="revolute">
       <parent link="010-120"/>
       <child  link="010-120-200"/>
       <origin rpy="0 0 0" xyz="0.2 0.3 -0.0" />
     <axis xyz="1 0 0"/>
       <limit effort="0.0" lower="-3.14159" upper="3.14159" velocity="0.0"/>
    </joint>
    <link name="010-120-200">
        <inertial>
            <origin xyz="0.1 0.0 -0.0" rpy="0 0 0"/>
            <mass value="1" />
            <inertia ixx="100" ixy="0" ixz="0" iyy="100" iyz="0" izz="100" />
        </inertial>
        <visual>
            <origin xyz="0.1 0.0 -0.0" rpy="0 0 0"/>
            <geometry>
                <box size="0.2 0.3 0.6" />
            </geometry>
            <material name="Blue">
                <color rgba="0 0.0 1.0 1.0"/>
            </material>
        </visual>
        <collision>
            <origin xyz="0.1 0.0 -0.0" rpy="0 0 0"/>
            <geometry>
                <box size="0.2 0.3 0.6" />
            </geometry>
        </collision>
    </link>
    <joint name="010-120-200_010-120-200-300" type="revolute">
       <parent link="010-120-200"/>
       <child  link="010-120-200-300"/>
       <origin rpy="0 0 0" xyz="0.1 0.15 -0.0" />
     <axis xyz="0 1 0"/>
       <limit effort="0.0" lower="-3.14159" upper="3.14159" velocity="0.0"/>
    </joint>
    <link name="010-120-200-300">
        <inertial>
            <origin xyz="0.0 0.2 -0.0" rpy="0 0 0"/>
            <mass value="1" />
            <inertia ixx="100" ixy="0" ixz="0" iyy="100" iyz="0" izz="100" />
        </inertial>
        <visual>
            <origin xyz="0.0 0.2 -0.0" rpy="0 0 0"/>
            <geometry>
                <box size="0.4 0.4 0.6" />
            </geometry>
            <material name="Green">
                <color rgba="0 1.0 0.0 1.0"/>
            </material>
        </visual>
        <collision>
            <origin xyz="0.0 0.2 -0.0" rpy="0 0 0"/>
            <geometry>
                <box size="0.4 0.4 0.6" />
            </geometry>
        </collision>
    </link>
    <joint name="010-120-200-300_010-120-200-310" type="revolute">
       <parent link="010-120-200-300"/>
       <child  link="010-120-200-310"/>
       <origin rpy="0 0 0" xyz="0.0 0.4 -0.0" />
     <axis xyz="0 1 0"/>
       <limit effort="0.0" lower="-3.14159" upper="3.14159" velocity="0.0"/>
    </joint>
    <link name="010-120-200-310">
        <inertial>
            <origin xyz="0.0 0.2 -0.0" rpy="0 0 0"/>
            <mass value="1" />
            <inertia ixx="100" ixy="0" ixz="0" iyy="100" iyz="0" izz="100" />
        </inertial>
        <visual>
            <origin xyz="0.0 0.2 -0.0" rpy="0 0 0"/>
            <geometry>
                <box size="0.4 0.4 0.6" />
            </geometry>
            <material name="Green">
                <color rgba="0 1.0 0.0 1.0"/>
            </material>
        </visual>
        <collision>
            <origin xyz="0.0 0.2 -0.0" rpy="0 0 0"/>
            <geometry>
                <box size="0.4 0.4 0.6" />
            </geometry>
        </collision>
    </link>
    <joint name="010-120-200-310_010-120-200-320" type="revolute">
       <parent link="010-120-200-310"/>
       <child  link="010-120-200-320"/>
       <origin rpy="0 0 0" xyz="0.0 0.4 -0.0" />
     <axis xyz="0 1 0"/>
       <limit effort="0.0" lower="-3.14159" upper="3.14159" velocity="0.0"/>
    </joint>
    <link name="010-120-200-320">
        <inertial>
            <origin xyz="0.0 0.2 -0.0" rpy="0 0 0"/>
            <mass value="1" />
            <inertia ixx="100" ixy="0" ixz="0" iyy="100" iyz="0" izz="100" />
        </inertial>
        <visual>
            <origin xyz="0.0 0.2 -0.0" rpy="0 0 0"/>
            <geometry>
                <box size="0.4 0.4 0.6" />
            </geometry>
            <material name="Green">
                <color rgba="0 1.0 0.0 1.0"/>
            </material>
        </visual>
        <collision>
            <origin xyz="0.0 0.2 -0.0" rpy="0 0 0"/>
            <geometry>
                <box size="0.4 0.4 0.6" />
            </geometry>
        </collision>
    </link>
    <joint name="010-120-200-320_010-120-200-330" type="revolute">
       <parent link="010-120-200-320"/>
       <child  link="010-120-200-330"/>
       <origin rpy="0 0 0" xyz="0.0 0.4 -0.0" />
     <axis xyz="0 1 0"/>
       <limit effort="0.0" lower="-3.14159" upper="3.14159" velocity="0.0"/>
    </joint>
    <link name="010-120-200-330">
        <inertial>
            <origin xyz="0.0 0.2 -0.0" rpy="0 0 0"/>
            <mass value="1" />
            <inertia ixx="100" ixy="0" ixz="0" iyy="100" iyz="0" izz="100" />
        </inertial>
        <visual>
            <origin xyz="0.0 0.2 -0.0" rpy="0 0 0"/>
            <geometry>
                <box size="0.4 0.4 0.6" />
            </geometry>
            <material name="Green">
                <color rgba="0 1.0 0.0 1.0"/>
            </material>
        </visual>
        <collision>
            <origin xyz="0.0 0.2 -0.0" rpy="0 0 0"/>
            <geometry>
                <box size="0.4 0.4 0.6" />
            </geometry>
        </collision>
    </link>
    <joint name="010-120_010-120-201" type="revolute">
       <parent link="010-120"/>
       <child  link="010-120-201"/>
       <origin rpy="0 0 0" xyz="-0.2 0.3 -0.0" />
     <axis xyz="1 0 0"/>
       <limit effort="0.0" lower="-3.14159" upper="3.14159" velocity="0.0"/>
    </joint>
    <link name="010-120-201">
        <inertial>
            <origin xyz="-0.1 0.0 -0.0" rpy="0 0 0"/>
            <mass value="1" />
            <inertia ixx="100" ixy="0" ixz="0" iyy="100" iyz="0" izz="100" />
        </inertial>
        <visual>
            <origin xyz="-0.1 0.0 -0.0" rpy="0 0 0"/>
            <geometry>
                <box size="0.2 0.3 0.6" />
            </geometry>
            <material name="Blue">
                <color rgba="0 0.0 1.0 1.0"/>
            </material>
        </visual>
        <collision>
            <origin xyz="-0.1 0.0 -0.0" rpy="0 0 0"/>
            <geometry>
                <box size="0.2 0.3 0.6" />
            </geometry>
        </collision>
    </link>
    <joint name="010-120-201_010-120-201-300" type="revolute">
       <parent link="010-120-201"/>
       <child  link="010-120-201-300"/>
       <origin rpy="0 0 0" xyz="-0.1 0.15 -0.0" />
     <axis xyz="0 1 0"/>
       <limit effort="0.0" lower="-3.14159" upper="3.14159" velocity="0.0"/>
    </joint>
    <link name="010-120-201-300">
        <inertial>
            <origin xyz="-0.0 0.2 -0.0" rpy="0 0 0"/>
            <mass value="1" />
            <inertia ixx="100" ixy="0" ixz="0" iyy="100" iyz="0" izz="100" />
        </inertial>
        <visual>
            <origin xyz="-0.0 0.2 -0.0" rpy="0 0 0"/>
            <geometry>
                <box size="0.4 0.4 0.6" />
            </geometry>
            <material name="Green">
                <color rgba="0 1.0 0.0 1.0"/>
            </material>
        </visual>
        <collision>
            <origin xyz="-0.0 0.2 -0.0" rpy="0 0 0"/>
            <geometry>
                <box size="0.4 0.4 0.6" />
            </geometry>
        </collision>
    </link>
    <joint name="010-120-201-300_010-120-201-310" type="revolute">
       <parent link="010-120-201-300"/>
       <child  link="010-120-201-310"/>
       <origin rpy="0 0 0" xyz="-0.0 0.4 -0.0" />
     <axis xyz="0 1 0"/>
       <limit effort="0.0" lower="-3.14159" upper="3.14159" velocity="0.0"/>
    </joint>
    <link name="010-120-201-310">
        <inertial>
            <origin xyz="-0.0 0.2 -0.0" rpy="0 0 0"/>
            <mass value="1" />
            <inertia ixx="100" ixy="0" ixz="0" iyy="100" iyz="0" izz="100" />
        </inertial>
        <visual>
            <origin xyz="-0.0 0.2 -0.0" rpy="0 0 0"/>
            <geometry>
                <box size="0.4 0.4 0.6" />
            </geometry>
            <material name="Green">
                <color rgba="0 1.0 0.0 1.0"/>
            </material>
        </visual>
        <collision>
            <origin xyz="-0.0 0.2 -0.0" rpy="0 0 0"/>
            <geometry>
                <box size="0.4 0.4 0.6" />
            </geometry>
        </collision>
    </link>
    <joint name="010-120-201-310_010-120-201-320" type="revolute">
       <parent link="010-120-201-310"/>
       <child  link="010-120-201-320"/>
       <origin rpy="0 0 0" xyz="-0.0 0.4 -0.0" />
     <axis xyz="0 1 0"/>
       <limit effort="0.0" lower="-3.14159" upper="3.14159" velocity="0.0"/>
    </joint>
    <link name="010-120-201-320">
        <inertial>
            <origin xyz="-0.0 0.2 -0.0" rpy="0 0 0"/>
            <mass value="1" />
            <inertia ixx="100" ixy="0" ixz="0" iyy="100" iyz="0" izz="100" />
        </inertial>
        <visual>
            <origin xyz="-0.0 0.2 -0.0" rpy="0 0 0"/>
            <geometry>
                <box size="0.4 0.4 0.6" />
            </geometry>
            <material name="Green">
                <color rgba="0 1.0 0.0 1.0"/>
            </material>
        </visual>
        <collision>
            <origin xyz="-0.0 0.2 -0.0" rpy="0 0 0"/>
            <geometry>
                <box size="0.4 0.4 0.6" />
            </geometry>
        </collision>
    </link>
    <joint name="010-120-201-320_010-120-201-330" type="revolute">
       <parent link="010-120-201-320"/>
       <child  link="010-120-201-330"/>
       <origin rpy="0 0 0" xyz="-0.0 0.4 -0.0" />
     <axis xyz="0 1 0"/>
       <limit effort="0.0" lower="-3.14159" upper="3.14159" velocity="0.0"/>
    </joint>
    <link name="010-120-201-330">
        <inertial>
            <origin xyz="-0.0 0.2 -0.0" rpy="0 0 0"/>
            <mass value="1" />
            <inertia ixx="100" ixy="0" ixz="0" iyy="100" iyz="0" izz="100" />
        </inertial>
        <visual>
            <origin xyz="-0.0 0.2 -0.0" rpy="0 0 0"/>
            <geometry>
                <box size="0.4 0.4 0.6" />
            </geometry>
            <material name="Green">
                <color rgba="0 1.0 0.0 1.0"/>
            </material>
        </visual>
        <collision>
            <origin xyz="-0.0 0.2 -0.0" rpy="0 0 0"/>
            <geometry>
                <box size="0.4 0.4 0.6" />
            </geometry>
        </collision>
    </link>
    <joint name="010-110_010-110-200" type="revolute">
       <parent link="010-110"/>
       <child  link="010-110-200"/>
       <origin rpy="0 0 0" xyz="0.2 0.3 -0.0" />
     <axis xyz="1 0 0"/>
       <limit effort="0.0" lower="-3.14159" upper="3.14159" velocity="0.0"/>
    </joint>
    <link name="010-110-200">
        <inertial>
            <origin xyz="0.1 0.0 -0.0" rpy="0 0 0"/>
            <mass value="1" />
            <inertia ixx="100" ixy="0" ixz="0" iyy="100" iyz="0" izz="100" />
        </inertial>
        <visual>
            <origin xyz="0.1 0.0 -0.0" rpy="0 0 0"/>
            <geometry>
                <box size="0.2 0.3 0.6" />
            </geometry>
            <material name="Blue">
                <color rgba="0 0.0 1.0 1.0"/>
            </material>
        </visual>
        <collision>
            <origin xyz="0.1 0.0 -0.0" rpy="0 0 0"/>
            <geometry>
                <box size="0.2 0.3 0.6" />
            </geometry>
        </collision>
    </link>
    <joint name="010-110-200_010-110-200-300" type="revolute">
       <parent link="010-110-200"/>
       <child  link="010-110-200-300"/>
       <origin rpy="0 0 0" xyz="0.1 0.15 -0.0" />
     <axis xyz="0 1 0"/>
       <limit effort="0.0" lower="-3.14159" upper="3.14159" velocity="0.0"/>
    </joint>
    <link name="010-110-200-300">
        <inertial>
            <origin xyz="0.0 0.2 -0.0" rpy="0 0 0"/>
            <mass value="1" />
            <inertia ixx="100" ixy="0" ixz="0" iyy="100" iyz="0" izz="100" />
        </inertial>
        <visual>
            <origin xyz="0.0 0.2 -0.0" rpy="0 0 0"/>
            <geometry>
                <box size="0.4 0.4 0.6" />
            </geometry>
            <material name="Green">
                <color rgba="0 1.0 0.0 1.0"/>
            </material>
        </visual>
        <collision>
            <origin xyz="0.0 0.2 -0.0" rpy="0 0 0"/>
            <geometry>
                <box size="0.4 0.4 0.6" />
            </geometry>
        </collision>
    </link>
    <joint name="010-110_010-110-201" type="revolute">
       <parent link="010-110"/>
       <child  link="010-110-201"/>
       <origin rpy="0 0 0" xyz="-0.2 0.3 -0.0" />
     <axis xyz="1 0 0"/>
       <limit effort="0.0" lower="-3.14159" upper="3.14159" velocity="0.0"/>
    </joint>
    <link name="010-110-201">
        <inertial>
            <origin xyz="-0.1 0.0 -0.0" rpy="0 0 0"/>
            <mass value="1" />
            <inertia ixx="100" ixy="0" ixz="0" iyy="100" iyz="0" izz="100" />
        </inertial>
        <visual>
            <origin xyz="-0.1 0.0 -0.0" rpy="0 0 0"/>
            <geometry>
                <box size="0.2 0.3 0.6" />
            </geometry>
            <material name="Blue">
                <color rgba="0 0.0 1.0 1.0"/>
            </material>
        </visual>
        <collision>
            <origin xyz="-0.1 0.0 -0.0" rpy="0 0 0"/>
            <geometry>
                <box size="0.2 0.3 0.6" />
            </geometry>
        </collision>
    </link>
    <joint name="010-110-201_010-110-201-300" type="revolute">
       <parent link="010-110-201"/>
       <child  link="010-110-201-300"/>
       <origin rpy="0 0 0" xyz="-0.1 0.15 -0.0" />
     <axis xyz="0 1 0"/>
       <limit effort="0.0" lower="-3.14159" upper="3.14159" velocity="0.0"/>
    </joint>
    <link name="010-110-201-300">
        <inertial>
            <origin xyz="-0.0 0.2 -0.0" rpy="0 0 0"/>
            <mass value="1" />
            <inertia ixx="100" ixy="0" ixz="0" iyy="100" iyz="0" izz="100" />
        </inertial>
        <visual>
            <origin xyz="-0.0 0.2 -0.0" rpy="0 0 0"/>
            <geometry>
                <box size="0.4 0.4 0.6" />
            </geometry>
            <material name="Green">
                <color rgba="0 1.0 0.0 1.0"/>
            </material>
        </visual>
        <collision>
            <origin xyz="-0.0 0.2 -0.0" rpy="0 0 0"/>
            <geometry>
                <box size="0.4 0.4 0.6" />
            </geometry>
        </collision>
    </link>
    <joint name="010-100_010-100-200" type="revolute">
       <parent link="010-100"/>
       <child  link="010-100-200"/>
       <origin rpy="0 0 0" xyz="0.2 0.3 -0.0" />
     <axis xyz="1 0 0"/>
       <limit effort="0.0" lower="-3.14159" upper="3.14159" velocity="0.0"/>
    </joint>
    <link name="010-100-200">
        <inertial>
            <origin xyz="0.1 0.0 -0.0" rpy="0 0 0"/>
            <mass value="1" />
            <inertia ixx="100" ixy="0" ixz="0" iyy="100" iyz="0" izz="100" />
        </inertial>
        <visual>
            <origin xyz="0.1 0.0 -0.0" rpy="0 0 0"/>
            <geometry>
                <box size="0.2 0.3 0.6" />
            </geometry>
            <material name="Blue">
                <color rgba="0 0.0 1.0 1.0"/>
            </material>
        </visual>
        <collision>
            <origin xyz="0.1 0.0 -0.0" rpy="0 0 0"/>
            <geometry>
                <box size="0.2 0.3 0.6" />
            </geometry>
        </collision>
    </link>
    <joint name="010-100-200_010-100-200-300" type="revolute">
       <parent link="010-100-200"/>
       <child  link="010-100-200-300"/>
       <origin rpy="0 0 0" xyz="0.1 0.15 -0.0" />
     <axis xyz="0 1 0"/>
       <limit effort="0.0" lower="-3.14159" upper="3.14159" velocity="0.0"/>
    </joint>
    <link name="010-100-200-300">
        <inertial>
            <origin xyz="0.0 0.2 -0.0" rpy="0 0 0"/>
            <mass value="1" />
            <inertia ixx="100" ixy="0" ixz="0" iyy="100" iyz="0" izz="100" />
        </inertial>
        <visual>
            <origin xyz="0.0 0.2 -0.0" rpy="0 0 0"/>
            <geometry>
                <box size="0.4 0.4 0.6" />
            </geometry>
            <material name="Green">
                <color rgba="0 1.0 0.0 1.0"/>
            </material>
        </visual>
        <collision>
            <origin xyz="0.0 0.2 -0.0" rpy="0 0 0"/>
            <geometry>
                <box size="0.4 0.4 0.6" />
            </geometry>
        </collision>
    </link>
    <joint name="010-100_010-100-201" type="revolute">
       <parent link="010-100"/>
       <child  link="010-100-201"/>
       <origin rpy="0 0 0" xyz="-0.2 0.3 -0.0" />
     <axis xyz="1 0 0"/>
       <limit effort="0.0" lower="-3.14159" upper="3.14159" velocity="0.0"/>
    </joint>
    <link name="010-100-201">
        <inertial>
            <origin xyz="-0.1 0.0 -0.0" rpy="0 0 0"/>
            <mass value="1" />
            <inertia ixx="100" ixy="0" ixz="0" iyy="100" iyz="0" izz="100" />
        </inertial>
        <visual>
            <origin xyz="-0.1 0.0 -0.0" rpy="0 0 0"/>
            <geometry>
                <box size="0.2 0.3 0.6" />
            </geometry>
            <material name="Blue">
                <color rgba="0 0.0 1.0 1.0"/>
            </material>
        </visual>
        <collision>
            <origin xyz="-0.1 0.0 -0.0" rpy="0 0 0"/>
            <geometry>
                <box size="0.2 0.3 0.6" />
            </geometry>
        </collision>
    </link>
    <joint name="010-100-201_010-100-201-300" type="revolute">
       <parent link="010-100-201"/>
       <child  link="010-100-201-300"/>
       <origin rpy="0 0 0" xyz="-0.1 0.15 -0.0" />
     <axis xyz="0 1 0"/>
       <limit effort="0.0" lower="-3.14159" upper="3.14159" velocity="0.0"/>
    </joint>
    <link name="010-100-201-300">
        <inertial>
            <origin xyz="-0.0 0.2 -0.0" rpy="0 0 0"/>
            <mass value="1" />
            <inertia ixx="100" ixy="0" ixz="0" iyy="100" iyz="0" izz="100" />
        </inertial>
        <visual>
            <origin xyz="-0.0 0.2 -0.0" rpy="0 0 0"/>
            <geometry>
                <box size="0.4 0.4 0.6" />
            </geometry>
            <material name="Green">
                <color rgba="0 1.0 0.0 1.0"/>
            </material>
        </visual>
        <collision>
            <origin xyz="-0.0 0.2 -0.0" rpy="0 0 0"/>
            <geometry>
                <box size="0.4 0.4 0.6" />
            </geometry>
        </collision>
    </link>
</robot>