<robot name = "robot">
    <link name="root">
        <inertial>
            <origin xyz="0.0 0.0 1.5" rpy="0 0 0"/>
            <mass value="1" />
            <inertia ixx="100" ixy="0" ixz="0" iyy="100" iyz="0" izz="100" />
        </inertial>
        <visual>
            <origin xyz="0.0 0.0 1.5" rpy="0 0 0"/>
            <geometry>
                <box size="0 0 0.0001" />
            </geometry>
            <material name="Green">
                <color rgba="0 1.0 0.0 1.0"/>
            </material>
        </visual>
        <collision>
            <origin xyz="0.0 0.0 1.5" rpy="0 0 0"/>
            <geometry>
                <box size="0 0 0.0001" />
            </geometry>
        </collision>
    </link>
    <joint name="root_000" type="revolute">
       <parent link="root"/>
       <child  link="000"/>
       <origin rpy="0 0 0" xyz="0.0 0.0 1.5" />
     <axis xyz="1 0 0"/>
       <limit effort="0.0" lower="-3.14159" upper="3.14159" velocity="0.0"/>
    </joint>
    <link name="000">
        <inertial>
            <origin xyz="0.0 0.3 0.0" rpy="0 0 0"/>
            <mass value="1" />
            <inertia ixx="100" ixy="0" ixz="0" iyy="100" iyz="0" izz="100" />
        </inertial>
        <visual>
            <origin xyz="0.0 0.3 0.0" rpy="0 0 0"/>
            <geometry>
                <box size="0.4 0.6 0.7" />
            </geometry>
            <material name="Green">
                <color rgba="0 1.0 0.0 1.0"/>
            </material>
        </visual>
        <collision>
            <origin xyz="0.0 0.3 0.0" rpy="0 0 0"/>
            <geometry>
                <box size="0.4 0.6 0.7" />
            </geometry>
        </collision>
    </link>
    <joint name="000_000-100" type="revolute">
       <parent link="000"/>
       <child  link="000-100"/>
       <origin rpy="0 0 0" xyz="0.2 0.3 -0.0" />
     <axis xyz="1 0 0"/>
       <limit effort="0.0" lower="-3.14159" upper="3.14159" velocity="0.0"/>
    </joint>
    <link name="000-100">
        <inertial>
            <origin xyz="0.3 0.0 -0.0" rpy="0 0 0"/>
            <mass value="1" />
            <inertia ixx="100" ixy="0" ixz="0" iyy="100" iyz="0" izz="100" />
        </inertial>
        <visual>
            <origin xyz="0.3 0.0 -0.0" rpy="0 0 0"/>
            <geometry>
                <box size="0.6 0.3 0.7" />
            </geometry>
            <material name="Green">
                <color rgba="0 1.0 0.0 1.0"/>
            </material>
        </visual>
        <collision>
            <origin xyz="0.3 0.0 -0.0" rpy="0 0 0"/>
            <geometry>
                <box size="0.6 0.3 0.7" />
            </geometry>
        </collision>
    </link>
    <joint name="000-100_000-110" type="revolute">
       <parent link="000-100"/>
       <child  link="000-110"/>
       <origin rpy="0 0 0" xyz="0.6 0.0 -0.0" />
     <axis xyz="1 0 0"/>
       <limit effort="0.0" lower="-3.14159" upper="3.14159" velocity="0.0"/>
    </joint>
    <link name="000-110">
        <inertial>
            <origin xyz="0.3 0.0 -0.0" rpy="0 0 0"/>
            <mass value="1" />
            <inertia ixx="100" ixy="0" ixz="0" iyy="100" iyz="0" izz="100" />
        </inertial>
        <visual>
            <origin xyz="0.3 0.0 -0.0" rpy="0 0 0"/>
            <geometry>
                <box size="0.6 0.3 0.7" />
            </geometry>
            <material name="Green">
                <color rgba="0 1.0 0.0 1.0"/>
            </material>
        </visual>
        <collision>
            <origin xyz="0.3 0.0 -0.0" rpy="0 0 0"/>
            <geometry>
                <box size="0.6 0.3 0.7" />
            </geometry>
        </collision>
    </link>
    <joint name="000-110_000-110-200" type="revolute">
       <parent link="000-110"/>
       <child  link="000-110-200"/>
       <origin rpy="0 0 0" xyz="0.3 0.15 -0.0" />
     <axis xyz="0 1 0"/>
       <limit effort="0.0" lower="-3.14159" upper="3.14159" velocity="0.0"/>
    </joint>
    <link name="000-110-200">
        <inertial>
            <origin xyz="0.0 0.3 -0.0" rpy="0 0 0"/>
            <mass value="1" />
            <inertia ixx="100" ixy="0" ixz="0" iyy="100" iyz="0" izz="100" />
        </inertial>
        <visual>
            <origin xyz="0.0 0.3 -0.0" rpy="0 0 0"/>
            <geometry>
                <box size="0.6 0.6 0.3" />
            </geometry>
            <material name="Green">
                <color rgba="0 1.0 0.0 1.0"/>
            </material>
        </visual>
        <collision>
            <origin xyz="0.0 0.3 -0.0" rpy="0 0 0"/>
            <geometry>
                <box size="0.6 0.6 0.3" />
            </geometry>
        </collision>
    </link>
    <joint name="000-110-200_000-110-210" type="revolute">
       <parent link="000-110-200"/>
       <child  link="000-110-210"/>
       <origin rpy="0 0 0" xyz="0.0 0.6 -0.0" />
     <axis xyz="0 1 0"/>
       <limit effort="0.0" lower="-3.14159" upper="3.14159" velocity="0.0"/>
    </joint>
    <link name="000-110-210">
        <inertial>
            <origin xyz="0.0 0.3 -0.0" rpy="0 0 0"/>
            <mass value="1" />
            <inertia ixx="100" ixy="0" ixz="0" iyy="100" iyz="0" izz="100" />
        </inertial>
        <visual>
            <origin xyz="0.0 0.3 -0.0" rpy="0 0 0"/>
            <geometry>
                <box size="0.6 0.6 0.3" />
            </geometry>
            <material name="Green">
                <color rgba="0 1.0 0.0 1.0"/>
            </material>
        </visual>
        <collision>
            <origin xyz="0.0 0.3 -0.0" rpy="0 0 0"/>
            <geometry>
                <box size="0.6 0.6 0.3" />
            </geometry>
        </collision>
    </link>
    <joint name="000-110-210_000-110-220" type="revolute">
       <parent link="000-110-210"/>
       <child  link="000-110-220"/>
       <origin rpy="0 0 0" xyz="0.0 0.6 -0.0" />
     <axis xyz="0 1 0"/>
       <limit effort="0.0" lower="-3.14159" upper="3.14159" velocity="0.0"/>
    </joint>
    <link name="000-110-220">
        <inertial>
            <origin xyz="0.0 0.3 -0.0" rpy="0 0 0"/>
            <mass value="1" />
            <inertia ixx="100" ixy="0" ixz="0" iyy="100" iyz="0" izz="100" />
        </inertial>
        <visual>
            <origin xyz="0.0 0.3 -0.0" rpy="0 0 0"/>
            <geometry>
                <box size="0.6 0.6 0.3" />
            </geometry>
            <material name="Green">
                <color rgba="0 1.0 0.0 1.0"/>
            </material>
        </visual>
        <collision>
            <origin xyz="0.0 0.3 -0.0" rpy="0 0 0"/>
            <geometry>
                <box size="0.6 0.6 0.3" />
            </geometry>
        </collision>
    </link>
    <joint name="000-110-220_000-110-220-300" type="revolute">
       <parent link="000-110-220"/>
       <child  link="000-110-220-300"/>
       <origin rpy="0 0 0" xyz="0.0 0.3 -0.15" />
     <axis xyz="0 0 1"/>
       <limit effort="0.0" lower="-3.14159" upper="3.14159" velocity="0.0"/>
    </joint>
    <link name="000-110-220-300">
        <inertial>
            <origin xyz="0.0 0.0 -0.3" rpy="0 0 0"/>
            <mass value="1" />
            <inertia ixx="100" ixy="0" ixz="0" iyy="100" iyz="0" izz="100" />
        </inertial>
        <visual>
            <origin xyz="0.0 0.0 -0.3" rpy="0 0 0"/>
            <geometry>
                <box size="0.7 0.2 0.6" />
            </geometry>
            <material name="Blue">
                <color rgba="0 0.0 1.0 1.0"/>
            </material>
        </visual>
        <collision>
            <origin xyz="0.0 0.0 -0.3" rpy="0 0 0"/>
            <geometry>
                <box size="0.7 0.2 0.6" />
            </geometry>
        </collision>
    </link>
    <joint name="000-110-210_000-110-210-300" type="revolute">
       <parent link="000-110-210"/>
       <child  link="000-110-210-300"/>
       <origin rpy="0 0 0" xyz="0.0 0.3 -0.15" />
     <axis xyz="0 0 1"/>
       <limit effort="0.0" lower="-3.14159" upper="3.14159" velocity="0.0"/>
    </joint>
    <link name="000-110-210-300">
        <inertial>
            <origin xyz="0.0 0.0 -0.3" rpy="0 0 0"/>
            <mass value="1" />
            <inertia ixx="100" ixy="0" ixz="0" iyy="100" iyz="0" izz="100" />
        </inertial>
        <visual>
            <origin xyz="0.0 0.0 -0.3" rpy="0 0 0"/>
            <geometry>
                <box size="0.7 0.2 0.6" />
            </geometry>
            <material name="Blue">
                <color rgba="0 0.0 1.0 1.0"/>
            </material>
        </visual>
        <collision>
            <origin xyz="0.0 0.0 -0.3" rpy="0 0 0"/>
            <geometry>
                <box size="0.7 0.2 0.6" />
            </geometry>
        </collision>
    </link>
    <joint name="000-110-200_000-110-200-300" type="revolute">
       <parent link="000-110-200"/>
       <child  link="000-110-200-300"/>
       <origin rpy="0 0 0" xyz="0.0 0.3 -0.15" />
     <axis xyz="0 0 1"/>
       <limit effort="0.0" lower="-3.14159" upper="3.14159" velocity="0.0"/>
    </joint>
    <link name="000-110-200-300">
        <inertial>
            <origin xyz="0.0 0.0 -0.3" rpy="0 0 0"/>
            <mass value="1" />
            <inertia ixx="100" ixy="0" ixz="0" iyy="100" iyz="0" izz="100" />
        </inertial>
        <visual>
            <origin xyz="0.0 0.0 -0.3" rpy="0 0 0"/>
            <geometry>
                <box size="0.7 0.2 0.6" />
            </geometry>
            <material name="Blue">
                <color rgba="0 0.0 1.0 1.0"/>
            </material>
        </visual>
        <collision>
            <origin xyz="0.0 0.0 -0.3" rpy="0 0 0"/>
            <geometry>
                <box size="0.7 0.2 0.6" />
            </geometry>
        </collision>
    </link>
    <joint name="000-100_000-100-200" type="revolute">
       <parent link="000-100"/>
       <child  link="000-100-200"/>
       <origin rpy="0 0 0" xyz="0.3 0.15 -0.0" />
     <axis xyz="0 1 0"/>
       <limit effort="0.0" lower="-3.14159" upper="3.14159" velocity="0.0"/>
    </joint>
    <link name="000-100-200">
        <inertial>
            <origin xyz="0.0 0.3 -0.0" rpy="0 0 0"/>
            <mass value="1" />
            <inertia ixx="100" ixy="0" ixz="0" iyy="100" iyz="0" izz="100" />
        </inertial>
        <visual>
            <origin xyz="0.0 0.3 -0.0" rpy="0 0 0"/>
            <geometry>
                <box size="0.6 0.6 0.3" />
            </geometry>
            <material name="Green">
                <color rgba="0 1.0 0.0 1.0"/>
            </material>
        </visual>
        <collision>
            <origin xyz="0.0 0.3 -0.0" rpy="0 0 0"/>
            <geometry>
                <box size="0.6 0.6 0.3" />
            </geometry>
        </collision>
    </link>
    <joint name="000-100-200_000-100-210" type="revolute">
       <parent link="000-100-200"/>
       <child  link="000-100-210"/>
       <origin rpy="0 0 0" xyz="0.0 0.6 -0.0" />
     <axis xyz="0 1 0"/>
       <limit effort="0.0" lower="-3.14159" upper="3.14159" velocity="0.0"/>
    </joint>
    <link name="000-100-210">
        <inertial>
            <origin xyz="0.0 0.3 -0.0" rpy="0 0 0"/>
            <mass value="1" />
            <inertia ixx="100" ixy="0" ixz="0" iyy="100" iyz="0" izz="100" />
        </inertial>
        <visual>
            <origin xyz="0.0 0.3 -0.0" rpy="0 0 0"/>
            <geometry>
                <box size="0.6 0.6 0.3" />
            </geometry>
            <material name="Green">
                <color rgba="0 1.0 0.0 1.0"/>
            </material>
        </visual>
        <collision>
            <origin xyz="0.0 0.3 -0.0" rpy="0 0 0"/>
            <geometry>
                <box size="0.6 0.6 0.3" />
            </geometry>
        </collision>
    </link>
    <joint name="000-100-210_000-100-220" type="revolute">
       <parent link="000-100-210"/>
       <child  link="000-100-220"/>
       <origin rpy="0 0 0" xyz="0.0 0.6 -0.0" />
     <axis xyz="0 1 0"/>
       <limit effort="0.0" lower="-3.14159" upper="3.14159" velocity="0.0"/>
    </joint>
    <link name="000-100-220">
        <inertial>
            <origin xyz="0.0 0.3 -0.0" rpy="0 0 0"/>
            <mass value="1" />
            <inertia ixx="100" ixy="0" ixz="0" iyy="100" iyz="0" izz="100" />
        </inertial>
        <visual>
            <origin xyz="0.0 0.3 -0.0" rpy="0 0 0"/>
            <geometry>
                <box size="0.6 0.6 0.3" />
            </geometry>
            <material name="Green">
                <color rgba="0 1.0 0.0 1.0"/>
            </material>
        </visual>
        <collision>
            <origin xyz="0.0 0.3 -0.0" rpy="0 0 0"/>
            <geometry>
                <box size="0.6 0.6 0.3" />
            </geometry>
        </collision>
    </link>
    <joint name="000-100-220_000-100-220-300" type="revolute">
       <parent link="000-100-220"/>
       <child  link="000-100-220-300"/>
       <origin rpy="0 0 0" xyz="0.0 0.3 -0.15" />
     <axis xyz="0 0 1"/>
       <limit effort="0.0" lower="-3.14159" upper="3.14159" velocity="0.0"/>
    </joint>
    <link name="000-100-220-300">
        <inertial>
            <origin xyz="0.0 0.0 -0.3" rpy="0 0 0"/>
            <mass value="1" />
            <inertia ixx="100" ixy="0" ixz="0" iyy="100" iyz="0" izz="100" />
        </inertial>
        <visual>
            <origin xyz="0.0 0.0 -0.3" rpy="0 0 0"/>
            <geometry>
                <box size="0.7 0.2 0.6" />
            </geometry>
            <material name="Blue">
                <color rgba="0 0.0 1.0 1.0"/>
            </material>
        </visual>
        <collision>
            <origin xyz="0.0 0.0 -0.3" rpy="0 0 0"/>
            <geometry>
                <box size="0.7 0.2 0.6" />
            </geometry>
        </collision>
    </link>
    <joint name="000-100-210_000-100-210-300" type="revolute">
       <parent link="000-100-210"/>
       <child  link="000-100-210-300"/>
       <origin rpy="0 0 0" xyz="0.0 0.3 -0.15" />
     <axis xyz="0 0 1"/>
       <limit effort="0.0" lower="-3.14159" upper="3.14159" velocity="0.0"/>
    </joint>
    <link name="000-100-210-300">
        <inertial>
            <origin xyz="0.0 0.0 -0.3" rpy="0 0 0"/>
            <mass value="1" />
            <inertia ixx="100" ixy="0" ixz="0" iyy="100" iyz="0" izz="100" />
        </inertial>
        <visual>
            <origin xyz="0.0 0.0 -0.3" rpy="0 0 0"/>
            <geometry>
                <box size="0.7 0.2 0.6" />
            </geometry>
            <material name="Blue">
                <color rgba="0 0.0 1.0 1.0"/>
            </material>
        </visual>
        <collision>
            <origin xyz="0.0 0.0 -0.3" rpy="0 0 0"/>
            <geometry>
                <box size="0.7 0.2 0.6" />
            </geometry>
        </collision>
    </link>
    <joint name="000-100-200_000-100-200-300" type="revolute">
       <parent link="000-100-200"/>
       <child  link="000-100-200-300"/>
       <origin rpy="0 0 0" xyz="0.0 0.3 -0.15" />
     <axis xyz="0 0 1"/>
       <limit effort="0.0" lower="-3.14159" upper="3.14159" velocity="0.0"/>
    </joint>
    <link name="000-100-200-300">
        <inertial>
            <origin xyz="0.0 0.0 -0.3" rpy="0 0 0"/>
            <mass value="1" />
            <inertia ixx="100" ixy="0" ixz="0" iyy="100" iyz="0" izz="100" />
        </inertial>
        <visual>
            <origin xyz="0.0 0.0 -0.3" rpy="0 0 0"/>
            <geometry>
                <box size="0.7 0.2 0.6" />
            </geometry>
            <material name="Blue">
                <color rgba="0 0.0 1.0 1.0"/>
            </material>
        </visual>
        <collision>
            <origin xyz="0.0 0.0 -0.3" rpy="0 0 0"/>
            <geometry>
                <box size="0.7 0.2 0.6" />
            </geometry>
        </collision>
    </link>
    <joint name="000_000-101" type="revolute">
       <parent link="000"/>
       <child  link="000-101"/>
       <origin rpy="0 0 0" xyz="-0.2 0.3 -0.0" />
     <axis xyz="1 0 0"/>
       <limit effort="0.0" lower="-3.14159" upper="3.14159" velocity="0.0"/>
    </joint>
    <link name="000-101">
        <inertial>
            <origin xyz="-0.3 0.0 -0.0" rpy="0 0 0"/>
            <mass value="1" />
            <inertia ixx="100" ixy="0" ixz="0" iyy="100" iyz="0" izz="100" />
        </inertial>
        <visual>
            <origin xyz="-0.3 0.0 -0.0" rpy="0 0 0"/>
            <geometry>
                <box size="0.6 0.3 0.7" />
            </geometry>
            <material name="Green">
                <color rgba="0 1.0 0.0 1.0"/>
            </material>
        </visual>
        <collision>
            <origin xyz="-0.3 0.0 -0.0" rpy="0 0 0"/>
            <geometry>
                <box size="0.6 0.3 0.7" />
            </geometry>
        </collision>
    </link>
    <joint name="000-101_000-111" type="revolute">
       <parent link="000-101"/>
       <child  link="000-111"/>
       <origin rpy="0 0 0" xyz="-0.6 0.0 -0.0" />
     <axis xyz="1 0 0"/>
       <limit effort="0.0" lower="-3.14159" upper="3.14159" velocity="0.0"/>
    </joint>
    <link name="000-111">
        <inertial>
            <origin xyz="-0.3 0.0 -0.0" rpy="0 0 0"/>
            <mass value="1" />
            <inertia ixx="100" ixy="0" ixz="0" iyy="100" iyz="0" izz="100" />
        </inertial>
        <visual>
            <origin xyz="-0.3 0.0 -0.0" rpy="0 0 0"/>
            <geometry>
                <box size="0.6 0.3 0.7" />
            </geometry>
            <material name="Green">
                <color rgba="0 1.0 0.0 1.0"/>
            </material>
        </visual>
        <collision>
            <origin xyz="-0.3 0.0 -0.0" rpy="0 0 0"/>
            <geometry>
                <box size="0.6 0.3 0.7" />
            </geometry>
        </collision>
    </link>
    <joint name="000-111_000-111-200" type="revolute">
       <parent link="000-111"/>
       <child  link="000-111-200"/>
       <origin rpy="0 0 0" xyz="-0.3 0.15 -0.0" />
     <axis xyz="0 1 0"/>
       <limit effort="0.0" lower="-3.14159" upper="3.14159" velocity="0.0"/>
    </joint>
    <link name="000-111-200">
        <inertial>
            <origin xyz="-0.0 0.3 -0.0" rpy="0 0 0"/>
            <mass value="1" />
            <inertia ixx="100" ixy="0" ixz="0" iyy="100" iyz="0" izz="100" />
        </inertial>
        <visual>
            <origin xyz="-0.0 0.3 -0.0" rpy="0 0 0"/>
            <geometry>
                <box size="0.6 0.6 0.3" />
            </geometry>
            <material name="Green">
                <color rgba="0 1.0 0.0 1.0"/>
            </material>
        </visual>
        <collision>
            <origin xyz="-0.0 0.3 -0.0" rpy="0 0 0"/>
            <geometry>
                <box size="0.6 0.6 0.3" />
            </geometry>
        </collision>
    </link>
    <joint name="000-111-200_000-111-210" type="revolute">
       <parent link="000-111-200"/>
       <child  link="000-111-210"/>
       <origin rpy="0 0 0" xyz="-0.0 0.6 -0.0" />
     <axis xyz="0 1 0"/>
       <limit effort="0.0" lower="-3.14159" upper="3.14159" velocity="0.0"/>
    </joint>
    <link name="000-111-210">
        <inertial>
            <origin xyz="-0.0 0.3 -0.0" rpy="0 0 0"/>
            <mass value="1" />
            <inertia ixx="100" ixy="0" ixz="0" iyy="100" iyz="0" izz="100" />
        </inertial>
        <visual>
            <origin xyz="-0.0 0.3 -0.0" rpy="0 0 0"/>
            <geometry>
                <box size="0.6 0.6 0.3" />
            </geometry>
            <material name="Green">
                <color rgba="0 1.0 0.0 1.0"/>
            </material>
        </visual>
        <collision>
            <origin xyz="-0.0 0.3 -0.0" rpy="0 0 0"/>
            <geometry>
                <box size="0.6 0.6 0.3" />
            </geometry>
        </collision>
    </link>
    <joint name="000-111-210_000-111-220" type="revolute">
       <parent link="000-111-210"/>
       <child  link="000-111-220"/>
       <origin rpy="0 0 0" xyz="-0.0 0.6 -0.0" />
     <axis xyz="0 1 0"/>
       <limit effort="0.0" lower="-3.14159" upper="3.14159" velocity="0.0"/>
    </joint>
    <link name="000-111-220">
        <inertial>
            <origin xyz="-0.0 0.3 -0.0" rpy="0 0 0"/>
            <mass value="1" />
            <inertia ixx="100" ixy="0" ixz="0" iyy="100" iyz="0" izz="100" />
        </inertial>
        <visual>
            <origin xyz="-0.0 0.3 -0.0" rpy="0 0 0"/>
            <geometry>
                <box size="0.6 0.6 0.3" />
            </geometry>
            <material name="Green">
                <color rgba="0 1.0 0.0 1.0"/>
            </material>
        </visual>
        <collision>
            <origin xyz="-0.0 0.3 -0.0" rpy="0 0 0"/>
            <geometry>
                <box size="0.6 0.6 0.3" />
            </geometry>
        </collision>
    </link>
    <joint name="000-111-220_000-111-220-300" type="revolute">
       <parent link="000-111-220"/>
       <child  link="000-111-220-300"/>
       <origin rpy="0 0 0" xyz="-0.0 0.3 -0.15" />
     <axis xyz="0 0 1"/>
       <limit effort="0.0" lower="-3.14159" upper="3.14159" velocity="0.0"/>
    </joint>
    <link name="000-111-220-300">
        <inertial>
            <origin xyz="-0.0 0.0 -0.3" rpy="0 0 0"/>
            <mass value="1" />
            <inertia ixx="100" ixy="0" ixz="0" iyy="100" iyz="0" izz="100" />
        </inertial>
        <visual>
            <origin xyz="-0.0 0.0 -0.3" rpy="0 0 0"/>
            <geometry>
                <box size="0.7 0.2 0.6" />
            </geometry>
            <material name="Blue">
                <color rgba="0 0.0 1.0 1.0"/>
            </material>
        </visual>
        <collision>
            <origin xyz="-0.0 0.0 -0.3" rpy="0 0 0"/>
            <geometry>
                <box size="0.7 0.2 0.6" />
            </geometry>
        </collision>
    </link>
    <joint name="000-111-210_000-111-210-300" type="revolute">
       <parent link="000-111-210"/>
       <child  link="000-111-210-300"/>
       <origin rpy="0 0 0" xyz="-0.0 0.3 -0.15" />
     <axis xyz="0 0 1"/>
       <limit effort="0.0" lower="-3.14159" upper="3.14159" velocity="0.0"/>
    </joint>
    <link name="000-111-210-300">
        <inertial>
            <origin xyz="-0.0 0.0 -0.3" rpy="0 0 0"/>
            <mass value="1" />
            <inertia ixx="100" ixy="0" ixz="0" iyy="100" iyz="0" izz="100" />
        </inertial>
        <visual>
            <origin xyz="-0.0 0.0 -0.3" rpy="0 0 0"/>
            <geometry>
                <box size="0.7 0.2 0.6" />
            </geometry>
            <material name="Blue">
                <color rgba="0 0.0 1.0 1.0"/>
            </material>
        </visual>
        <collision>
            <origin xyz="-0.0 0.0 -0.3" rpy="0 0 0"/>
            <geometry>
                <box size="0.7 0.2 0.6" />
            </geometry>
        </collision>
    </link>
    <joint name="000-111-200_000-111-200-300" type="revolute">
       <parent link="000-111-200"/>
       <child  link="000-111-200-300"/>
       <origin rpy="0 0 0" xyz="-0.0 0.3 -0.15" />
     <axis xyz="0 0 1"/>
       <limit effort="0.0" lower="-3.14159" upper="3.14159" velocity="0.0"/>
    </joint>
    <link name="000-111-200-300">
        <inertial>
            <origin xyz="-0.0 0.0 -0.3" rpy="0 0 0"/>
            <mass value="1" />
            <inertia ixx="100" ixy="0" ixz="0" iyy="100" iyz="0" izz="100" />
        </inertial>
        <visual>
            <origin xyz="-0.0 0.0 -0.3" rpy="0 0 0"/>
            <geometry>
                <box size="0.7 0.2 0.6" />
            </geometry>
            <material name="Blue">
                <color rgba="0 0.0 1.0 1.0"/>
            </material>
        </visual>
        <collision>
            <origin xyz="-0.0 0.0 -0.3" rpy="0 0 0"/>
            <geometry>
                <box size="0.7 0.2 0.6" />
            </geometry>
        </collision>
    </link>
    <joint name="000-101_000-101-200" type="revolute">
       <parent link="000-101"/>
       <child  link="000-101-200"/>
       <origin rpy="0 0 0" xyz="-0.3 0.15 -0.0" />
     <axis xyz="0 1 0"/>
       <limit effort="0.0" lower="-3.14159" upper="3.14159" velocity="0.0"/>
    </joint>
    <link name="000-101-200">
        <inertial>
            <origin xyz="-0.0 0.3 -0.0" rpy="0 0 0"/>
            <mass value="1" />
            <inertia ixx="100" ixy="0" ixz="0" iyy="100" iyz="0" izz="100" />
        </inertial>
        <visual>
            <origin xyz="-0.0 0.3 -0.0" rpy="0 0 0"/>
            <geometry>
                <box size="0.6 0.6 0.3" />
            </geometry>
            <material name="Green">
                <color rgba="0 1.0 0.0 1.0"/>
            </material>
        </visual>
        <collision>
            <origin xyz="-0.0 0.3 -0.0" rpy="0 0 0"/>
            <geometry>
                <box size="0.6 0.6 0.3" />
            </geometry>
        </collision>
    </link>
    <joint name="000-101-200_000-101-210" type="revolute">
       <parent link="000-101-200"/>
       <child  link="000-101-210"/>
       <origin rpy="0 0 0" xyz="-0.0 0.6 -0.0" />
     <axis xyz="0 1 0"/>
       <limit effort="0.0" lower="-3.14159" upper="3.14159" velocity="0.0"/>
    </joint>
    <link name="000-101-210">
        <inertial>
            <origin xyz="-0.0 0.3 -0.0" rpy="0 0 0"/>
            <mass value="1" />
            <inertia ixx="100" ixy="0" ixz="0" iyy="100" iyz="0" izz="100" />
        </inertial>
        <visual>
            <origin xyz="-0.0 0.3 -0.0" rpy="0 0 0"/>
            <geometry>
                <box size="0.6 0.6 0.3" />
            </geometry>
            <material name="Green">
                <color rgba="0 1.0 0.0 1.0"/>
            </material>
        </visual>
        <collision>
            <origin xyz="-0.0 0.3 -0.0" rpy="0 0 0"/>
            <geometry>
                <box size="0.6 0.6 0.3" />
            </geometry>
        </collision>
    </link>
    <joint name="000-101-210_000-101-220" type="revolute">
       <parent link="000-101-210"/>
       <child  link="000-101-220"/>
       <origin rpy="0 0 0" xyz="-0.0 0.6 -0.0" />
     <axis xyz="0 1 0"/>
       <limit effort="0.0" lower="-3.14159" upper="3.14159" velocity="0.0"/>
    </joint>
    <link name="000-101-220">
        <inertial>
            <origin xyz="-0.0 0.3 -0.0" rpy="0 0 0"/>
            <mass value="1" />
            <inertia ixx="100" ixy="0" ixz="0" iyy="100" iyz="0" izz="100" />
        </inertial>
        <visual>
            <origin xyz="-0.0 0.3 -0.0" rpy="0 0 0"/>
            <geometry>
                <box size="0.6 0.6 0.3" />
            </geometry>
            <material name="Green">
                <color rgba="0 1.0 0.0 1.0"/>
            </material>
        </visual>
        <collision>
            <origin xyz="-0.0 0.3 -0.0" rpy="0 0 0"/>
            <geometry>
                <box size="0.6 0.6 0.3" />
            </geometry>
        </collision>
    </link>
    <joint name="000-101-220_000-101-220-300" type="revolute">
       <parent link="000-101-220"/>
       <child  link="000-101-220-300"/>
       <origin rpy="0 0 0" xyz="-0.0 0.3 -0.15" />
     <axis xyz="0 0 1"/>
       <limit effort="0.0" lower="-3.14159" upper="3.14159" velocity="0.0"/>
    </joint>
    <link name="000-101-220-300">
        <inertial>
            <origin xyz="-0.0 0.0 -0.3" rpy="0 0 0"/>
            <mass value="1" />
            <inertia ixx="100" ixy="0" ixz="0" iyy="100" iyz="0" izz="100" />
        </inertial>
        <visual>
            <origin xyz="-0.0 0.0 -0.3" rpy="0 0 0"/>
            <geometry>
                <box size="0.7 0.2 0.6" />
            </geometry>
            <material name="Blue">
                <color rgba="0 0.0 1.0 1.0"/>
            </material>
        </visual>
        <collision>
            <origin xyz="-0.0 0.0 -0.3" rpy="0 0 0"/>
            <geometry>
                <box size="0.7 0.2 0.6" />
            </geometry>
        </collision>
    </link>
    <joint name="000-101-210_000-101-210-300" type="revolute">
       <parent link="000-101-210"/>
       <child  link="000-101-210-300"/>
       <origin rpy="0 0 0" xyz="-0.0 0.3 -0.15" />
     <axis xyz="0 0 1"/>
       <limit effort="0.0" lower="-3.14159" upper="3.14159" velocity="0.0"/>
    </joint>
    <link name="000-101-210-300">
        <inertial>
            <origin xyz="-0.0 0.0 -0.3" rpy="0 0 0"/>
            <mass value="1" />
            <inertia ixx="100" ixy="0" ixz="0" iyy="100" iyz="0" izz="100" />
        </inertial>
        <visual>
            <origin xyz="-0.0 0.0 -0.3" rpy="0 0 0"/>
            <geometry>
                <box size="0.7 0.2 0.6" />
            </geometry>
            <material name="Blue">
                <color rgba="0 0.0 1.0 1.0"/>
            </material>
        </visual>
        <collision>
            <origin xyz="-0.0 0.0 -0.3" rpy="0 0 0"/>
            <geometry>
                <box size="0.7 0.2 0.6" />
            </geometry>
        </collision>
    </link>
    <joint name="000-101-200_000-101-200-300" type="revolute">
       <parent link="000-101-200"/>
       <child  link="000-101-200-300"/>
       <origin rpy="0 0 0" xyz="-0.0 0.3 -0.15" />
     <axis xyz="0 0 1"/>
       <limit effort="0.0" lower="-3.14159" upper="3.14159" velocity="0.0"/>
    </joint>
    <link name="000-101-200-300">
        <inertial>
            <origin xyz="-0.0 0.0 -0.3" rpy="0 0 0"/>
            <mass value="1" />
            <inertia ixx="100" ixy="0" ixz="0" iyy="100" iyz="0" izz="100" />
        </inertial>
        <visual>
            <origin xyz="-0.0 0.0 -0.3" rpy="0 0 0"/>
            <geometry>
                <box size="0.7 0.2 0.6" />
            </geometry>
            <material name="Blue">
                <color rgba="0 0.0 1.0 1.0"/>
            </material>
        </visual>
        <collision>
            <origin xyz="-0.0 0.0 -0.3" rpy="0 0 0"/>
            <geometry>
                <box size="0.7 0.2 0.6" />
            </geometry>
        </collision>
    </link>
</robot>