<robot name = "robot">
    <link name="root">
        <inertial>
            <origin xyz="0.0 0.0 1.5" rpy="0 0 0"/>
            <mass value="1" />
            <inertia ixx="100" ixy="0" ixz="0" iyy="100" iyz="0" izz="100" />
        </inertial>
        <visual>
            <origin xyz="0.0 0.0 1.5" rpy="0 0 0"/>
            <geometry>
                <box size="0 0 0.0001" />
            </geometry>
            <material name="Green">
                <color rgba="0 1.0 0.0 1.0"/>
            </material>
        </visual>
        <collision>
            <origin xyz="0.0 0.0 1.5" rpy="0 0 0"/>
            <geometry>
                <box size="0 0 0.0001" />
            </geometry>
        </collision>
    </link>
    <joint name="root_000" type="revolute">
       <parent link="root"/>
       <child  link="000"/>
       <origin rpy="0 0 0" xyz="0.0 0.0 1.5" />
     <axis xyz="1 0 0"/>
       <limit effort="0.0" lower="-3.14159" upper="3.14159" velocity="0.0"/>
    </joint>
    <link name="000">
        <inertial>
            <origin xyz="0.0 0.0 -0.3" rpy="0 0 0"/>
            <mass value="1" />
            <inertia ixx="100" ixy="0" ixz="0" iyy="100" iyz="0" izz="100" />
        </inertial>
        <visual>
            <origin xyz="0.0 0.0 -0.3" rpy="0 0 0"/>
            <geometry>
                <box size="0.6 0.3 0.6" />
            </geometry>
            <material name="Green">
                <color rgba="0 1.0 0.0 1.0"/>
            </material>
        </visual>
        <collision>
            <origin xyz="0.0 0.0 -0.3" rpy="0 0 0"/>
            <geometry>
                <box size="0.6 0.3 0.6" />
            </geometry>
        </collision>
    </link>
    <joint name="000_000-100" type="revolute">
       <parent link="000"/>
       <child  link="000-100"/>
       <origin rpy="0 0 0" xyz="0.3 0.0 -0.3" />
     <axis xyz="1 0 0"/>
       <limit effort="0.0" lower="-3.14159" upper="3.14159" velocity="0.0"/>
    </joint>
    <link name="000-100">
        <inertial>
            <origin xyz="0.05 0.0 -0.0" rpy="0 0 0"/>
            <mass value="1" />
            <inertia ixx="100" ixy="0" ixz="0" iyy="100" iyz="0" izz="100" />
        </inertial>
        <visual>
            <origin xyz="0.05 0.0 -0.0" rpy="0 0 0"/>
            <geometry>
                <box size="0.1 0.3 0.2" />
            </geometry>
            <material name="Blue">
                <color rgba="0 0.0 1.0 1.0"/>
            </material>
        </visual>
        <collision>
            <origin xyz="0.05 0.0 -0.0" rpy="0 0 0"/>
            <geometry>
                <box size="0.1 0.3 0.2" />
            </geometry>
        </collision>
    </link>
    <joint name="000-100_000-110" type="revolute">
       <parent link="000-100"/>
       <child  link="000-110"/>
       <origin rpy="0 0 0" xyz="0.1 0.0 -0.0" />
     <axis xyz="1 0 0"/>
       <limit effort="0.0" lower="-3.14159" upper="3.14159" velocity="0.0"/>
    </joint>
    <link name="000-110">
        <inertial>
            <origin xyz="0.05 0.0 -0.0" rpy="0 0 0"/>
            <mass value="1" />
            <inertia ixx="100" ixy="0" ixz="0" iyy="100" iyz="0" izz="100" />
        </inertial>
        <visual>
            <origin xyz="0.05 0.0 -0.0" rpy="0 0 0"/>
            <geometry>
                <box size="0.1 0.3 0.2" />
            </geometry>
            <material name="Blue">
                <color rgba="0 0.0 1.0 1.0"/>
            </material>
        </visual>
        <collision>
            <origin xyz="0.05 0.0 -0.0" rpy="0 0 0"/>
            <geometry>
                <box size="0.1 0.3 0.2" />
            </geometry>
        </collision>
    </link>
    <joint name="000-110_000-120" type="revolute">
       <parent link="000-110"/>
       <child  link="000-120"/>
       <origin rpy="0 0 0" xyz="0.1 0.0 -0.0" />
     <axis xyz="1 0 0"/>
       <limit effort="0.0" lower="-3.14159" upper="3.14159" velocity="0.0"/>
    </joint>
    <link name="000-120">
        <inertial>
            <origin xyz="0.05 0.0 -0.0" rpy="0 0 0"/>
            <mass value="1" />
            <inertia ixx="100" ixy="0" ixz="0" iyy="100" iyz="0" izz="100" />
        </inertial>
        <visual>
            <origin xyz="0.05 0.0 -0.0" rpy="0 0 0"/>
            <geometry>
                <box size="0.1 0.3 0.2" />
            </geometry>
            <material name="Blue">
                <color rgba="0 0.0 1.0 1.0"/>
            </material>
        </visual>
        <collision>
            <origin xyz="0.05 0.0 -0.0" rpy="0 0 0"/>
            <geometry>
                <box size="0.1 0.3 0.2" />
            </geometry>
        </collision>
    </link>
    <joint name="000-120_000-120-200" type="revolute">
       <parent link="000-120"/>
       <child  link="000-120-200"/>
       <origin rpy="0 0 0" xyz="0.05 0.0 -0.1" />
     <axis xyz="0 0 1"/>
       <limit effort="0.0" lower="-3.14159" upper="3.14159" velocity="0.0"/>
    </joint>
    <link name="000-120-200">
        <inertial>
            <origin xyz="0.0 0.0 -0.2" rpy="0 0 0"/>
            <mass value="1" />
            <inertia ixx="100" ixy="0" ixz="0" iyy="100" iyz="0" izz="100" />
        </inertial>
        <visual>
            <origin xyz="0.0 0.0 -0.2" rpy="0 0 0"/>
            <geometry>
                <box size="0.4 0.4 0.4" />
            </geometry>
            <material name="Green">
                <color rgba="0 1.0 0.0 1.0"/>
            </material>
        </visual>
        <collision>
            <origin xyz="0.0 0.0 -0.2" rpy="0 0 0"/>
            <geometry>
                <box size="0.4 0.4 0.4" />
            </geometry>
        </collision>
    </link>
</robot>