<robot name = "robot">
    <link name="root">
        <inertial>
            <origin xyz="0.0 0.0 1.5" rpy="0 0 0"/>
            <mass value="1" />
            <inertia ixx="100" ixy="0" ixz="0" iyy="100" iyz="0" izz="100" />
        </inertial>
        <visual>
            <origin xyz="0.0 0.0 1.5" rpy="0 0 0"/>
            <geometry>
                <box size="0 0 0.0001" />
            </geometry>
            <material name="Green">
                <color rgba="0 1.0 0.0 1.0"/>
            </material>
        </visual>
        <collision>
            <origin xyz="0.0 0.0 1.5" rpy="0 0 0"/>
            <geometry>
                <box size="0 0 0.0001" />
            </geometry>
        </collision>
    </link>
    <joint name="root_000" type="revolute">
       <parent link="root"/>
       <child  link="000"/>
       <origin rpy="0 0 0" xyz="0.0 0.0 1.5" />
     <axis xyz="1 0 0"/>
       <limit effort="0.0" lower="-3.14159" upper="3.14159" velocity="0.0"/>
    </joint>
    <link name="000">
        <inertial>
            <origin xyz="0.0 0.1 0.0" rpy="0 0 0"/>
            <mass value="1" />
            <inertia ixx="100" ixy="0" ixz="0" iyy="100" iyz="0" izz="100" />
        </inertial>
        <visual>
            <origin xyz="0.0 0.1 0.0" rpy="0 0 0"/>
            <geometry>
                <box size="0.5 0.2 0.5" />
            </geometry>
            <material name="Green">
                <color rgba="0 1.0 0.0 1.0"/>
            </material>
        </visual>
        <collision>
            <origin xyz="0.0 0.1 0.0" rpy="0 0 0"/>
            <geometry>
                <box size="0.5 0.2 0.5" />
            </geometry>
        </collision>
    </link>
    <joint name="000_000-100" type="revolute">
       <parent link="000"/>
       <child  link="000-100"/>
       <origin rpy="0 0 0" xyz="0.25 0.1 -0.0" />
     <axis xyz="1 0 0"/>
       <limit effort="0.0" lower="-3.14159" upper="3.14159" velocity="0.0"/>
    </joint>
    <link name="000-100">
        <inertial>
            <origin xyz="0.3 0.0 -0.0" rpy="0 0 0"/>
            <mass value="1" />
            <inertia ixx="100" ixy="0" ixz="0" iyy="100" iyz="0" izz="100" />
        </inertial>
        <visual>
            <origin xyz="0.3 0.0 -0.0" rpy="0 0 0"/>
            <geometry>
                <box size="0.6 0.1 0.4" />
            </geometry>
            <material name="Green">
                <color rgba="0 1.0 0.0 1.0"/>
            </material>
        </visual>
        <collision>
            <origin xyz="0.3 0.0 -0.0" rpy="0 0 0"/>
            <geometry>
                <box size="0.6 0.1 0.4" />
            </geometry>
        </collision>
    </link>
    <joint name="000-100_000-100-200" type="revolute">
       <parent link="000-100"/>
       <child  link="000-100-200"/>
       <origin rpy="0 0 0" xyz="0.3 0.05 -0.0" />
     <axis xyz="0 1 0"/>
       <limit effort="0.0" lower="-3.14159" upper="3.14159" velocity="0.0"/>
    </joint>
    <link name="000-100-200">
        <inertial>
            <origin xyz="0.0 0.35 -0.0" rpy="0 0 0"/>
            <mass value="1" />
            <inertia ixx="100" ixy="0" ixz="0" iyy="100" iyz="0" izz="100" />
        </inertial>
        <visual>
            <origin xyz="0.0 0.35 -0.0" rpy="0 0 0"/>
            <geometry>
                <box size="0.1 0.7 0.3" />
            </geometry>
            <material name="Blue">
                <color rgba="0 0.0 1.0 1.0"/>
            </material>
        </visual>
        <collision>
            <origin xyz="0.0 0.35 -0.0" rpy="0 0 0"/>
            <geometry>
                <box size="0.1 0.7 0.3" />
            </geometry>
        </collision>
    </link>
    <joint name="000-100-200_000-100-210" type="revolute">
       <parent link="000-100-200"/>
       <child  link="000-100-210"/>
       <origin rpy="0 0 0" xyz="0.0 0.7 -0.0" />
     <axis xyz="0 1 0"/>
       <limit effort="0.0" lower="-3.14159" upper="3.14159" velocity="0.0"/>
    </joint>
    <link name="000-100-210">
        <inertial>
            <origin xyz="0.0 0.35 -0.0" rpy="0 0 0"/>
            <mass value="1" />
            <inertia ixx="100" ixy="0" ixz="0" iyy="100" iyz="0" izz="100" />
        </inertial>
        <visual>
            <origin xyz="0.0 0.35 -0.0" rpy="0 0 0"/>
            <geometry>
                <box size="0.1 0.7 0.3" />
            </geometry>
            <material name="Blue">
                <color rgba="0 0.0 1.0 1.0"/>
            </material>
        </visual>
        <collision>
            <origin xyz="0.0 0.35 -0.0" rpy="0 0 0"/>
            <geometry>
                <box size="0.1 0.7 0.3" />
            </geometry>
        </collision>
    </link>
    <joint name="000-100-210_000-100-220" type="revolute">
       <parent link="000-100-210"/>
       <child  link="000-100-220"/>
       <origin rpy="0 0 0" xyz="0.0 0.7 -0.0" />
     <axis xyz="0 1 0"/>
       <limit effort="0.0" lower="-3.14159" upper="3.14159" velocity="0.0"/>
    </joint>
    <link name="000-100-220">
        <inertial>
            <origin xyz="0.0 0.35 -0.0" rpy="0 0 0"/>
            <mass value="1" />
            <inertia ixx="100" ixy="0" ixz="0" iyy="100" iyz="0" izz="100" />
        </inertial>
        <visual>
            <origin xyz="0.0 0.35 -0.0" rpy="0 0 0"/>
            <geometry>
                <box size="0.1 0.7 0.3" />
            </geometry>
            <material name="Blue">
                <color rgba="0 0.0 1.0 1.0"/>
            </material>
        </visual>
        <collision>
            <origin xyz="0.0 0.35 -0.0" rpy="0 0 0"/>
            <geometry>
                <box size="0.1 0.7 0.3" />
            </geometry>
        </collision>
    </link>
    <joint name="000-100-220_000-100-220-300" type="revolute">
       <parent link="000-100-220"/>
       <child  link="000-100-220-300"/>
       <origin rpy="0 0 0" xyz="0.0 0.35 -0.15" />
     <axis xyz="0 0 1"/>
       <limit effort="0.0" lower="-3.14159" upper="3.14159" velocity="0.0"/>
    </joint>
    <link name="000-100-220-300">
        <inertial>
            <origin xyz="0.0 0.0 -0.1" rpy="0 0 0"/>
            <mass value="1" />
            <inertia ixx="100" ixy="0" ixz="0" iyy="100" iyz="0" izz="100" />
        </inertial>
        <visual>
            <origin xyz="0.0 0.0 -0.1" rpy="0 0 0"/>
            <geometry>
                <box size="0.3 0.6 0.2" />
            </geometry>
            <material name="Green">
                <color rgba="0 1.0 0.0 1.0"/>
            </material>
        </visual>
        <collision>
            <origin xyz="0.0 0.0 -0.1" rpy="0 0 0"/>
            <geometry>
                <box size="0.3 0.6 0.2" />
            </geometry>
        </collision>
    </link>
    <joint name="000-100-220-300_000-100-220-310" type="revolute">
       <parent link="000-100-220-300"/>
       <child  link="000-100-220-310"/>
       <origin rpy="0 0 0" xyz="0.0 0.0 -0.2" />
     <axis xyz="0 0 1"/>
       <limit effort="0.0" lower="-3.14159" upper="3.14159" velocity="0.0"/>
    </joint>
    <link name="000-100-220-310">
        <inertial>
            <origin xyz="0.0 0.0 -0.1" rpy="0 0 0"/>
            <mass value="1" />
            <inertia ixx="100" ixy="0" ixz="0" iyy="100" iyz="0" izz="100" />
        </inertial>
        <visual>
            <origin xyz="0.0 0.0 -0.1" rpy="0 0 0"/>
            <geometry>
                <box size="0.3 0.6 0.2" />
            </geometry>
            <material name="Green">
                <color rgba="0 1.0 0.0 1.0"/>
            </material>
        </visual>
        <collision>
            <origin xyz="0.0 0.0 -0.1" rpy="0 0 0"/>
            <geometry>
                <box size="0.3 0.6 0.2" />
            </geometry>
        </collision>
    </link>
    <joint name="000-100-210_000-100-210-300" type="revolute">
       <parent link="000-100-210"/>
       <child  link="000-100-210-300"/>
       <origin rpy="0 0 0" xyz="0.0 0.35 -0.15" />
     <axis xyz="0 0 1"/>
       <limit effort="0.0" lower="-3.14159" upper="3.14159" velocity="0.0"/>
    </joint>
    <link name="000-100-210-300">
        <inertial>
            <origin xyz="0.0 0.0 -0.1" rpy="0 0 0"/>
            <mass value="1" />
            <inertia ixx="100" ixy="0" ixz="0" iyy="100" iyz="0" izz="100" />
        </inertial>
        <visual>
            <origin xyz="0.0 0.0 -0.1" rpy="0 0 0"/>
            <geometry>
                <box size="0.3 0.6 0.2" />
            </geometry>
            <material name="Green">
                <color rgba="0 1.0 0.0 1.0"/>
            </material>
        </visual>
        <collision>
            <origin xyz="0.0 0.0 -0.1" rpy="0 0 0"/>
            <geometry>
                <box size="0.3 0.6 0.2" />
            </geometry>
        </collision>
    </link>
    <joint name="000-100-210-300_000-100-210-310" type="revolute">
       <parent link="000-100-210-300"/>
       <child  link="000-100-210-310"/>
       <origin rpy="0 0 0" xyz="0.0 0.0 -0.2" />
     <axis xyz="0 0 1"/>
       <limit effort="0.0" lower="-3.14159" upper="3.14159" velocity="0.0"/>
    </joint>
    <link name="000-100-210-310">
        <inertial>
            <origin xyz="0.0 0.0 -0.1" rpy="0 0 0"/>
            <mass value="1" />
            <inertia ixx="100" ixy="0" ixz="0" iyy="100" iyz="0" izz="100" />
        </inertial>
        <visual>
            <origin xyz="0.0 0.0 -0.1" rpy="0 0 0"/>
            <geometry>
                <box size="0.3 0.6 0.2" />
            </geometry>
            <material name="Green">
                <color rgba="0 1.0 0.0 1.0"/>
            </material>
        </visual>
        <collision>
            <origin xyz="0.0 0.0 -0.1" rpy="0 0 0"/>
            <geometry>
                <box size="0.3 0.6 0.2" />
            </geometry>
        </collision>
    </link>
    <joint name="000-100-200_000-100-200-300" type="revolute">
       <parent link="000-100-200"/>
       <child  link="000-100-200-300"/>
       <origin rpy="0 0 0" xyz="0.0 0.35 -0.15" />
     <axis xyz="0 0 1"/>
       <limit effort="0.0" lower="-3.14159" upper="3.14159" velocity="0.0"/>
    </joint>
    <link name="000-100-200-300">
        <inertial>
            <origin xyz="0.0 0.0 -0.1" rpy="0 0 0"/>
            <mass value="1" />
            <inertia ixx="100" ixy="0" ixz="0" iyy="100" iyz="0" izz="100" />
        </inertial>
        <visual>
            <origin xyz="0.0 0.0 -0.1" rpy="0 0 0"/>
            <geometry>
                <box size="0.3 0.6 0.2" />
            </geometry>
            <material name="Green">
                <color rgba="0 1.0 0.0 1.0"/>
            </material>
        </visual>
        <collision>
            <origin xyz="0.0 0.0 -0.1" rpy="0 0 0"/>
            <geometry>
                <box size="0.3 0.6 0.2" />
            </geometry>
        </collision>
    </link>
    <joint name="000-100-200-300_000-100-200-310" type="revolute">
       <parent link="000-100-200-300"/>
       <child  link="000-100-200-310"/>
       <origin rpy="0 0 0" xyz="0.0 0.0 -0.2" />
     <axis xyz="0 0 1"/>
       <limit effort="0.0" lower="-3.14159" upper="3.14159" velocity="0.0"/>
    </joint>
    <link name="000-100-200-310">
        <inertial>
            <origin xyz="0.0 0.0 -0.1" rpy="0 0 0"/>
            <mass value="1" />
            <inertia ixx="100" ixy="0" ixz="0" iyy="100" iyz="0" izz="100" />
        </inertial>
        <visual>
            <origin xyz="0.0 0.0 -0.1" rpy="0 0 0"/>
            <geometry>
                <box size="0.3 0.6 0.2" />
            </geometry>
            <material name="Green">
                <color rgba="0 1.0 0.0 1.0"/>
            </material>
        </visual>
        <collision>
            <origin xyz="0.0 0.0 -0.1" rpy="0 0 0"/>
            <geometry>
                <box size="0.3 0.6 0.2" />
            </geometry>
        </collision>
    </link>
    <joint name="000-100_000-100-201" type="revolute">
       <parent link="000-100"/>
       <child  link="000-100-201"/>
       <origin rpy="0 0 0" xyz="0.3 -0.05 -0.0" />
     <axis xyz="0 1 0"/>
       <limit effort="0.0" lower="-3.14159" upper="3.14159" velocity="0.0"/>
    </joint>
    <link name="000-100-201">
        <inertial>
            <origin xyz="0.0 -0.35 -0.0" rpy="0 0 0"/>
            <mass value="1" />
            <inertia ixx="100" ixy="0" ixz="0" iyy="100" iyz="0" izz="100" />
        </inertial>
        <visual>
            <origin xyz="0.0 -0.35 -0.0" rpy="0 0 0"/>
            <geometry>
                <box size="0.1 0.7 0.3" />
            </geometry>
            <material name="Blue">
                <color rgba="0 0.0 1.0 1.0"/>
            </material>
        </visual>
        <collision>
            <origin xyz="0.0 -0.35 -0.0" rpy="0 0 0"/>
            <geometry>
                <box size="0.1 0.7 0.3" />
            </geometry>
        </collision>
    </link>
    <joint name="000-100-201_000-100-211" type="revolute">
       <parent link="000-100-201"/>
       <child  link="000-100-211"/>
       <origin rpy="0 0 0" xyz="0.0 -0.7 -0.0" />
     <axis xyz="0 1 0"/>
       <limit effort="0.0" lower="-3.14159" upper="3.14159" velocity="0.0"/>
    </joint>
    <link name="000-100-211">
        <inertial>
            <origin xyz="0.0 -0.35 -0.0" rpy="0 0 0"/>
            <mass value="1" />
            <inertia ixx="100" ixy="0" ixz="0" iyy="100" iyz="0" izz="100" />
        </inertial>
        <visual>
            <origin xyz="0.0 -0.35 -0.0" rpy="0 0 0"/>
            <geometry>
                <box size="0.1 0.7 0.3" />
            </geometry>
            <material name="Blue">
                <color rgba="0 0.0 1.0 1.0"/>
            </material>
        </visual>
        <collision>
            <origin xyz="0.0 -0.35 -0.0" rpy="0 0 0"/>
            <geometry>
                <box size="0.1 0.7 0.3" />
            </geometry>
        </collision>
    </link>
    <joint name="000-100-211_000-100-221" type="revolute">
       <parent link="000-100-211"/>
       <child  link="000-100-221"/>
       <origin rpy="0 0 0" xyz="0.0 -0.7 -0.0" />
     <axis xyz="0 1 0"/>
       <limit effort="0.0" lower="-3.14159" upper="3.14159" velocity="0.0"/>
    </joint>
    <link name="000-100-221">
        <inertial>
            <origin xyz="0.0 -0.35 -0.0" rpy="0 0 0"/>
            <mass value="1" />
            <inertia ixx="100" ixy="0" ixz="0" iyy="100" iyz="0" izz="100" />
        </inertial>
        <visual>
            <origin xyz="0.0 -0.35 -0.0" rpy="0 0 0"/>
            <geometry>
                <box size="0.1 0.7 0.3" />
            </geometry>
            <material name="Blue">
                <color rgba="0 0.0 1.0 1.0"/>
            </material>
        </visual>
        <collision>
            <origin xyz="0.0 -0.35 -0.0" rpy="0 0 0"/>
            <geometry>
                <box size="0.1 0.7 0.3" />
            </geometry>
        </collision>
    </link>
    <joint name="000-100-221_000-100-221-300" type="revolute">
       <parent link="000-100-221"/>
       <child  link="000-100-221-300"/>
       <origin rpy="0 0 0" xyz="0.0 -0.35 -0.15" />
     <axis xyz="0 0 1"/>
       <limit effort="0.0" lower="-3.14159" upper="3.14159" velocity="0.0"/>
    </joint>
    <link name="000-100-221-300">
        <inertial>
            <origin xyz="0.0 -0.0 -0.1" rpy="0 0 0"/>
            <mass value="1" />
            <inertia ixx="100" ixy="0" ixz="0" iyy="100" iyz="0" izz="100" />
        </inertial>
        <visual>
            <origin xyz="0.0 -0.0 -0.1" rpy="0 0 0"/>
            <geometry>
                <box size="0.3 0.6 0.2" />
            </geometry>
            <material name="Green">
                <color rgba="0 1.0 0.0 1.0"/>
            </material>
        </visual>
        <collision>
            <origin xyz="0.0 -0.0 -0.1" rpy="0 0 0"/>
            <geometry>
                <box size="0.3 0.6 0.2" />
            </geometry>
        </collision>
    </link>
    <joint name="000-100-221-300_000-100-221-310" type="revolute">
       <parent link="000-100-221-300"/>
       <child  link="000-100-221-310"/>
       <origin rpy="0 0 0" xyz="0.0 -0.0 -0.2" />
     <axis xyz="0 0 1"/>
       <limit effort="0.0" lower="-3.14159" upper="3.14159" velocity="0.0"/>
    </joint>
    <link name="000-100-221-310">
        <inertial>
            <origin xyz="0.0 -0.0 -0.1" rpy="0 0 0"/>
            <mass value="1" />
            <inertia ixx="100" ixy="0" ixz="0" iyy="100" iyz="0" izz="100" />
        </inertial>
        <visual>
            <origin xyz="0.0 -0.0 -0.1" rpy="0 0 0"/>
            <geometry>
                <box size="0.3 0.6 0.2" />
            </geometry>
            <material name="Green">
                <color rgba="0 1.0 0.0 1.0"/>
            </material>
        </visual>
        <collision>
            <origin xyz="0.0 -0.0 -0.1" rpy="0 0 0"/>
            <geometry>
                <box size="0.3 0.6 0.2" />
            </geometry>
        </collision>
    </link>
    <joint name="000-100-211_000-100-211-300" type="revolute">
       <parent link="000-100-211"/>
       <child  link="000-100-211-300"/>
       <origin rpy="0 0 0" xyz="0.0 -0.35 -0.15" />
     <axis xyz="0 0 1"/>
       <limit effort="0.0" lower="-3.14159" upper="3.14159" velocity="0.0"/>
    </joint>
    <link name="000-100-211-300">
        <inertial>
            <origin xyz="0.0 -0.0 -0.1" rpy="0 0 0"/>
            <mass value="1" />
            <inertia ixx="100" ixy="0" ixz="0" iyy="100" iyz="0" izz="100" />
        </inertial>
        <visual>
            <origin xyz="0.0 -0.0 -0.1" rpy="0 0 0"/>
            <geometry>
                <box size="0.3 0.6 0.2" />
            </geometry>
            <material name="Green">
                <color rgba="0 1.0 0.0 1.0"/>
            </material>
        </visual>
        <collision>
            <origin xyz="0.0 -0.0 -0.1" rpy="0 0 0"/>
            <geometry>
                <box size="0.3 0.6 0.2" />
            </geometry>
        </collision>
    </link>
    <joint name="000-100-211-300_000-100-211-310" type="revolute">
       <parent link="000-100-211-300"/>
       <child  link="000-100-211-310"/>
       <origin rpy="0 0 0" xyz="0.0 -0.0 -0.2" />
     <axis xyz="0 0 1"/>
       <limit effort="0.0" lower="-3.14159" upper="3.14159" velocity="0.0"/>
    </joint>
    <link name="000-100-211-310">
        <inertial>
            <origin xyz="0.0 -0.0 -0.1" rpy="0 0 0"/>
            <mass value="1" />
            <inertia ixx="100" ixy="0" ixz="0" iyy="100" iyz="0" izz="100" />
        </inertial>
        <visual>
            <origin xyz="0.0 -0.0 -0.1" rpy="0 0 0"/>
            <geometry>
                <box size="0.3 0.6 0.2" />
            </geometry>
            <material name="Green">
                <color rgba="0 1.0 0.0 1.0"/>
            </material>
        </visual>
        <collision>
            <origin xyz="0.0 -0.0 -0.1" rpy="0 0 0"/>
            <geometry>
                <box size="0.3 0.6 0.2" />
            </geometry>
        </collision>
    </link>
    <joint name="000-100-201_000-100-201-300" type="revolute">
       <parent link="000-100-201"/>
       <child  link="000-100-201-300"/>
       <origin rpy="0 0 0" xyz="0.0 -0.35 -0.15" />
     <axis xyz="0 0 1"/>
       <limit effort="0.0" lower="-3.14159" upper="3.14159" velocity="0.0"/>
    </joint>
    <link name="000-100-201-300">
        <inertial>
            <origin xyz="0.0 -0.0 -0.1" rpy="0 0 0"/>
            <mass value="1" />
            <inertia ixx="100" ixy="0" ixz="0" iyy="100" iyz="0" izz="100" />
        </inertial>
        <visual>
            <origin xyz="0.0 -0.0 -0.1" rpy="0 0 0"/>
            <geometry>
                <box size="0.3 0.6 0.2" />
            </geometry>
            <material name="Green">
                <color rgba="0 1.0 0.0 1.0"/>
            </material>
        </visual>
        <collision>
            <origin xyz="0.0 -0.0 -0.1" rpy="0 0 0"/>
            <geometry>
                <box size="0.3 0.6 0.2" />
            </geometry>
        </collision>
    </link>
    <joint name="000-100-201-300_000-100-201-310" type="revolute">
       <parent link="000-100-201-300"/>
       <child  link="000-100-201-310"/>
       <origin rpy="0 0 0" xyz="0.0 -0.0 -0.2" />
     <axis xyz="0 0 1"/>
       <limit effort="0.0" lower="-3.14159" upper="3.14159" velocity="0.0"/>
    </joint>
    <link name="000-100-201-310">
        <inertial>
            <origin xyz="0.0 -0.0 -0.1" rpy="0 0 0"/>
            <mass value="1" />
            <inertia ixx="100" ixy="0" ixz="0" iyy="100" iyz="0" izz="100" />
        </inertial>
        <visual>
            <origin xyz="0.0 -0.0 -0.1" rpy="0 0 0"/>
            <geometry>
                <box size="0.3 0.6 0.2" />
            </geometry>
            <material name="Green">
                <color rgba="0 1.0 0.0 1.0"/>
            </material>
        </visual>
        <collision>
            <origin xyz="0.0 -0.0 -0.1" rpy="0 0 0"/>
            <geometry>
                <box size="0.3 0.6 0.2" />
            </geometry>
        </collision>
    </link>
    <joint name="000_000-101" type="revolute">
       <parent link="000"/>
       <child  link="000-101"/>
       <origin rpy="0 0 0" xyz="-0.25 0.1 -0.0" />
     <axis xyz="1 0 0"/>
       <limit effort="0.0" lower="-3.14159" upper="3.14159" velocity="0.0"/>
    </joint>
    <link name="000-101">
        <inertial>
            <origin xyz="-0.3 0.0 -0.0" rpy="0 0 0"/>
            <mass value="1" />
            <inertia ixx="100" ixy="0" ixz="0" iyy="100" iyz="0" izz="100" />
        </inertial>
        <visual>
            <origin xyz="-0.3 0.0 -0.0" rpy="0 0 0"/>
            <geometry>
                <box size="0.6 0.1 0.4" />
            </geometry>
            <material name="Green">
                <color rgba="0 1.0 0.0 1.0"/>
            </material>
        </visual>
        <collision>
            <origin xyz="-0.3 0.0 -0.0" rpy="0 0 0"/>
            <geometry>
                <box size="0.6 0.1 0.4" />
            </geometry>
        </collision>
    </link>
    <joint name="000-101_000-101-200" type="revolute">
       <parent link="000-101"/>
       <child  link="000-101-200"/>
       <origin rpy="0 0 0" xyz="-0.3 0.05 -0.0" />
     <axis xyz="0 1 0"/>
       <limit effort="0.0" lower="-3.14159" upper="3.14159" velocity="0.0"/>
    </joint>
    <link name="000-101-200">
        <inertial>
            <origin xyz="-0.0 0.35 -0.0" rpy="0 0 0"/>
            <mass value="1" />
            <inertia ixx="100" ixy="0" ixz="0" iyy="100" iyz="0" izz="100" />
        </inertial>
        <visual>
            <origin xyz="-0.0 0.35 -0.0" rpy="0 0 0"/>
            <geometry>
                <box size="0.1 0.7 0.3" />
            </geometry>
            <material name="Blue">
                <color rgba="0 0.0 1.0 1.0"/>
            </material>
        </visual>
        <collision>
            <origin xyz="-0.0 0.35 -0.0" rpy="0 0 0"/>
            <geometry>
                <box size="0.1 0.7 0.3" />
            </geometry>
        </collision>
    </link>
    <joint name="000-101-200_000-101-210" type="revolute">
       <parent link="000-101-200"/>
       <child  link="000-101-210"/>
       <origin rpy="0 0 0" xyz="-0.0 0.7 -0.0" />
     <axis xyz="0 1 0"/>
       <limit effort="0.0" lower="-3.14159" upper="3.14159" velocity="0.0"/>
    </joint>
    <link name="000-101-210">
        <inertial>
            <origin xyz="-0.0 0.35 -0.0" rpy="0 0 0"/>
            <mass value="1" />
            <inertia ixx="100" ixy="0" ixz="0" iyy="100" iyz="0" izz="100" />
        </inertial>
        <visual>
            <origin xyz="-0.0 0.35 -0.0" rpy="0 0 0"/>
            <geometry>
                <box size="0.1 0.7 0.3" />
            </geometry>
            <material name="Blue">
                <color rgba="0 0.0 1.0 1.0"/>
            </material>
        </visual>
        <collision>
            <origin xyz="-0.0 0.35 -0.0" rpy="0 0 0"/>
            <geometry>
                <box size="0.1 0.7 0.3" />
            </geometry>
        </collision>
    </link>
    <joint name="000-101-210_000-101-220" type="revolute">
       <parent link="000-101-210"/>
       <child  link="000-101-220"/>
       <origin rpy="0 0 0" xyz="-0.0 0.7 -0.0" />
     <axis xyz="0 1 0"/>
       <limit effort="0.0" lower="-3.14159" upper="3.14159" velocity="0.0"/>
    </joint>
    <link name="000-101-220">
        <inertial>
            <origin xyz="-0.0 0.35 -0.0" rpy="0 0 0"/>
            <mass value="1" />
            <inertia ixx="100" ixy="0" ixz="0" iyy="100" iyz="0" izz="100" />
        </inertial>
        <visual>
            <origin xyz="-0.0 0.35 -0.0" rpy="0 0 0"/>
            <geometry>
                <box size="0.1 0.7 0.3" />
            </geometry>
            <material name="Blue">
                <color rgba="0 0.0 1.0 1.0"/>
            </material>
        </visual>
        <collision>
            <origin xyz="-0.0 0.35 -0.0" rpy="0 0 0"/>
            <geometry>
                <box size="0.1 0.7 0.3" />
            </geometry>
        </collision>
    </link>
    <joint name="000-101-220_000-101-220-300" type="revolute">
       <parent link="000-101-220"/>
       <child  link="000-101-220-300"/>
       <origin rpy="0 0 0" xyz="-0.0 0.35 -0.15" />
     <axis xyz="0 0 1"/>
       <limit effort="0.0" lower="-3.14159" upper="3.14159" velocity="0.0"/>
    </joint>
    <link name="000-101-220-300">
        <inertial>
            <origin xyz="-0.0 0.0 -0.1" rpy="0 0 0"/>
            <mass value="1" />
            <inertia ixx="100" ixy="0" ixz="0" iyy="100" iyz="0" izz="100" />
        </inertial>
        <visual>
            <origin xyz="-0.0 0.0 -0.1" rpy="0 0 0"/>
            <geometry>
                <box size="0.3 0.6 0.2" />
            </geometry>
            <material name="Green">
                <color rgba="0 1.0 0.0 1.0"/>
            </material>
        </visual>
        <collision>
            <origin xyz="-0.0 0.0 -0.1" rpy="0 0 0"/>
            <geometry>
                <box size="0.3 0.6 0.2" />
            </geometry>
        </collision>
    </link>
    <joint name="000-101-220-300_000-101-220-310" type="revolute">
       <parent link="000-101-220-300"/>
       <child  link="000-101-220-310"/>
       <origin rpy="0 0 0" xyz="-0.0 0.0 -0.2" />
     <axis xyz="0 0 1"/>
       <limit effort="0.0" lower="-3.14159" upper="3.14159" velocity="0.0"/>
    </joint>
    <link name="000-101-220-310">
        <inertial>
            <origin xyz="-0.0 0.0 -0.1" rpy="0 0 0"/>
            <mass value="1" />
            <inertia ixx="100" ixy="0" ixz="0" iyy="100" iyz="0" izz="100" />
        </inertial>
        <visual>
            <origin xyz="-0.0 0.0 -0.1" rpy="0 0 0"/>
            <geometry>
                <box size="0.3 0.6 0.2" />
            </geometry>
            <material name="Green">
                <color rgba="0 1.0 0.0 1.0"/>
            </material>
        </visual>
        <collision>
            <origin xyz="-0.0 0.0 -0.1" rpy="0 0 0"/>
            <geometry>
                <box size="0.3 0.6 0.2" />
            </geometry>
        </collision>
    </link>
    <joint name="000-101-210_000-101-210-300" type="revolute">
       <parent link="000-101-210"/>
       <child  link="000-101-210-300"/>
       <origin rpy="0 0 0" xyz="-0.0 0.35 -0.15" />
     <axis xyz="0 0 1"/>
       <limit effort="0.0" lower="-3.14159" upper="3.14159" velocity="0.0"/>
    </joint>
    <link name="000-101-210-300">
        <inertial>
            <origin xyz="-0.0 0.0 -0.1" rpy="0 0 0"/>
            <mass value="1" />
            <inertia ixx="100" ixy="0" ixz="0" iyy="100" iyz="0" izz="100" />
        </inertial>
        <visual>
            <origin xyz="-0.0 0.0 -0.1" rpy="0 0 0"/>
            <geometry>
                <box size="0.3 0.6 0.2" />
            </geometry>
            <material name="Green">
                <color rgba="0 1.0 0.0 1.0"/>
            </material>
        </visual>
        <collision>
            <origin xyz="-0.0 0.0 -0.1" rpy="0 0 0"/>
            <geometry>
                <box size="0.3 0.6 0.2" />
            </geometry>
        </collision>
    </link>
    <joint name="000-101-210-300_000-101-210-310" type="revolute">
       <parent link="000-101-210-300"/>
       <child  link="000-101-210-310"/>
       <origin rpy="0 0 0" xyz="-0.0 0.0 -0.2" />
     <axis xyz="0 0 1"/>
       <limit effort="0.0" lower="-3.14159" upper="3.14159" velocity="0.0"/>
    </joint>
    <link name="000-101-210-310">
        <inertial>
            <origin xyz="-0.0 0.0 -0.1" rpy="0 0 0"/>
            <mass value="1" />
            <inertia ixx="100" ixy="0" ixz="0" iyy="100" iyz="0" izz="100" />
        </inertial>
        <visual>
            <origin xyz="-0.0 0.0 -0.1" rpy="0 0 0"/>
            <geometry>
                <box size="0.3 0.6 0.2" />
            </geometry>
            <material name="Green">
                <color rgba="0 1.0 0.0 1.0"/>
            </material>
        </visual>
        <collision>
            <origin xyz="-0.0 0.0 -0.1" rpy="0 0 0"/>
            <geometry>
                <box size="0.3 0.6 0.2" />
            </geometry>
        </collision>
    </link>
    <joint name="000-101-200_000-101-200-300" type="revolute">
       <parent link="000-101-200"/>
       <child  link="000-101-200-300"/>
       <origin rpy="0 0 0" xyz="-0.0 0.35 -0.15" />
     <axis xyz="0 0 1"/>
       <limit effort="0.0" lower="-3.14159" upper="3.14159" velocity="0.0"/>
    </joint>
    <link name="000-101-200-300">
        <inertial>
            <origin xyz="-0.0 0.0 -0.1" rpy="0 0 0"/>
            <mass value="1" />
            <inertia ixx="100" ixy="0" ixz="0" iyy="100" iyz="0" izz="100" />
        </inertial>
        <visual>
            <origin xyz="-0.0 0.0 -0.1" rpy="0 0 0"/>
            <geometry>
                <box size="0.3 0.6 0.2" />
            </geometry>
            <material name="Green">
                <color rgba="0 1.0 0.0 1.0"/>
            </material>
        </visual>
        <collision>
            <origin xyz="-0.0 0.0 -0.1" rpy="0 0 0"/>
            <geometry>
                <box size="0.3 0.6 0.2" />
            </geometry>
        </collision>
    </link>
    <joint name="000-101-200-300_000-101-200-310" type="revolute">
       <parent link="000-101-200-300"/>
       <child  link="000-101-200-310"/>
       <origin rpy="0 0 0" xyz="-0.0 0.0 -0.2" />
     <axis xyz="0 0 1"/>
       <limit effort="0.0" lower="-3.14159" upper="3.14159" velocity="0.0"/>
    </joint>
    <link name="000-101-200-310">
        <inertial>
            <origin xyz="-0.0 0.0 -0.1" rpy="0 0 0"/>
            <mass value="1" />
            <inertia ixx="100" ixy="0" ixz="0" iyy="100" iyz="0" izz="100" />
        </inertial>
        <visual>
            <origin xyz="-0.0 0.0 -0.1" rpy="0 0 0"/>
            <geometry>
                <box size="0.3 0.6 0.2" />
            </geometry>
            <material name="Green">
                <color rgba="0 1.0 0.0 1.0"/>
            </material>
        </visual>
        <collision>
            <origin xyz="-0.0 0.0 -0.1" rpy="0 0 0"/>
            <geometry>
                <box size="0.3 0.6 0.2" />
            </geometry>
        </collision>
    </link>
    <joint name="000-101_000-101-201" type="revolute">
       <parent link="000-101"/>
       <child  link="000-101-201"/>
       <origin rpy="0 0 0" xyz="-0.3 -0.05 -0.0" />
     <axis xyz="0 1 0"/>
       <limit effort="0.0" lower="-3.14159" upper="3.14159" velocity="0.0"/>
    </joint>
    <link name="000-101-201">
        <inertial>
            <origin xyz="-0.0 -0.35 -0.0" rpy="0 0 0"/>
            <mass value="1" />
            <inertia ixx="100" ixy="0" ixz="0" iyy="100" iyz="0" izz="100" />
        </inertial>
        <visual>
            <origin xyz="-0.0 -0.35 -0.0" rpy="0 0 0"/>
            <geometry>
                <box size="0.1 0.7 0.3" />
            </geometry>
            <material name="Blue">
                <color rgba="0 0.0 1.0 1.0"/>
            </material>
        </visual>
        <collision>
            <origin xyz="-0.0 -0.35 -0.0" rpy="0 0 0"/>
            <geometry>
                <box size="0.1 0.7 0.3" />
            </geometry>
        </collision>
    </link>
    <joint name="000-101-201_000-101-211" type="revolute">
       <parent link="000-101-201"/>
       <child  link="000-101-211"/>
       <origin rpy="0 0 0" xyz="-0.0 -0.7 -0.0" />
     <axis xyz="0 1 0"/>
       <limit effort="0.0" lower="-3.14159" upper="3.14159" velocity="0.0"/>
    </joint>
    <link name="000-101-211">
        <inertial>
            <origin xyz="-0.0 -0.35 -0.0" rpy="0 0 0"/>
            <mass value="1" />
            <inertia ixx="100" ixy="0" ixz="0" iyy="100" iyz="0" izz="100" />
        </inertial>
        <visual>
            <origin xyz="-0.0 -0.35 -0.0" rpy="0 0 0"/>
            <geometry>
                <box size="0.1 0.7 0.3" />
            </geometry>
            <material name="Blue">
                <color rgba="0 0.0 1.0 1.0"/>
            </material>
        </visual>
        <collision>
            <origin xyz="-0.0 -0.35 -0.0" rpy="0 0 0"/>
            <geometry>
                <box size="0.1 0.7 0.3" />
            </geometry>
        </collision>
    </link>
    <joint name="000-101-211_000-101-221" type="revolute">
       <parent link="000-101-211"/>
       <child  link="000-101-221"/>
       <origin rpy="0 0 0" xyz="-0.0 -0.7 -0.0" />
     <axis xyz="0 1 0"/>
       <limit effort="0.0" lower="-3.14159" upper="3.14159" velocity="0.0"/>
    </joint>
    <link name="000-101-221">
        <inertial>
            <origin xyz="-0.0 -0.35 -0.0" rpy="0 0 0"/>
            <mass value="1" />
            <inertia ixx="100" ixy="0" ixz="0" iyy="100" iyz="0" izz="100" />
        </inertial>
        <visual>
            <origin xyz="-0.0 -0.35 -0.0" rpy="0 0 0"/>
            <geometry>
                <box size="0.1 0.7 0.3" />
            </geometry>
            <material name="Blue">
                <color rgba="0 0.0 1.0 1.0"/>
            </material>
        </visual>
        <collision>
            <origin xyz="-0.0 -0.35 -0.0" rpy="0 0 0"/>
            <geometry>
                <box size="0.1 0.7 0.3" />
            </geometry>
        </collision>
    </link>
    <joint name="000-101-221_000-101-221-300" type="revolute">
       <parent link="000-101-221"/>
       <child  link="000-101-221-300"/>
       <origin rpy="0 0 0" xyz="-0.0 -0.35 -0.15" />
     <axis xyz="0 0 1"/>
       <limit effort="0.0" lower="-3.14159" upper="3.14159" velocity="0.0"/>
    </joint>
    <link name="000-101-221-300">
        <inertial>
            <origin xyz="-0.0 -0.0 -0.1" rpy="0 0 0"/>
            <mass value="1" />
            <inertia ixx="100" ixy="0" ixz="0" iyy="100" iyz="0" izz="100" />
        </inertial>
        <visual>
            <origin xyz="-0.0 -0.0 -0.1" rpy="0 0 0"/>
            <geometry>
                <box size="0.3 0.6 0.2" />
            </geometry>
            <material name="Green">
                <color rgba="0 1.0 0.0 1.0"/>
            </material>
        </visual>
        <collision>
            <origin xyz="-0.0 -0.0 -0.1" rpy="0 0 0"/>
            <geometry>
                <box size="0.3 0.6 0.2" />
            </geometry>
        </collision>
    </link>
    <joint name="000-101-221-300_000-101-221-310" type="revolute">
       <parent link="000-101-221-300"/>
       <child  link="000-101-221-310"/>
       <origin rpy="0 0 0" xyz="-0.0 -0.0 -0.2" />
     <axis xyz="0 0 1"/>
       <limit effort="0.0" lower="-3.14159" upper="3.14159" velocity="0.0"/>
    </joint>
    <link name="000-101-221-310">
        <inertial>
            <origin xyz="-0.0 -0.0 -0.1" rpy="0 0 0"/>
            <mass value="1" />
            <inertia ixx="100" ixy="0" ixz="0" iyy="100" iyz="0" izz="100" />
        </inertial>
        <visual>
            <origin xyz="-0.0 -0.0 -0.1" rpy="0 0 0"/>
            <geometry>
                <box size="0.3 0.6 0.2" />
            </geometry>
            <material name="Green">
                <color rgba="0 1.0 0.0 1.0"/>
            </material>
        </visual>
        <collision>
            <origin xyz="-0.0 -0.0 -0.1" rpy="0 0 0"/>
            <geometry>
                <box size="0.3 0.6 0.2" />
            </geometry>
        </collision>
    </link>
    <joint name="000-101-211_000-101-211-300" type="revolute">
       <parent link="000-101-211"/>
       <child  link="000-101-211-300"/>
       <origin rpy="0 0 0" xyz="-0.0 -0.35 -0.15" />
     <axis xyz="0 0 1"/>
       <limit effort="0.0" lower="-3.14159" upper="3.14159" velocity="0.0"/>
    </joint>
    <link name="000-101-211-300">
        <inertial>
            <origin xyz="-0.0 -0.0 -0.1" rpy="0 0 0"/>
            <mass value="1" />
            <inertia ixx="100" ixy="0" ixz="0" iyy="100" iyz="0" izz="100" />
        </inertial>
        <visual>
            <origin xyz="-0.0 -0.0 -0.1" rpy="0 0 0"/>
            <geometry>
                <box size="0.3 0.6 0.2" />
            </geometry>
            <material name="Green">
                <color rgba="0 1.0 0.0 1.0"/>
            </material>
        </visual>
        <collision>
            <origin xyz="-0.0 -0.0 -0.1" rpy="0 0 0"/>
            <geometry>
                <box size="0.3 0.6 0.2" />
            </geometry>
        </collision>
    </link>
    <joint name="000-101-211-300_000-101-211-310" type="revolute">
       <parent link="000-101-211-300"/>
       <child  link="000-101-211-310"/>
       <origin rpy="0 0 0" xyz="-0.0 -0.0 -0.2" />
     <axis xyz="0 0 1"/>
       <limit effort="0.0" lower="-3.14159" upper="3.14159" velocity="0.0"/>
    </joint>
    <link name="000-101-211-310">
        <inertial>
            <origin xyz="-0.0 -0.0 -0.1" rpy="0 0 0"/>
            <mass value="1" />
            <inertia ixx="100" ixy="0" ixz="0" iyy="100" iyz="0" izz="100" />
        </inertial>
        <visual>
            <origin xyz="-0.0 -0.0 -0.1" rpy="0 0 0"/>
            <geometry>
                <box size="0.3 0.6 0.2" />
            </geometry>
            <material name="Green">
                <color rgba="0 1.0 0.0 1.0"/>
            </material>
        </visual>
        <collision>
            <origin xyz="-0.0 -0.0 -0.1" rpy="0 0 0"/>
            <geometry>
                <box size="0.3 0.6 0.2" />
            </geometry>
        </collision>
    </link>
    <joint name="000-101-201_000-101-201-300" type="revolute">
       <parent link="000-101-201"/>
       <child  link="000-101-201-300"/>
       <origin rpy="0 0 0" xyz="-0.0 -0.35 -0.15" />
     <axis xyz="0 0 1"/>
       <limit effort="0.0" lower="-3.14159" upper="3.14159" velocity="0.0"/>
    </joint>
    <link name="000-101-201-300">
        <inertial>
            <origin xyz="-0.0 -0.0 -0.1" rpy="0 0 0"/>
            <mass value="1" />
            <inertia ixx="100" ixy="0" ixz="0" iyy="100" iyz="0" izz="100" />
        </inertial>
        <visual>
            <origin xyz="-0.0 -0.0 -0.1" rpy="0 0 0"/>
            <geometry>
                <box size="0.3 0.6 0.2" />
            </geometry>
            <material name="Green">
                <color rgba="0 1.0 0.0 1.0"/>
            </material>
        </visual>
        <collision>
            <origin xyz="-0.0 -0.0 -0.1" rpy="0 0 0"/>
            <geometry>
                <box size="0.3 0.6 0.2" />
            </geometry>
        </collision>
    </link>
    <joint name="000-101-201-300_000-101-201-310" type="revolute">
       <parent link="000-101-201-300"/>
       <child  link="000-101-201-310"/>
       <origin rpy="0 0 0" xyz="-0.0 -0.0 -0.2" />
     <axis xyz="0 0 1"/>
       <limit effort="0.0" lower="-3.14159" upper="3.14159" velocity="0.0"/>
    </joint>
    <link name="000-101-201-310">
        <inertial>
            <origin xyz="-0.0 -0.0 -0.1" rpy="0 0 0"/>
            <mass value="1" />
            <inertia ixx="100" ixy="0" ixz="0" iyy="100" iyz="0" izz="100" />
        </inertial>
        <visual>
            <origin xyz="-0.0 -0.0 -0.1" rpy="0 0 0"/>
            <geometry>
                <box size="0.3 0.6 0.2" />
            </geometry>
            <material name="Green">
                <color rgba="0 1.0 0.0 1.0"/>
            </material>
        </visual>
        <collision>
            <origin xyz="-0.0 -0.0 -0.1" rpy="0 0 0"/>
            <geometry>
                <box size="0.3 0.6 0.2" />
            </geometry>
        </collision>
    </link>
</robot>