<robot name = "robot">
    <link name="root">
        <inertial>
            <origin xyz="0.0 0.0 1.5" rpy="0 0 0"/>
            <mass value="1" />
            <inertia ixx="100" ixy="0" ixz="0" iyy="100" iyz="0" izz="100" />
        </inertial>
        <visual>
            <origin xyz="0.0 0.0 1.5" rpy="0 0 0"/>
            <geometry>
                <box size="0 0 0.0001" />
            </geometry>
            <material name="Green">
                <color rgba="0 1.0 0.0 1.0"/>
            </material>
        </visual>
        <collision>
            <origin xyz="0.0 0.0 1.5" rpy="0 0 0"/>
            <geometry>
                <box size="0 0 0.0001" />
            </geometry>
        </collision>
    </link>
    <joint name="root_000" type="revolute">
       <parent link="root"/>
       <child  link="000"/>
       <origin rpy="0 0 0" xyz="0.0 0.0 1.5" />
     <axis xyz="1 0 0"/>
       <limit effort="0.0" lower="-3.14159" upper="3.14159" velocity="0.0"/>
    </joint>
    <link name="000">
        <inertial>
            <origin xyz="0.0 0.0 -0.3" rpy="0 0 0"/>
            <mass value="1" />
            <inertia ixx="100" ixy="0" ixz="0" iyy="100" iyz="0" izz="100" />
        </inertial>
        <visual>
            <origin xyz="0.0 0.0 -0.3" rpy="0 0 0"/>
            <geometry>
                <box size="0.5 0.7 0.6" />
            </geometry>
            <material name="Green">
                <color rgba="0 1.0 0.0 1.0"/>
            </material>
        </visual>
        <collision>
            <origin xyz="0.0 0.0 -0.3" rpy="0 0 0"/>
            <geometry>
                <box size="0.5 0.7 0.6" />
            </geometry>
        </collision>
    </link>
    <joint name="000_000-100" type="revolute">
       <parent link="000"/>
       <child  link="000-100"/>
       <origin rpy="0 0 0" xyz="0.0 0.35 -0.3" />
     <axis xyz="0 1 0"/>
       <limit effort="0.0" lower="-3.14159" upper="3.14159" velocity="0.0"/>
    </joint>
    <link name="000-100">
        <inertial>
            <origin xyz="0.0 0.05 -0.0" rpy="0 0 0"/>
            <mass value="1" />
            <inertia ixx="100" ixy="0" ixz="0" iyy="100" iyz="0" izz="100" />
        </inertial>
        <visual>
            <origin xyz="0.0 0.05 -0.0" rpy="0 0 0"/>
            <geometry>
                <box size="0.2 0.1 0.4" />
            </geometry>
            <material name="Blue">
                <color rgba="0 0.0 1.0 1.0"/>
            </material>
        </visual>
        <collision>
            <origin xyz="0.0 0.05 -0.0" rpy="0 0 0"/>
            <geometry>
                <box size="0.2 0.1 0.4" />
            </geometry>
        </collision>
    </link>
    <joint name="000-100_000-110" type="revolute">
       <parent link="000-100"/>
       <child  link="000-110"/>
       <origin rpy="0 0 0" xyz="0.0 0.1 -0.0" />
     <axis xyz="0 1 0"/>
       <limit effort="0.0" lower="-3.14159" upper="3.14159" velocity="0.0"/>
    </joint>
    <link name="000-110">
        <inertial>
            <origin xyz="0.0 0.05 -0.0" rpy="0 0 0"/>
            <mass value="1" />
            <inertia ixx="100" ixy="0" ixz="0" iyy="100" iyz="0" izz="100" />
        </inertial>
        <visual>
            <origin xyz="0.0 0.05 -0.0" rpy="0 0 0"/>
            <geometry>
                <box size="0.2 0.1 0.4" />
            </geometry>
            <material name="Blue">
                <color rgba="0 0.0 1.0 1.0"/>
            </material>
        </visual>
        <collision>
            <origin xyz="0.0 0.05 -0.0" rpy="0 0 0"/>
            <geometry>
                <box size="0.2 0.1 0.4" />
            </geometry>
        </collision>
    </link>
    <joint name="000-110_000-110-200" type="revolute">
       <parent link="000-110"/>
       <child  link="000-110-200"/>
       <origin rpy="0 0 0" xyz="0.0 0.05 -0.2" />
     <axis xyz="0 0 1"/>
       <limit effort="0.0" lower="-3.14159" upper="3.14159" velocity="0.0"/>
    </joint>
    <link name="000-110-200">
        <inertial>
            <origin xyz="0.0 0.0 -0.25" rpy="0 0 0"/>
            <mass value="1" />
            <inertia ixx="100" ixy="0" ixz="0" iyy="100" iyz="0" izz="100" />
        </inertial>
        <visual>
            <origin xyz="0.0 0.0 -0.25" rpy="0 0 0"/>
            <geometry>
                <box size="0.2 0.5 0.5" />
            </geometry>
            <material name="Green">
                <color rgba="0 1.0 0.0 1.0"/>
            </material>
        </visual>
        <collision>
            <origin xyz="0.0 0.0 -0.25" rpy="0 0 0"/>
            <geometry>
                <box size="0.2 0.5 0.5" />
            </geometry>
        </collision>
    </link>
    <joint name="000-110-200_000-110-200-300" type="revolute">
       <parent link="000-110-200"/>
       <child  link="000-110-200-300"/>
       <origin rpy="0 0 0" xyz="0.0 0.25 -0.25" />
     <axis xyz="0 1 0"/>
       <limit effort="0.0" lower="-3.14159" upper="3.14159" velocity="0.0"/>
    </joint>
    <link name="000-110-200-300">
        <inertial>
            <origin xyz="0.0 0.2 -0.0" rpy="0 0 0"/>
            <mass value="1" />
            <inertia ixx="100" ixy="0" ixz="0" iyy="100" iyz="0" izz="100" />
        </inertial>
        <visual>
            <origin xyz="0.0 0.2 -0.0" rpy="0 0 0"/>
            <geometry>
                <box size="0.1 0.4 0.3" />
            </geometry>
            <material name="Green">
                <color rgba="0 1.0 0.0 1.0"/>
            </material>
        </visual>
        <collision>
            <origin xyz="0.0 0.2 -0.0" rpy="0 0 0"/>
            <geometry>
                <box size="0.1 0.4 0.3" />
            </geometry>
        </collision>
    </link>
    <joint name="000-110-200-300_000-110-200-310" type="revolute">
       <parent link="000-110-200-300"/>
       <child  link="000-110-200-310"/>
       <origin rpy="0 0 0" xyz="0.0 0.4 -0.0" />
     <axis xyz="0 1 0"/>
       <limit effort="0.0" lower="-3.14159" upper="3.14159" velocity="0.0"/>
    </joint>
    <link name="000-110-200-310">
        <inertial>
            <origin xyz="0.0 0.2 -0.0" rpy="0 0 0"/>
            <mass value="1" />
            <inertia ixx="100" ixy="0" ixz="0" iyy="100" iyz="0" izz="100" />
        </inertial>
        <visual>
            <origin xyz="0.0 0.2 -0.0" rpy="0 0 0"/>
            <geometry>
                <box size="0.1 0.4 0.3" />
            </geometry>
            <material name="Green">
                <color rgba="0 1.0 0.0 1.0"/>
            </material>
        </visual>
        <collision>
            <origin xyz="0.0 0.2 -0.0" rpy="0 0 0"/>
            <geometry>
                <box size="0.1 0.4 0.3" />
            </geometry>
        </collision>
    </link>
</robot>