<robot name = "robot">
    <link name="root">
        <inertial>
            <origin xyz="0.0 0.0 1.5" rpy="0 0 0"/>
            <mass value="1" />
            <inertia ixx="100" ixy="0" ixz="0" iyy="100" iyz="0" izz="100" />
        </inertial>
        <visual>
            <origin xyz="0.0 0.0 1.5" rpy="0 0 0"/>
            <geometry>
                <box size="0 0 0.0001" />
            </geometry>
            <material name="Green">
                <color rgba="0 1.0 0.0 1.0"/>
            </material>
        </visual>
        <collision>
            <origin xyz="0.0 0.0 1.5" rpy="0 0 0"/>
            <geometry>
                <box size="0 0 0.0001" />
            </geometry>
        </collision>
    </link>
    <joint name="root_000" type="revolute">
       <parent link="root"/>
       <child  link="000"/>
       <origin rpy="0 0 0" xyz="0.0 0.0 1.5" />
     <axis xyz="1 0 0"/>
       <limit effort="0.0" lower="-3.14159" upper="3.14159" velocity="0.0"/>
    </joint>
    <link name="000">
        <inertial>
            <origin xyz="0.0 0.0 -0.1" rpy="0 0 0"/>
            <mass value="1" />
            <inertia ixx="100" ixy="0" ixz="0" iyy="100" iyz="0" izz="100" />
        </inertial>
        <visual>
            <origin xyz="0.0 0.0 -0.1" rpy="0 0 0"/>
            <geometry>
                <box size="0.4 0.4 0.2" />
            </geometry>
            <material name="Green">
                <color rgba="0 1.0 0.0 1.0"/>
            </material>
        </visual>
        <collision>
            <origin xyz="0.0 0.0 -0.1" rpy="0 0 0"/>
            <geometry>
                <box size="0.4 0.4 0.2" />
            </geometry>
        </collision>
    </link>
    <joint name="000_000-100" type="revolute">
       <parent link="000"/>
       <child  link="000-100"/>
       <origin rpy="0 0 0" xyz="0.0 0.2 -0.1" />
     <axis xyz="0 1 0"/>
       <limit effort="0.0" lower="-3.14159" upper="3.14159" velocity="0.0"/>
    </joint>
    <link name="000-100">
        <inertial>
            <origin xyz="0.0 0.25 -0.0" rpy="0 0 0"/>
            <mass value="1" />
            <inertia ixx="100" ixy="0" ixz="0" iyy="100" iyz="0" izz="100" />
        </inertial>
        <visual>
            <origin xyz="0.0 0.25 -0.0" rpy="0 0 0"/>
            <geometry>
                <box size="0.5 0.5 0.1" />
            </geometry>
            <material name="Green">
                <color rgba="0 1.0 0.0 1.0"/>
            </material>
        </visual>
        <collision>
            <origin xyz="0.0 0.25 -0.0" rpy="0 0 0"/>
            <geometry>
                <box size="0.5 0.5 0.1" />
            </geometry>
        </collision>
    </link>
    <joint name="000-100_000-110" type="revolute">
       <parent link="000-100"/>
       <child  link="000-110"/>
       <origin rpy="0 0 0" xyz="0.0 0.5 -0.0" />
     <axis xyz="0 1 0"/>
       <limit effort="0.0" lower="-3.14159" upper="3.14159" velocity="0.0"/>
    </joint>
    <link name="000-110">
        <inertial>
            <origin xyz="0.0 0.25 -0.0" rpy="0 0 0"/>
            <mass value="1" />
            <inertia ixx="100" ixy="0" ixz="0" iyy="100" iyz="0" izz="100" />
        </inertial>
        <visual>
            <origin xyz="0.0 0.25 -0.0" rpy="0 0 0"/>
            <geometry>
                <box size="0.5 0.5 0.1" />
            </geometry>
            <material name="Green">
                <color rgba="0 1.0 0.0 1.0"/>
            </material>
        </visual>
        <collision>
            <origin xyz="0.0 0.25 -0.0" rpy="0 0 0"/>
            <geometry>
                <box size="0.5 0.5 0.1" />
            </geometry>
        </collision>
    </link>
    <joint name="000-110_000-120" type="revolute">
       <parent link="000-110"/>
       <child  link="000-120"/>
       <origin rpy="0 0 0" xyz="0.0 0.5 -0.0" />
     <axis xyz="0 1 0"/>
       <limit effort="0.0" lower="-3.14159" upper="3.14159" velocity="0.0"/>
    </joint>
    <link name="000-120">
        <inertial>
            <origin xyz="0.0 0.25 -0.0" rpy="0 0 0"/>
            <mass value="1" />
            <inertia ixx="100" ixy="0" ixz="0" iyy="100" iyz="0" izz="100" />
        </inertial>
        <visual>
            <origin xyz="0.0 0.25 -0.0" rpy="0 0 0"/>
            <geometry>
                <box size="0.5 0.5 0.1" />
            </geometry>
            <material name="Green">
                <color rgba="0 1.0 0.0 1.0"/>
            </material>
        </visual>
        <collision>
            <origin xyz="0.0 0.25 -0.0" rpy="0 0 0"/>
            <geometry>
                <box size="0.5 0.5 0.1" />
            </geometry>
        </collision>
    </link>
    <joint name="000-120_000-120-200" type="revolute">
       <parent link="000-120"/>
       <child  link="000-120-200"/>
       <origin rpy="0 0 0" xyz="0.25 0.25 -0.0" />
     <axis xyz="1 0 0"/>
       <limit effort="0.0" lower="-3.14159" upper="3.14159" velocity="0.0"/>
    </joint>
    <link name="000-120-200">
        <inertial>
            <origin xyz="0.25 0.0 -0.0" rpy="0 0 0"/>
            <mass value="1" />
            <inertia ixx="100" ixy="0" ixz="0" iyy="100" iyz="0" izz="100" />
        </inertial>
        <visual>
            <origin xyz="0.25 0.0 -0.0" rpy="0 0 0"/>
            <geometry>
                <box size="0.5 0.6 0.6" />
            </geometry>
            <material name="Green">
                <color rgba="0 1.0 0.0 1.0"/>
            </material>
        </visual>
        <collision>
            <origin xyz="0.25 0.0 -0.0" rpy="0 0 0"/>
            <geometry>
                <box size="0.5 0.6 0.6" />
            </geometry>
        </collision>
    </link>
    <joint name="000-120_000-120-201" type="revolute">
       <parent link="000-120"/>
       <child  link="000-120-201"/>
       <origin rpy="0 0 0" xyz="-0.25 0.25 -0.0" />
     <axis xyz="1 0 0"/>
       <limit effort="0.0" lower="-3.14159" upper="3.14159" velocity="0.0"/>
    </joint>
    <link name="000-120-201">
        <inertial>
            <origin xyz="-0.25 0.0 -0.0" rpy="0 0 0"/>
            <mass value="1" />
            <inertia ixx="100" ixy="0" ixz="0" iyy="100" iyz="0" izz="100" />
        </inertial>
        <visual>
            <origin xyz="-0.25 0.0 -0.0" rpy="0 0 0"/>
            <geometry>
                <box size="0.5 0.6 0.6" />
            </geometry>
            <material name="Green">
                <color rgba="0 1.0 0.0 1.0"/>
            </material>
        </visual>
        <collision>
            <origin xyz="-0.25 0.0 -0.0" rpy="0 0 0"/>
            <geometry>
                <box size="0.5 0.6 0.6" />
            </geometry>
        </collision>
    </link>
    <joint name="000-110_000-110-200" type="revolute">
       <parent link="000-110"/>
       <child  link="000-110-200"/>
       <origin rpy="0 0 0" xyz="0.25 0.25 -0.0" />
     <axis xyz="1 0 0"/>
       <limit effort="0.0" lower="-3.14159" upper="3.14159" velocity="0.0"/>
    </joint>
    <link name="000-110-200">
        <inertial>
            <origin xyz="0.25 0.0 -0.0" rpy="0 0 0"/>
            <mass value="1" />
            <inertia ixx="100" ixy="0" ixz="0" iyy="100" iyz="0" izz="100" />
        </inertial>
        <visual>
            <origin xyz="0.25 0.0 -0.0" rpy="0 0 0"/>
            <geometry>
                <box size="0.5 0.6 0.6" />
            </geometry>
            <material name="Green">
                <color rgba="0 1.0 0.0 1.0"/>
            </material>
        </visual>
        <collision>
            <origin xyz="0.25 0.0 -0.0" rpy="0 0 0"/>
            <geometry>
                <box size="0.5 0.6 0.6" />
            </geometry>
        </collision>
    </link>
    <joint name="000-110_000-110-201" type="revolute">
       <parent link="000-110"/>
       <child  link="000-110-201"/>
       <origin rpy="0 0 0" xyz="-0.25 0.25 -0.0" />
     <axis xyz="1 0 0"/>
       <limit effort="0.0" lower="-3.14159" upper="3.14159" velocity="0.0"/>
    </joint>
    <link name="000-110-201">
        <inertial>
            <origin xyz="-0.25 0.0 -0.0" rpy="0 0 0"/>
            <mass value="1" />
            <inertia ixx="100" ixy="0" ixz="0" iyy="100" iyz="0" izz="100" />
        </inertial>
        <visual>
            <origin xyz="-0.25 0.0 -0.0" rpy="0 0 0"/>
            <geometry>
                <box size="0.5 0.6 0.6" />
            </geometry>
            <material name="Green">
                <color rgba="0 1.0 0.0 1.0"/>
            </material>
        </visual>
        <collision>
            <origin xyz="-0.25 0.0 -0.0" rpy="0 0 0"/>
            <geometry>
                <box size="0.5 0.6 0.6" />
            </geometry>
        </collision>
    </link>
    <joint name="000-100_000-100-200" type="revolute">
       <parent link="000-100"/>
       <child  link="000-100-200"/>
       <origin rpy="0 0 0" xyz="0.25 0.25 -0.0" />
     <axis xyz="1 0 0"/>
       <limit effort="0.0" lower="-3.14159" upper="3.14159" velocity="0.0"/>
    </joint>
    <link name="000-100-200">
        <inertial>
            <origin xyz="0.25 0.0 -0.0" rpy="0 0 0"/>
            <mass value="1" />
            <inertia ixx="100" ixy="0" ixz="0" iyy="100" iyz="0" izz="100" />
        </inertial>
        <visual>
            <origin xyz="0.25 0.0 -0.0" rpy="0 0 0"/>
            <geometry>
                <box size="0.5 0.6 0.6" />
            </geometry>
            <material name="Green">
                <color rgba="0 1.0 0.0 1.0"/>
            </material>
        </visual>
        <collision>
            <origin xyz="0.25 0.0 -0.0" rpy="0 0 0"/>
            <geometry>
                <box size="0.5 0.6 0.6" />
            </geometry>
        </collision>
    </link>
    <joint name="000-100_000-100-201" type="revolute">
       <parent link="000-100"/>
       <child  link="000-100-201"/>
       <origin rpy="0 0 0" xyz="-0.25 0.25 -0.0" />
     <axis xyz="1 0 0"/>
       <limit effort="0.0" lower="-3.14159" upper="3.14159" velocity="0.0"/>
    </joint>
    <link name="000-100-201">
        <inertial>
            <origin xyz="-0.25 0.0 -0.0" rpy="0 0 0"/>
            <mass value="1" />
            <inertia ixx="100" ixy="0" ixz="0" iyy="100" iyz="0" izz="100" />
        </inertial>
        <visual>
            <origin xyz="-0.25 0.0 -0.0" rpy="0 0 0"/>
            <geometry>
                <box size="0.5 0.6 0.6" />
            </geometry>
            <material name="Green">
                <color rgba="0 1.0 0.0 1.0"/>
            </material>
        </visual>
        <collision>
            <origin xyz="-0.25 0.0 -0.0" rpy="0 0 0"/>
            <geometry>
                <box size="0.5 0.6 0.6" />
            </geometry>
        </collision>
    </link>
    <joint name="000_000-101" type="revolute">
       <parent link="000"/>
       <child  link="000-101"/>
       <origin rpy="0 0 0" xyz="0.0 -0.2 -0.1" />
     <axis xyz="0 1 0"/>
       <limit effort="0.0" lower="-3.14159" upper="3.14159" velocity="0.0"/>
    </joint>
    <link name="000-101">
        <inertial>
            <origin xyz="0.0 -0.25 -0.0" rpy="0 0 0"/>
            <mass value="1" />
            <inertia ixx="100" ixy="0" ixz="0" iyy="100" iyz="0" izz="100" />
        </inertial>
        <visual>
            <origin xyz="0.0 -0.25 -0.0" rpy="0 0 0"/>
            <geometry>
                <box size="0.5 0.5 0.1" />
            </geometry>
            <material name="Green">
                <color rgba="0 1.0 0.0 1.0"/>
            </material>
        </visual>
        <collision>
            <origin xyz="0.0 -0.25 -0.0" rpy="0 0 0"/>
            <geometry>
                <box size="0.5 0.5 0.1" />
            </geometry>
        </collision>
    </link>
    <joint name="000-101_000-111" type="revolute">
       <parent link="000-101"/>
       <child  link="000-111"/>
       <origin rpy="0 0 0" xyz="0.0 -0.5 -0.0" />
     <axis xyz="0 1 0"/>
       <limit effort="0.0" lower="-3.14159" upper="3.14159" velocity="0.0"/>
    </joint>
    <link name="000-111">
        <inertial>
            <origin xyz="0.0 -0.25 -0.0" rpy="0 0 0"/>
            <mass value="1" />
            <inertia ixx="100" ixy="0" ixz="0" iyy="100" iyz="0" izz="100" />
        </inertial>
        <visual>
            <origin xyz="0.0 -0.25 -0.0" rpy="0 0 0"/>
            <geometry>
                <box size="0.5 0.5 0.1" />
            </geometry>
            <material name="Green">
                <color rgba="0 1.0 0.0 1.0"/>
            </material>
        </visual>
        <collision>
            <origin xyz="0.0 -0.25 -0.0" rpy="0 0 0"/>
            <geometry>
                <box size="0.5 0.5 0.1" />
            </geometry>
        </collision>
    </link>
    <joint name="000-111_000-121" type="revolute">
       <parent link="000-111"/>
       <child  link="000-121"/>
       <origin rpy="0 0 0" xyz="0.0 -0.5 -0.0" />
     <axis xyz="0 1 0"/>
       <limit effort="0.0" lower="-3.14159" upper="3.14159" velocity="0.0"/>
    </joint>
    <link name="000-121">
        <inertial>
            <origin xyz="0.0 -0.25 -0.0" rpy="0 0 0"/>
            <mass value="1" />
            <inertia ixx="100" ixy="0" ixz="0" iyy="100" iyz="0" izz="100" />
        </inertial>
        <visual>
            <origin xyz="0.0 -0.25 -0.0" rpy="0 0 0"/>
            <geometry>
                <box size="0.5 0.5 0.1" />
            </geometry>
            <material name="Green">
                <color rgba="0 1.0 0.0 1.0"/>
            </material>
        </visual>
        <collision>
            <origin xyz="0.0 -0.25 -0.0" rpy="0 0 0"/>
            <geometry>
                <box size="0.5 0.5 0.1" />
            </geometry>
        </collision>
    </link>
    <joint name="000-121_000-121-200" type="revolute">
       <parent link="000-121"/>
       <child  link="000-121-200"/>
       <origin rpy="0 0 0" xyz="0.25 -0.25 -0.0" />
     <axis xyz="1 0 0"/>
       <limit effort="0.0" lower="-3.14159" upper="3.14159" velocity="0.0"/>
    </joint>
    <link name="000-121-200">
        <inertial>
            <origin xyz="0.25 -0.0 -0.0" rpy="0 0 0"/>
            <mass value="1" />
            <inertia ixx="100" ixy="0" ixz="0" iyy="100" iyz="0" izz="100" />
        </inertial>
        <visual>
            <origin xyz="0.25 -0.0 -0.0" rpy="0 0 0"/>
            <geometry>
                <box size="0.5 0.6 0.6" />
            </geometry>
            <material name="Green">
                <color rgba="0 1.0 0.0 1.0"/>
            </material>
        </visual>
        <collision>
            <origin xyz="0.25 -0.0 -0.0" rpy="0 0 0"/>
            <geometry>
                <box size="0.5 0.6 0.6" />
            </geometry>
        </collision>
    </link>
    <joint name="000-121_000-121-201" type="revolute">
       <parent link="000-121"/>
       <child  link="000-121-201"/>
       <origin rpy="0 0 0" xyz="-0.25 -0.25 -0.0" />
     <axis xyz="1 0 0"/>
       <limit effort="0.0" lower="-3.14159" upper="3.14159" velocity="0.0"/>
    </joint>
    <link name="000-121-201">
        <inertial>
            <origin xyz="-0.25 -0.0 -0.0" rpy="0 0 0"/>
            <mass value="1" />
            <inertia ixx="100" ixy="0" ixz="0" iyy="100" iyz="0" izz="100" />
        </inertial>
        <visual>
            <origin xyz="-0.25 -0.0 -0.0" rpy="0 0 0"/>
            <geometry>
                <box size="0.5 0.6 0.6" />
            </geometry>
            <material name="Green">
                <color rgba="0 1.0 0.0 1.0"/>
            </material>
        </visual>
        <collision>
            <origin xyz="-0.25 -0.0 -0.0" rpy="0 0 0"/>
            <geometry>
                <box size="0.5 0.6 0.6" />
            </geometry>
        </collision>
    </link>
    <joint name="000-111_000-111-200" type="revolute">
       <parent link="000-111"/>
       <child  link="000-111-200"/>
       <origin rpy="0 0 0" xyz="0.25 -0.25 -0.0" />
     <axis xyz="1 0 0"/>
       <limit effort="0.0" lower="-3.14159" upper="3.14159" velocity="0.0"/>
    </joint>
    <link name="000-111-200">
        <inertial>
            <origin xyz="0.25 -0.0 -0.0" rpy="0 0 0"/>
            <mass value="1" />
            <inertia ixx="100" ixy="0" ixz="0" iyy="100" iyz="0" izz="100" />
        </inertial>
        <visual>
            <origin xyz="0.25 -0.0 -0.0" rpy="0 0 0"/>
            <geometry>
                <box size="0.5 0.6 0.6" />
            </geometry>
            <material name="Green">
                <color rgba="0 1.0 0.0 1.0"/>
            </material>
        </visual>
        <collision>
            <origin xyz="0.25 -0.0 -0.0" rpy="0 0 0"/>
            <geometry>
                <box size="0.5 0.6 0.6" />
            </geometry>
        </collision>
    </link>
    <joint name="000-111_000-111-201" type="revolute">
       <parent link="000-111"/>
       <child  link="000-111-201"/>
       <origin rpy="0 0 0" xyz="-0.25 -0.25 -0.0" />
     <axis xyz="1 0 0"/>
       <limit effort="0.0" lower="-3.14159" upper="3.14159" velocity="0.0"/>
    </joint>
    <link name="000-111-201">
        <inertial>
            <origin xyz="-0.25 -0.0 -0.0" rpy="0 0 0"/>
            <mass value="1" />
            <inertia ixx="100" ixy="0" ixz="0" iyy="100" iyz="0" izz="100" />
        </inertial>
        <visual>
            <origin xyz="-0.25 -0.0 -0.0" rpy="0 0 0"/>
            <geometry>
                <box size="0.5 0.6 0.6" />
            </geometry>
            <material name="Green">
                <color rgba="0 1.0 0.0 1.0"/>
            </material>
        </visual>
        <collision>
            <origin xyz="-0.25 -0.0 -0.0" rpy="0 0 0"/>
            <geometry>
                <box size="0.5 0.6 0.6" />
            </geometry>
        </collision>
    </link>
    <joint name="000-101_000-101-200" type="revolute">
       <parent link="000-101"/>
       <child  link="000-101-200"/>
       <origin rpy="0 0 0" xyz="0.25 -0.25 -0.0" />
     <axis xyz="1 0 0"/>
       <limit effort="0.0" lower="-3.14159" upper="3.14159" velocity="0.0"/>
    </joint>
    <link name="000-101-200">
        <inertial>
            <origin xyz="0.25 -0.0 -0.0" rpy="0 0 0"/>
            <mass value="1" />
            <inertia ixx="100" ixy="0" ixz="0" iyy="100" iyz="0" izz="100" />
        </inertial>
        <visual>
            <origin xyz="0.25 -0.0 -0.0" rpy="0 0 0"/>
            <geometry>
                <box size="0.5 0.6 0.6" />
            </geometry>
            <material name="Green">
                <color rgba="0 1.0 0.0 1.0"/>
            </material>
        </visual>
        <collision>
            <origin xyz="0.25 -0.0 -0.0" rpy="0 0 0"/>
            <geometry>
                <box size="0.5 0.6 0.6" />
            </geometry>
        </collision>
    </link>
    <joint name="000-101_000-101-201" type="revolute">
       <parent link="000-101"/>
       <child  link="000-101-201"/>
       <origin rpy="0 0 0" xyz="-0.25 -0.25 -0.0" />
     <axis xyz="1 0 0"/>
       <limit effort="0.0" lower="-3.14159" upper="3.14159" velocity="0.0"/>
    </joint>
    <link name="000-101-201">
        <inertial>
            <origin xyz="-0.25 -0.0 -0.0" rpy="0 0 0"/>
            <mass value="1" />
            <inertia ixx="100" ixy="0" ixz="0" iyy="100" iyz="0" izz="100" />
        </inertial>
        <visual>
            <origin xyz="-0.25 -0.0 -0.0" rpy="0 0 0"/>
            <geometry>
                <box size="0.5 0.6 0.6" />
            </geometry>
            <material name="Green">
                <color rgba="0 1.0 0.0 1.0"/>
            </material>
        </visual>
        <collision>
            <origin xyz="-0.25 -0.0 -0.0" rpy="0 0 0"/>
            <geometry>
                <box size="0.5 0.6 0.6" />
            </geometry>
        </collision>
    </link>
</robot>